Failure # 1 (occurred at 2022-06-14_23-07-54)
Traceback (most recent call last):
  File "/home/xwm/anaconda3/envs/SV/lib/python3.6/site-packages/ray/tune/trial_runner.py", line 886, in _process_trial
    results = self.trial_executor.fetch_result(trial)
  File "/home/xwm/anaconda3/envs/SV/lib/python3.6/site-packages/ray/tune/ray_trial_executor.py", line 675, in fetch_result
    result = ray.get(trial_future[0], timeout=DEFAULT_GET_TIMEOUT)
  File "/home/xwm/anaconda3/envs/SV/lib/python3.6/site-packages/ray/_private/client_mode_hook.py", line 105, in wrapper
    return func(*args, **kwargs)
  File "/home/xwm/anaconda3/envs/SV/lib/python3.6/site-packages/ray/worker.py", line 1763, in get
    raise value.as_instanceof_cause()
ray.exceptions.RayTaskError(TuneError): [36mray::ImplicitFunc.train()[39m (pid=189480, ip=192.168.249.74, repr=train_tune)
  File "/home/xwm/anaconda3/envs/SV/lib/python3.6/site-packages/ray/tune/trainable.py", line 319, in train
    result = self.step()
  File "/home/xwm/anaconda3/envs/SV/lib/python3.6/site-packages/ray/tune/function_runner.py", line 381, in step
    self._report_thread_runner_error(block=True)
  File "/home/xwm/anaconda3/envs/SV/lib/python3.6/site-packages/ray/tune/function_runner.py", line 532, in _report_thread_runner_error
    ("Trial raised an exception. Traceback:\n{}".format(err_tb_str)
ray.tune.error.TuneError: Trial raised an exception. Traceback:
[36mray::ImplicitFunc.train()[39m (pid=189480, ip=192.168.249.74, repr=train_tune)
  File "/home/xwm/anaconda3/envs/SV/lib/python3.6/site-packages/ray/tune/function_runner.py", line 262, in run
    self._entrypoint()
  File "/home/xwm/anaconda3/envs/SV/lib/python3.6/site-packages/ray/tune/function_runner.py", line 331, in entrypoint
    self._status_reporter.get_checkpoint())
  File "/home/xwm/anaconda3/envs/SV/lib/python3.6/site-packages/ray/tune/function_runner.py", line 600, in _trainable_func
    output = fn()
  File "/home/xwm/anaconda3/envs/SV/lib/python3.6/site-packages/ray/tune/utils/trainable.py", line 371, in inner
    trainable(config, **fn_kwargs)
  File "train.py", line 572, in train_tune
    trainer.fit(model)
  File "/home/xwm/anaconda3/envs/SV/lib/python3.6/site-packages/pytorch_lightning/trainer/trainer.py", line 741, in fit
    self._fit_impl, model, train_dataloaders, val_dataloaders, datamodule, ckpt_path
  File "/home/xwm/anaconda3/envs/SV/lib/python3.6/site-packages/pytorch_lightning/trainer/trainer.py", line 685, in _call_and_handle_interrupt
    return trainer_fn(*args, **kwargs)
  File "/home/xwm/anaconda3/envs/SV/lib/python3.6/site-packages/pytorch_lightning/trainer/trainer.py", line 777, in _fit_impl
    self._run(model, ckpt_path=ckpt_path)
  File "/home/xwm/anaconda3/envs/SV/lib/python3.6/site-packages/pytorch_lightning/trainer/trainer.py", line 1145, in _run
    self.accelerator.setup(self)
  File "/home/xwm/anaconda3/envs/SV/lib/python3.6/site-packages/pytorch_lightning/accelerators/gpu.py", line 46, in setup
    return super().setup(trainer)
  File "/home/xwm/anaconda3/envs/SV/lib/python3.6/site-packages/pytorch_lightning/accelerators/accelerator.py", line 91, in setup
    self.setup_training_type_plugin()
  File "/home/xwm/anaconda3/envs/SV/lib/python3.6/site-packages/pytorch_lightning/accelerators/accelerator.py", line 363, in setup_training_type_plugin
    self.training_type_plugin.setup()
  File "/home/xwm/anaconda3/envs/SV/lib/python3.6/site-packages/pytorch_lightning/plugins/training_type/single_device.py", line 71, in setup
    self.model_to_device()
  File "/home/xwm/anaconda3/envs/SV/lib/python3.6/site-packages/pytorch_lightning/plugins/training_type/single_device.py", line 68, in model_to_device
    self._model.to(self.root_device)
  File "/home/xwm/anaconda3/envs/SV/lib/python3.6/site-packages/pytorch_lightning/core/mixins/device_dtype_mixin.py", line 111, in to
    return super().to(*args, **kwargs)
  File "/home/xwm/anaconda3/envs/SV/lib/python3.6/site-packages/torch/nn/modules/module.py", line 899, in to
    return self._apply(convert)
  File "/home/xwm/anaconda3/envs/SV/lib/python3.6/site-packages/torch/nn/modules/module.py", line 570, in _apply
    module._apply(fn)
  File "/home/xwm/anaconda3/envs/SV/lib/python3.6/site-packages/torch/nn/modules/module.py", line 570, in _apply
    module._apply(fn)
  File "/home/xwm/anaconda3/envs/SV/lib/python3.6/site-packages/torch/nn/modules/module.py", line 570, in _apply
    module._apply(fn)
  [Previous line repeated 1 more time]
  File "/home/xwm/anaconda3/envs/SV/lib/python3.6/site-packages/torch/nn/modules/module.py", line 593, in _apply
    param_applied = fn(param)
  File "/home/xwm/anaconda3/envs/SV/lib/python3.6/site-packages/torch/nn/modules/module.py", line 897, in convert
    return t.to(device, dtype if t.is_floating_point() or t.is_complex() else None, non_blocking)
RuntimeError: CUDA error: out of memory
CUDA kernel errors might be asynchronously reported at some other API call,so the stacktrace below might be incorrect.
For debugging consider passing CUDA_LAUNCH_BLOCKING=1.

Failure # 2 (occurred at 2022-06-14_23-08-54)
Traceback (most recent call last):
  File "/home/xwm/anaconda3/envs/SV/lib/python3.6/site-packages/ray/tune/trial_runner.py", line 886, in _process_trial
    results = self.trial_executor.fetch_result(trial)
  File "/home/xwm/anaconda3/envs/SV/lib/python3.6/site-packages/ray/tune/ray_trial_executor.py", line 675, in fetch_result
    result = ray.get(trial_future[0], timeout=DEFAULT_GET_TIMEOUT)
  File "/home/xwm/anaconda3/envs/SV/lib/python3.6/site-packages/ray/_private/client_mode_hook.py", line 105, in wrapper
    return func(*args, **kwargs)
  File "/home/xwm/anaconda3/envs/SV/lib/python3.6/site-packages/ray/worker.py", line 1763, in get
    raise value.as_instanceof_cause()
ray.exceptions.RayTaskError(TuneError): [36mray::ImplicitFunc.train()[39m (pid=190116, ip=192.168.249.74, repr=train_tune)
  File "/home/xwm/anaconda3/envs/SV/lib/python3.6/site-packages/ray/tune/trainable.py", line 319, in train
    result = self.step()
  File "/home/xwm/anaconda3/envs/SV/lib/python3.6/site-packages/ray/tune/function_runner.py", line 381, in step
    self._report_thread_runner_error(block=True)
  File "/home/xwm/anaconda3/envs/SV/lib/python3.6/site-packages/ray/tune/function_runner.py", line 532, in _report_thread_runner_error
    ("Trial raised an exception. Traceback:\n{}".format(err_tb_str)
ray.tune.error.TuneError: Trial raised an exception. Traceback:
[36mray::ImplicitFunc.train()[39m (pid=190116, ip=192.168.249.74, repr=train_tune)
  File "/home/xwm/anaconda3/envs/SV/lib/python3.6/site-packages/ray/tune/function_runner.py", line 262, in run
    self._entrypoint()
  File "/home/xwm/anaconda3/envs/SV/lib/python3.6/site-packages/ray/tune/function_runner.py", line 331, in entrypoint
    self._status_reporter.get_checkpoint())
  File "/home/xwm/anaconda3/envs/SV/lib/python3.6/site-packages/ray/tune/function_runner.py", line 600, in _trainable_func
    output = fn()
  File "/home/xwm/anaconda3/envs/SV/lib/python3.6/site-packages/ray/tune/utils/trainable.py", line 371, in inner
    trainable(config, **fn_kwargs)
  File "train.py", line 572, in train_tune
    trainer.fit(model)
  File "/home/xwm/anaconda3/envs/SV/lib/python3.6/site-packages/pytorch_lightning/trainer/trainer.py", line 741, in fit
    self._fit_impl, model, train_dataloaders, val_dataloaders, datamodule, ckpt_path
  File "/home/xwm/anaconda3/envs/SV/lib/python3.6/site-packages/pytorch_lightning/trainer/trainer.py", line 685, in _call_and_handle_interrupt
    return trainer_fn(*args, **kwargs)
  File "/home/xwm/anaconda3/envs/SV/lib/python3.6/site-packages/pytorch_lightning/trainer/trainer.py", line 777, in _fit_impl
    self._run(model, ckpt_path=ckpt_path)
  File "/home/xwm/anaconda3/envs/SV/lib/python3.6/site-packages/pytorch_lightning/trainer/trainer.py", line 1145, in _run
    self.accelerator.setup(self)
  File "/home/xwm/anaconda3/envs/SV/lib/python3.6/site-packages/pytorch_lightning/accelerators/gpu.py", line 46, in setup
    return super().setup(trainer)
  File "/home/xwm/anaconda3/envs/SV/lib/python3.6/site-packages/pytorch_lightning/accelerators/accelerator.py", line 91, in setup
    self.setup_training_type_plugin()
  File "/home/xwm/anaconda3/envs/SV/lib/python3.6/site-packages/pytorch_lightning/accelerators/accelerator.py", line 363, in setup_training_type_plugin
    self.training_type_plugin.setup()
  File "/home/xwm/anaconda3/envs/SV/lib/python3.6/site-packages/pytorch_lightning/plugins/training_type/single_device.py", line 71, in setup
    self.model_to_device()
  File "/home/xwm/anaconda3/envs/SV/lib/python3.6/site-packages/pytorch_lightning/plugins/training_type/single_device.py", line 68, in model_to_device
    self._model.to(self.root_device)
  File "/home/xwm/anaconda3/envs/SV/lib/python3.6/site-packages/pytorch_lightning/core/mixins/device_dtype_mixin.py", line 111, in to
    return super().to(*args, **kwargs)
  File "/home/xwm/anaconda3/envs/SV/lib/python3.6/site-packages/torch/nn/modules/module.py", line 899, in to
    return self._apply(convert)
  File "/home/xwm/anaconda3/envs/SV/lib/python3.6/site-packages/torch/nn/modules/module.py", line 570, in _apply
    module._apply(fn)
  File "/home/xwm/anaconda3/envs/SV/lib/python3.6/site-packages/torch/nn/modules/module.py", line 570, in _apply
    module._apply(fn)
  File "/home/xwm/anaconda3/envs/SV/lib/python3.6/site-packages/torch/nn/modules/module.py", line 570, in _apply
    module._apply(fn)
  [Previous line repeated 1 more time]
  File "/home/xwm/anaconda3/envs/SV/lib/python3.6/site-packages/torch/nn/modules/module.py", line 593, in _apply
    param_applied = fn(param)
  File "/home/xwm/anaconda3/envs/SV/lib/python3.6/site-packages/torch/nn/modules/module.py", line 897, in convert
    return t.to(device, dtype if t.is_floating_point() or t.is_complex() else None, non_blocking)
RuntimeError: CUDA error: out of memory
CUDA kernel errors might be asynchronously reported at some other API call,so the stacktrace below might be incorrect.
For debugging consider passing CUDA_LAUNCH_BLOCKING=1.

Failure # 3 (occurred at 2022-06-14_23-09-55)
Traceback (most recent call last):
  File "/home/xwm/anaconda3/envs/SV/lib/python3.6/site-packages/ray/tune/trial_runner.py", line 886, in _process_trial
    results = self.trial_executor.fetch_result(trial)
  File "/home/xwm/anaconda3/envs/SV/lib/python3.6/site-packages/ray/tune/ray_trial_executor.py", line 675, in fetch_result
    result = ray.get(trial_future[0], timeout=DEFAULT_GET_TIMEOUT)
  File "/home/xwm/anaconda3/envs/SV/lib/python3.6/site-packages/ray/_private/client_mode_hook.py", line 105, in wrapper
    return func(*args, **kwargs)
  File "/home/xwm/anaconda3/envs/SV/lib/python3.6/site-packages/ray/worker.py", line 1763, in get
    raise value.as_instanceof_cause()
ray.exceptions.RayTaskError(TuneError): [36mray::ImplicitFunc.train()[39m (pid=191166, ip=192.168.249.74, repr=train_tune)
  File "/home/xwm/anaconda3/envs/SV/lib/python3.6/site-packages/ray/tune/trainable.py", line 319, in train
    result = self.step()
  File "/home/xwm/anaconda3/envs/SV/lib/python3.6/site-packages/ray/tune/function_runner.py", line 381, in step
    self._report_thread_runner_error(block=True)
  File "/home/xwm/anaconda3/envs/SV/lib/python3.6/site-packages/ray/tune/function_runner.py", line 532, in _report_thread_runner_error
    ("Trial raised an exception. Traceback:\n{}".format(err_tb_str)
ray.tune.error.TuneError: Trial raised an exception. Traceback:
[36mray::ImplicitFunc.train()[39m (pid=191166, ip=192.168.249.74, repr=train_tune)
  File "/home/xwm/anaconda3/envs/SV/lib/python3.6/site-packages/ray/tune/function_runner.py", line 262, in run
    self._entrypoint()
  File "/home/xwm/anaconda3/envs/SV/lib/python3.6/site-packages/ray/tune/function_runner.py", line 331, in entrypoint
    self._status_reporter.get_checkpoint())
  File "/home/xwm/anaconda3/envs/SV/lib/python3.6/site-packages/ray/tune/function_runner.py", line 600, in _trainable_func
    output = fn()
  File "/home/xwm/anaconda3/envs/SV/lib/python3.6/site-packages/ray/tune/utils/trainable.py", line 371, in inner
    trainable(config, **fn_kwargs)
  File "train.py", line 572, in train_tune
    trainer.fit(model)
  File "/home/xwm/anaconda3/envs/SV/lib/python3.6/site-packages/pytorch_lightning/trainer/trainer.py", line 741, in fit
    self._fit_impl, model, train_dataloaders, val_dataloaders, datamodule, ckpt_path
  File "/home/xwm/anaconda3/envs/SV/lib/python3.6/site-packages/pytorch_lightning/trainer/trainer.py", line 685, in _call_and_handle_interrupt
    return trainer_fn(*args, **kwargs)
  File "/home/xwm/anaconda3/envs/SV/lib/python3.6/site-packages/pytorch_lightning/trainer/trainer.py", line 777, in _fit_impl
    self._run(model, ckpt_path=ckpt_path)
  File "/home/xwm/anaconda3/envs/SV/lib/python3.6/site-packages/pytorch_lightning/trainer/trainer.py", line 1145, in _run
    self.accelerator.setup(self)
  File "/home/xwm/anaconda3/envs/SV/lib/python3.6/site-packages/pytorch_lightning/accelerators/gpu.py", line 46, in setup
    return super().setup(trainer)
  File "/home/xwm/anaconda3/envs/SV/lib/python3.6/site-packages/pytorch_lightning/accelerators/accelerator.py", line 91, in setup
    self.setup_training_type_plugin()
  File "/home/xwm/anaconda3/envs/SV/lib/python3.6/site-packages/pytorch_lightning/accelerators/accelerator.py", line 363, in setup_training_type_plugin
    self.training_type_plugin.setup()
  File "/home/xwm/anaconda3/envs/SV/lib/python3.6/site-packages/pytorch_lightning/plugins/training_type/single_device.py", line 71, in setup
    self.model_to_device()
  File "/home/xwm/anaconda3/envs/SV/lib/python3.6/site-packages/pytorch_lightning/plugins/training_type/single_device.py", line 68, in model_to_device
    self._model.to(self.root_device)
  File "/home/xwm/anaconda3/envs/SV/lib/python3.6/site-packages/pytorch_lightning/core/mixins/device_dtype_mixin.py", line 111, in to
    return super().to(*args, **kwargs)
  File "/home/xwm/anaconda3/envs/SV/lib/python3.6/site-packages/torch/nn/modules/module.py", line 899, in to
    return self._apply(convert)
  File "/home/xwm/anaconda3/envs/SV/lib/python3.6/site-packages/torch/nn/modules/module.py", line 570, in _apply
    module._apply(fn)
  File "/home/xwm/anaconda3/envs/SV/lib/python3.6/site-packages/torch/nn/modules/module.py", line 570, in _apply
    module._apply(fn)
  File "/home/xwm/anaconda3/envs/SV/lib/python3.6/site-packages/torch/nn/modules/module.py", line 570, in _apply
    module._apply(fn)
  [Previous line repeated 1 more time]
  File "/home/xwm/anaconda3/envs/SV/lib/python3.6/site-packages/torch/nn/modules/module.py", line 593, in _apply
    param_applied = fn(param)
  File "/home/xwm/anaconda3/envs/SV/lib/python3.6/site-packages/torch/nn/modules/module.py", line 897, in convert
    return t.to(device, dtype if t.is_floating_point() or t.is_complex() else None, non_blocking)
RuntimeError: CUDA error: out of memory
CUDA kernel errors might be asynchronously reported at some other API call,so the stacktrace below might be incorrect.
For debugging consider passing CUDA_LAUNCH_BLOCKING=1.

Failure # 4 (occurred at 2022-06-14_23-10-52)
Traceback (most recent call last):
  File "/home/xwm/anaconda3/envs/SV/lib/python3.6/site-packages/ray/tune/trial_runner.py", line 886, in _process_trial
    results = self.trial_executor.fetch_result(trial)
  File "/home/xwm/anaconda3/envs/SV/lib/python3.6/site-packages/ray/tune/ray_trial_executor.py", line 675, in fetch_result
    result = ray.get(trial_future[0], timeout=DEFAULT_GET_TIMEOUT)
  File "/home/xwm/anaconda3/envs/SV/lib/python3.6/site-packages/ray/_private/client_mode_hook.py", line 105, in wrapper
    return func(*args, **kwargs)
  File "/home/xwm/anaconda3/envs/SV/lib/python3.6/site-packages/ray/worker.py", line 1763, in get
    raise value.as_instanceof_cause()
ray.exceptions.RayTaskError(TuneError): [36mray::ImplicitFunc.train()[39m (pid=191434, ip=192.168.249.74, repr=train_tune)
  File "/home/xwm/anaconda3/envs/SV/lib/python3.6/site-packages/ray/tune/trainable.py", line 319, in train
    result = self.step()
  File "/home/xwm/anaconda3/envs/SV/lib/python3.6/site-packages/ray/tune/function_runner.py", line 381, in step
    self._report_thread_runner_error(block=True)
  File "/home/xwm/anaconda3/envs/SV/lib/python3.6/site-packages/ray/tune/function_runner.py", line 532, in _report_thread_runner_error
    ("Trial raised an exception. Traceback:\n{}".format(err_tb_str)
ray.tune.error.TuneError: Trial raised an exception. Traceback:
[36mray::ImplicitFunc.train()[39m (pid=191434, ip=192.168.249.74, repr=train_tune)
  File "/home/xwm/anaconda3/envs/SV/lib/python3.6/site-packages/ray/tune/function_runner.py", line 262, in run
    self._entrypoint()
  File "/home/xwm/anaconda3/envs/SV/lib/python3.6/site-packages/ray/tune/function_runner.py", line 331, in entrypoint
    self._status_reporter.get_checkpoint())
  File "/home/xwm/anaconda3/envs/SV/lib/python3.6/site-packages/ray/tune/function_runner.py", line 600, in _trainable_func
    output = fn()
  File "/home/xwm/anaconda3/envs/SV/lib/python3.6/site-packages/ray/tune/utils/trainable.py", line 371, in inner
    trainable(config, **fn_kwargs)
  File "train.py", line 572, in train_tune
    trainer.fit(model)
  File "/home/xwm/anaconda3/envs/SV/lib/python3.6/site-packages/pytorch_lightning/trainer/trainer.py", line 741, in fit
    self._fit_impl, model, train_dataloaders, val_dataloaders, datamodule, ckpt_path
  File "/home/xwm/anaconda3/envs/SV/lib/python3.6/site-packages/pytorch_lightning/trainer/trainer.py", line 685, in _call_and_handle_interrupt
    return trainer_fn(*args, **kwargs)
  File "/home/xwm/anaconda3/envs/SV/lib/python3.6/site-packages/pytorch_lightning/trainer/trainer.py", line 777, in _fit_impl
    self._run(model, ckpt_path=ckpt_path)
  File "/home/xwm/anaconda3/envs/SV/lib/python3.6/site-packages/pytorch_lightning/trainer/trainer.py", line 1145, in _run
    self.accelerator.setup(self)
  File "/home/xwm/anaconda3/envs/SV/lib/python3.6/site-packages/pytorch_lightning/accelerators/gpu.py", line 46, in setup
    return super().setup(trainer)
  File "/home/xwm/anaconda3/envs/SV/lib/python3.6/site-packages/pytorch_lightning/accelerators/accelerator.py", line 91, in setup
    self.setup_training_type_plugin()
  File "/home/xwm/anaconda3/envs/SV/lib/python3.6/site-packages/pytorch_lightning/accelerators/accelerator.py", line 363, in setup_training_type_plugin
    self.training_type_plugin.setup()
  File "/home/xwm/anaconda3/envs/SV/lib/python3.6/site-packages/pytorch_lightning/plugins/training_type/single_device.py", line 71, in setup
    self.model_to_device()
  File "/home/xwm/anaconda3/envs/SV/lib/python3.6/site-packages/pytorch_lightning/plugins/training_type/single_device.py", line 68, in model_to_device
    self._model.to(self.root_device)
  File "/home/xwm/anaconda3/envs/SV/lib/python3.6/site-packages/pytorch_lightning/core/mixins/device_dtype_mixin.py", line 111, in to
    return super().to(*args, **kwargs)
  File "/home/xwm/anaconda3/envs/SV/lib/python3.6/site-packages/torch/nn/modules/module.py", line 899, in to
    return self._apply(convert)
  File "/home/xwm/anaconda3/envs/SV/lib/python3.6/site-packages/torch/nn/modules/module.py", line 570, in _apply
    module._apply(fn)
  File "/home/xwm/anaconda3/envs/SV/lib/python3.6/site-packages/torch/nn/modules/module.py", line 570, in _apply
    module._apply(fn)
  File "/home/xwm/anaconda3/envs/SV/lib/python3.6/site-packages/torch/nn/modules/module.py", line 570, in _apply
    module._apply(fn)
  [Previous line repeated 1 more time]
  File "/home/xwm/anaconda3/envs/SV/lib/python3.6/site-packages/torch/nn/modules/module.py", line 593, in _apply
    param_applied = fn(param)
  File "/home/xwm/anaconda3/envs/SV/lib/python3.6/site-packages/torch/nn/modules/module.py", line 897, in convert
    return t.to(device, dtype if t.is_floating_point() or t.is_complex() else None, non_blocking)
RuntimeError: CUDA error: out of memory
CUDA kernel errors might be asynchronously reported at some other API call,so the stacktrace below might be incorrect.
For debugging consider passing CUDA_LAUNCH_BLOCKING=1.

Failure # 5 (occurred at 2022-06-14_23-11-50)
Traceback (most recent call last):
  File "/home/xwm/anaconda3/envs/SV/lib/python3.6/site-packages/ray/tune/trial_runner.py", line 886, in _process_trial
    results = self.trial_executor.fetch_result(trial)
  File "/home/xwm/anaconda3/envs/SV/lib/python3.6/site-packages/ray/tune/ray_trial_executor.py", line 675, in fetch_result
    result = ray.get(trial_future[0], timeout=DEFAULT_GET_TIMEOUT)
  File "/home/xwm/anaconda3/envs/SV/lib/python3.6/site-packages/ray/_private/client_mode_hook.py", line 105, in wrapper
    return func(*args, **kwargs)
  File "/home/xwm/anaconda3/envs/SV/lib/python3.6/site-packages/ray/worker.py", line 1763, in get
    raise value.as_instanceof_cause()
ray.exceptions.RayTaskError(TuneError): [36mray::ImplicitFunc.train()[39m (pid=192110, ip=192.168.249.74, repr=train_tune)
  File "/home/xwm/anaconda3/envs/SV/lib/python3.6/site-packages/ray/tune/trainable.py", line 319, in train
    result = self.step()
  File "/home/xwm/anaconda3/envs/SV/lib/python3.6/site-packages/ray/tune/function_runner.py", line 381, in step
    self._report_thread_runner_error(block=True)
  File "/home/xwm/anaconda3/envs/SV/lib/python3.6/site-packages/ray/tune/function_runner.py", line 532, in _report_thread_runner_error
    ("Trial raised an exception. Traceback:\n{}".format(err_tb_str)
ray.tune.error.TuneError: Trial raised an exception. Traceback:
[36mray::ImplicitFunc.train()[39m (pid=192110, ip=192.168.249.74, repr=train_tune)
  File "/home/xwm/anaconda3/envs/SV/lib/python3.6/site-packages/ray/tune/function_runner.py", line 262, in run
    self._entrypoint()
  File "/home/xwm/anaconda3/envs/SV/lib/python3.6/site-packages/ray/tune/function_runner.py", line 331, in entrypoint
    self._status_reporter.get_checkpoint())
  File "/home/xwm/anaconda3/envs/SV/lib/python3.6/site-packages/ray/tune/function_runner.py", line 600, in _trainable_func
    output = fn()
  File "/home/xwm/anaconda3/envs/SV/lib/python3.6/site-packages/ray/tune/utils/trainable.py", line 371, in inner
    trainable(config, **fn_kwargs)
  File "train.py", line 572, in train_tune
    trainer.fit(model)
  File "/home/xwm/anaconda3/envs/SV/lib/python3.6/site-packages/pytorch_lightning/trainer/trainer.py", line 741, in fit
    self._fit_impl, model, train_dataloaders, val_dataloaders, datamodule, ckpt_path
  File "/home/xwm/anaconda3/envs/SV/lib/python3.6/site-packages/pytorch_lightning/trainer/trainer.py", line 685, in _call_and_handle_interrupt
    return trainer_fn(*args, **kwargs)
  File "/home/xwm/anaconda3/envs/SV/lib/python3.6/site-packages/pytorch_lightning/trainer/trainer.py", line 777, in _fit_impl
    self._run(model, ckpt_path=ckpt_path)
  File "/home/xwm/anaconda3/envs/SV/lib/python3.6/site-packages/pytorch_lightning/trainer/trainer.py", line 1145, in _run
    self.accelerator.setup(self)
  File "/home/xwm/anaconda3/envs/SV/lib/python3.6/site-packages/pytorch_lightning/accelerators/gpu.py", line 46, in setup
    return super().setup(trainer)
  File "/home/xwm/anaconda3/envs/SV/lib/python3.6/site-packages/pytorch_lightning/accelerators/accelerator.py", line 91, in setup
    self.setup_training_type_plugin()
  File "/home/xwm/anaconda3/envs/SV/lib/python3.6/site-packages/pytorch_lightning/accelerators/accelerator.py", line 363, in setup_training_type_plugin
    self.training_type_plugin.setup()
  File "/home/xwm/anaconda3/envs/SV/lib/python3.6/site-packages/pytorch_lightning/plugins/training_type/single_device.py", line 71, in setup
    self.model_to_device()
  File "/home/xwm/anaconda3/envs/SV/lib/python3.6/site-packages/pytorch_lightning/plugins/training_type/single_device.py", line 68, in model_to_device
    self._model.to(self.root_device)
  File "/home/xwm/anaconda3/envs/SV/lib/python3.6/site-packages/pytorch_lightning/core/mixins/device_dtype_mixin.py", line 111, in to
    return super().to(*args, **kwargs)
  File "/home/xwm/anaconda3/envs/SV/lib/python3.6/site-packages/torch/nn/modules/module.py", line 899, in to
    return self._apply(convert)
  File "/home/xwm/anaconda3/envs/SV/lib/python3.6/site-packages/torch/nn/modules/module.py", line 570, in _apply
    module._apply(fn)
  File "/home/xwm/anaconda3/envs/SV/lib/python3.6/site-packages/torch/nn/modules/module.py", line 570, in _apply
    module._apply(fn)
  File "/home/xwm/anaconda3/envs/SV/lib/python3.6/site-packages/torch/nn/modules/module.py", line 570, in _apply
    module._apply(fn)
  [Previous line repeated 1 more time]
  File "/home/xwm/anaconda3/envs/SV/lib/python3.6/site-packages/torch/nn/modules/module.py", line 593, in _apply
    param_applied = fn(param)
  File "/home/xwm/anaconda3/envs/SV/lib/python3.6/site-packages/torch/nn/modules/module.py", line 897, in convert
    return t.to(device, dtype if t.is_floating_point() or t.is_complex() else None, non_blocking)
RuntimeError: CUDA error: out of memory
CUDA kernel errors might be asynchronously reported at some other API call,so the stacktrace below might be incorrect.
For debugging consider passing CUDA_LAUNCH_BLOCKING=1.

Failure # 6 (occurred at 2022-06-14_23-12-50)
Traceback (most recent call last):
  File "/home/xwm/anaconda3/envs/SV/lib/python3.6/site-packages/ray/tune/trial_runner.py", line 886, in _process_trial
    results = self.trial_executor.fetch_result(trial)
  File "/home/xwm/anaconda3/envs/SV/lib/python3.6/site-packages/ray/tune/ray_trial_executor.py", line 675, in fetch_result
    result = ray.get(trial_future[0], timeout=DEFAULT_GET_TIMEOUT)
  File "/home/xwm/anaconda3/envs/SV/lib/python3.6/site-packages/ray/_private/client_mode_hook.py", line 105, in wrapper
    return func(*args, **kwargs)
  File "/home/xwm/anaconda3/envs/SV/lib/python3.6/site-packages/ray/worker.py", line 1763, in get
    raise value.as_instanceof_cause()
ray.exceptions.RayTaskError(TuneError): [36mray::ImplicitFunc.train()[39m (pid=192771, ip=192.168.249.74, repr=train_tune)
  File "/home/xwm/anaconda3/envs/SV/lib/python3.6/site-packages/ray/tune/trainable.py", line 319, in train
    result = self.step()
  File "/home/xwm/anaconda3/envs/SV/lib/python3.6/site-packages/ray/tune/function_runner.py", line 381, in step
    self._report_thread_runner_error(block=True)
  File "/home/xwm/anaconda3/envs/SV/lib/python3.6/site-packages/ray/tune/function_runner.py", line 532, in _report_thread_runner_error
    ("Trial raised an exception. Traceback:\n{}".format(err_tb_str)
ray.tune.error.TuneError: Trial raised an exception. Traceback:
[36mray::ImplicitFunc.train()[39m (pid=192771, ip=192.168.249.74, repr=train_tune)
  File "/home/xwm/anaconda3/envs/SV/lib/python3.6/site-packages/ray/tune/function_runner.py", line 262, in run
    self._entrypoint()
  File "/home/xwm/anaconda3/envs/SV/lib/python3.6/site-packages/ray/tune/function_runner.py", line 331, in entrypoint
    self._status_reporter.get_checkpoint())
  File "/home/xwm/anaconda3/envs/SV/lib/python3.6/site-packages/ray/tune/function_runner.py", line 600, in _trainable_func
    output = fn()
  File "/home/xwm/anaconda3/envs/SV/lib/python3.6/site-packages/ray/tune/utils/trainable.py", line 371, in inner
    trainable(config, **fn_kwargs)
  File "train.py", line 572, in train_tune
    trainer.fit(model)
  File "/home/xwm/anaconda3/envs/SV/lib/python3.6/site-packages/pytorch_lightning/trainer/trainer.py", line 741, in fit
    self._fit_impl, model, train_dataloaders, val_dataloaders, datamodule, ckpt_path
  File "/home/xwm/anaconda3/envs/SV/lib/python3.6/site-packages/pytorch_lightning/trainer/trainer.py", line 685, in _call_and_handle_interrupt
    return trainer_fn(*args, **kwargs)
  File "/home/xwm/anaconda3/envs/SV/lib/python3.6/site-packages/pytorch_lightning/trainer/trainer.py", line 777, in _fit_impl
    self._run(model, ckpt_path=ckpt_path)
  File "/home/xwm/anaconda3/envs/SV/lib/python3.6/site-packages/pytorch_lightning/trainer/trainer.py", line 1145, in _run
    self.accelerator.setup(self)
  File "/home/xwm/anaconda3/envs/SV/lib/python3.6/site-packages/pytorch_lightning/accelerators/gpu.py", line 46, in setup
    return super().setup(trainer)
  File "/home/xwm/anaconda3/envs/SV/lib/python3.6/site-packages/pytorch_lightning/accelerators/accelerator.py", line 91, in setup
    self.setup_training_type_plugin()
  File "/home/xwm/anaconda3/envs/SV/lib/python3.6/site-packages/pytorch_lightning/accelerators/accelerator.py", line 363, in setup_training_type_plugin
    self.training_type_plugin.setup()
  File "/home/xwm/anaconda3/envs/SV/lib/python3.6/site-packages/pytorch_lightning/plugins/training_type/single_device.py", line 71, in setup
    self.model_to_device()
  File "/home/xwm/anaconda3/envs/SV/lib/python3.6/site-packages/pytorch_lightning/plugins/training_type/single_device.py", line 68, in model_to_device
    self._model.to(self.root_device)
  File "/home/xwm/anaconda3/envs/SV/lib/python3.6/site-packages/pytorch_lightning/core/mixins/device_dtype_mixin.py", line 111, in to
    return super().to(*args, **kwargs)
  File "/home/xwm/anaconda3/envs/SV/lib/python3.6/site-packages/torch/nn/modules/module.py", line 899, in to
    return self._apply(convert)
  File "/home/xwm/anaconda3/envs/SV/lib/python3.6/site-packages/torch/nn/modules/module.py", line 570, in _apply
    module._apply(fn)
  File "/home/xwm/anaconda3/envs/SV/lib/python3.6/site-packages/torch/nn/modules/module.py", line 570, in _apply
    module._apply(fn)
  File "/home/xwm/anaconda3/envs/SV/lib/python3.6/site-packages/torch/nn/modules/module.py", line 570, in _apply
    module._apply(fn)
  [Previous line repeated 1 more time]
  File "/home/xwm/anaconda3/envs/SV/lib/python3.6/site-packages/torch/nn/modules/module.py", line 593, in _apply
    param_applied = fn(param)
  File "/home/xwm/anaconda3/envs/SV/lib/python3.6/site-packages/torch/nn/modules/module.py", line 897, in convert
    return t.to(device, dtype if t.is_floating_point() or t.is_complex() else None, non_blocking)
RuntimeError: CUDA error: out of memory
CUDA kernel errors might be asynchronously reported at some other API call,so the stacktrace below might be incorrect.
For debugging consider passing CUDA_LAUNCH_BLOCKING=1.

Failure # 7 (occurred at 2022-06-14_23-14-06)
Traceback (most recent call last):
  File "/home/xwm/anaconda3/envs/SV/lib/python3.6/site-packages/ray/tune/trial_runner.py", line 886, in _process_trial
    results = self.trial_executor.fetch_result(trial)
  File "/home/xwm/anaconda3/envs/SV/lib/python3.6/site-packages/ray/tune/ray_trial_executor.py", line 675, in fetch_result
    result = ray.get(trial_future[0], timeout=DEFAULT_GET_TIMEOUT)
  File "/home/xwm/anaconda3/envs/SV/lib/python3.6/site-packages/ray/_private/client_mode_hook.py", line 105, in wrapper
    return func(*args, **kwargs)
  File "/home/xwm/anaconda3/envs/SV/lib/python3.6/site-packages/ray/worker.py", line 1763, in get
    raise value.as_instanceof_cause()
ray.exceptions.RayTaskError(TuneError): [36mray::ImplicitFunc.train()[39m (pid=193404, ip=192.168.249.74, repr=train_tune)
  File "/home/xwm/anaconda3/envs/SV/lib/python3.6/site-packages/ray/tune/trainable.py", line 319, in train
    result = self.step()
  File "/home/xwm/anaconda3/envs/SV/lib/python3.6/site-packages/ray/tune/function_runner.py", line 381, in step
    self._report_thread_runner_error(block=True)
  File "/home/xwm/anaconda3/envs/SV/lib/python3.6/site-packages/ray/tune/function_runner.py", line 532, in _report_thread_runner_error
    ("Trial raised an exception. Traceback:\n{}".format(err_tb_str)
ray.tune.error.TuneError: Trial raised an exception. Traceback:
[36mray::ImplicitFunc.train()[39m (pid=193404, ip=192.168.249.74, repr=train_tune)
  File "/home/xwm/anaconda3/envs/SV/lib/python3.6/site-packages/ray/tune/function_runner.py", line 262, in run
    self._entrypoint()
  File "/home/xwm/anaconda3/envs/SV/lib/python3.6/site-packages/ray/tune/function_runner.py", line 331, in entrypoint
    self._status_reporter.get_checkpoint())
  File "/home/xwm/anaconda3/envs/SV/lib/python3.6/site-packages/ray/tune/function_runner.py", line 600, in _trainable_func
    output = fn()
  File "/home/xwm/anaconda3/envs/SV/lib/python3.6/site-packages/ray/tune/utils/trainable.py", line 371, in inner
    trainable(config, **fn_kwargs)
  File "train.py", line 572, in train_tune
    trainer.fit(model)
  File "/home/xwm/anaconda3/envs/SV/lib/python3.6/site-packages/pytorch_lightning/trainer/trainer.py", line 741, in fit
    self._fit_impl, model, train_dataloaders, val_dataloaders, datamodule, ckpt_path
  File "/home/xwm/anaconda3/envs/SV/lib/python3.6/site-packages/pytorch_lightning/trainer/trainer.py", line 685, in _call_and_handle_interrupt
    return trainer_fn(*args, **kwargs)
  File "/home/xwm/anaconda3/envs/SV/lib/python3.6/site-packages/pytorch_lightning/trainer/trainer.py", line 777, in _fit_impl
    self._run(model, ckpt_path=ckpt_path)
  File "/home/xwm/anaconda3/envs/SV/lib/python3.6/site-packages/pytorch_lightning/trainer/trainer.py", line 1145, in _run
    self.accelerator.setup(self)
  File "/home/xwm/anaconda3/envs/SV/lib/python3.6/site-packages/pytorch_lightning/accelerators/gpu.py", line 46, in setup
    return super().setup(trainer)
  File "/home/xwm/anaconda3/envs/SV/lib/python3.6/site-packages/pytorch_lightning/accelerators/accelerator.py", line 91, in setup
    self.setup_training_type_plugin()
  File "/home/xwm/anaconda3/envs/SV/lib/python3.6/site-packages/pytorch_lightning/accelerators/accelerator.py", line 363, in setup_training_type_plugin
    self.training_type_plugin.setup()
  File "/home/xwm/anaconda3/envs/SV/lib/python3.6/site-packages/pytorch_lightning/plugins/training_type/single_device.py", line 71, in setup
    self.model_to_device()
  File "/home/xwm/anaconda3/envs/SV/lib/python3.6/site-packages/pytorch_lightning/plugins/training_type/single_device.py", line 68, in model_to_device
    self._model.to(self.root_device)
  File "/home/xwm/anaconda3/envs/SV/lib/python3.6/site-packages/pytorch_lightning/core/mixins/device_dtype_mixin.py", line 111, in to
    return super().to(*args, **kwargs)
  File "/home/xwm/anaconda3/envs/SV/lib/python3.6/site-packages/torch/nn/modules/module.py", line 899, in to
    return self._apply(convert)
  File "/home/xwm/anaconda3/envs/SV/lib/python3.6/site-packages/torch/nn/modules/module.py", line 570, in _apply
    module._apply(fn)
  File "/home/xwm/anaconda3/envs/SV/lib/python3.6/site-packages/torch/nn/modules/module.py", line 570, in _apply
    module._apply(fn)
  File "/home/xwm/anaconda3/envs/SV/lib/python3.6/site-packages/torch/nn/modules/module.py", line 570, in _apply
    module._apply(fn)
  [Previous line repeated 1 more time]
  File "/home/xwm/anaconda3/envs/SV/lib/python3.6/site-packages/torch/nn/modules/module.py", line 593, in _apply
    param_applied = fn(param)
  File "/home/xwm/anaconda3/envs/SV/lib/python3.6/site-packages/torch/nn/modules/module.py", line 897, in convert
    return t.to(device, dtype if t.is_floating_point() or t.is_complex() else None, non_blocking)
RuntimeError: CUDA error: out of memory
CUDA kernel errors might be asynchronously reported at some other API call,so the stacktrace below might be incorrect.
For debugging consider passing CUDA_LAUNCH_BLOCKING=1.

Failure # 8 (occurred at 2022-06-14_23-15-25)
Traceback (most recent call last):
  File "/home/xwm/anaconda3/envs/SV/lib/python3.6/site-packages/ray/tune/trial_runner.py", line 886, in _process_trial
    results = self.trial_executor.fetch_result(trial)
  File "/home/xwm/anaconda3/envs/SV/lib/python3.6/site-packages/ray/tune/ray_trial_executor.py", line 675, in fetch_result
    result = ray.get(trial_future[0], timeout=DEFAULT_GET_TIMEOUT)
  File "/home/xwm/anaconda3/envs/SV/lib/python3.6/site-packages/ray/_private/client_mode_hook.py", line 105, in wrapper
    return func(*args, **kwargs)
  File "/home/xwm/anaconda3/envs/SV/lib/python3.6/site-packages/ray/worker.py", line 1763, in get
    raise value.as_instanceof_cause()
ray.exceptions.RayTaskError(TuneError): [36mray::ImplicitFunc.train()[39m (pid=194635, ip=192.168.249.74, repr=train_tune)
  File "/home/xwm/anaconda3/envs/SV/lib/python3.6/site-packages/ray/tune/trainable.py", line 319, in train
    result = self.step()
  File "/home/xwm/anaconda3/envs/SV/lib/python3.6/site-packages/ray/tune/function_runner.py", line 381, in step
    self._report_thread_runner_error(block=True)
  File "/home/xwm/anaconda3/envs/SV/lib/python3.6/site-packages/ray/tune/function_runner.py", line 532, in _report_thread_runner_error
    ("Trial raised an exception. Traceback:\n{}".format(err_tb_str)
ray.tune.error.TuneError: Trial raised an exception. Traceback:
[36mray::ImplicitFunc.train()[39m (pid=194635, ip=192.168.249.74, repr=train_tune)
  File "/home/xwm/anaconda3/envs/SV/lib/python3.6/site-packages/ray/tune/function_runner.py", line 262, in run
    self._entrypoint()
  File "/home/xwm/anaconda3/envs/SV/lib/python3.6/site-packages/ray/tune/function_runner.py", line 331, in entrypoint
    self._status_reporter.get_checkpoint())
  File "/home/xwm/anaconda3/envs/SV/lib/python3.6/site-packages/ray/tune/function_runner.py", line 600, in _trainable_func
    output = fn()
  File "/home/xwm/anaconda3/envs/SV/lib/python3.6/site-packages/ray/tune/utils/trainable.py", line 371, in inner
    trainable(config, **fn_kwargs)
  File "train.py", line 572, in train_tune
    trainer.fit(model)
  File "/home/xwm/anaconda3/envs/SV/lib/python3.6/site-packages/pytorch_lightning/trainer/trainer.py", line 741, in fit
    self._fit_impl, model, train_dataloaders, val_dataloaders, datamodule, ckpt_path
  File "/home/xwm/anaconda3/envs/SV/lib/python3.6/site-packages/pytorch_lightning/trainer/trainer.py", line 685, in _call_and_handle_interrupt
    return trainer_fn(*args, **kwargs)
  File "/home/xwm/anaconda3/envs/SV/lib/python3.6/site-packages/pytorch_lightning/trainer/trainer.py", line 777, in _fit_impl
    self._run(model, ckpt_path=ckpt_path)
  File "/home/xwm/anaconda3/envs/SV/lib/python3.6/site-packages/pytorch_lightning/trainer/trainer.py", line 1145, in _run
    self.accelerator.setup(self)
  File "/home/xwm/anaconda3/envs/SV/lib/python3.6/site-packages/pytorch_lightning/accelerators/gpu.py", line 46, in setup
    return super().setup(trainer)
  File "/home/xwm/anaconda3/envs/SV/lib/python3.6/site-packages/pytorch_lightning/accelerators/accelerator.py", line 91, in setup
    self.setup_training_type_plugin()
  File "/home/xwm/anaconda3/envs/SV/lib/python3.6/site-packages/pytorch_lightning/accelerators/accelerator.py", line 363, in setup_training_type_plugin
    self.training_type_plugin.setup()
  File "/home/xwm/anaconda3/envs/SV/lib/python3.6/site-packages/pytorch_lightning/plugins/training_type/single_device.py", line 71, in setup
    self.model_to_device()
  File "/home/xwm/anaconda3/envs/SV/lib/python3.6/site-packages/pytorch_lightning/plugins/training_type/single_device.py", line 68, in model_to_device
    self._model.to(self.root_device)
  File "/home/xwm/anaconda3/envs/SV/lib/python3.6/site-packages/pytorch_lightning/core/mixins/device_dtype_mixin.py", line 111, in to
    return super().to(*args, **kwargs)
  File "/home/xwm/anaconda3/envs/SV/lib/python3.6/site-packages/torch/nn/modules/module.py", line 899, in to
    return self._apply(convert)
  File "/home/xwm/anaconda3/envs/SV/lib/python3.6/site-packages/torch/nn/modules/module.py", line 570, in _apply
    module._apply(fn)
  File "/home/xwm/anaconda3/envs/SV/lib/python3.6/site-packages/torch/nn/modules/module.py", line 570, in _apply
    module._apply(fn)
  File "/home/xwm/anaconda3/envs/SV/lib/python3.6/site-packages/torch/nn/modules/module.py", line 570, in _apply
    module._apply(fn)
  [Previous line repeated 1 more time]
  File "/home/xwm/anaconda3/envs/SV/lib/python3.6/site-packages/torch/nn/modules/module.py", line 593, in _apply
    param_applied = fn(param)
  File "/home/xwm/anaconda3/envs/SV/lib/python3.6/site-packages/torch/nn/modules/module.py", line 897, in convert
    return t.to(device, dtype if t.is_floating_point() or t.is_complex() else None, non_blocking)
RuntimeError: CUDA error: out of memory
CUDA kernel errors might be asynchronously reported at some other API call,so the stacktrace below might be incorrect.
For debugging consider passing CUDA_LAUNCH_BLOCKING=1.

Failure # 9 (occurred at 2022-06-14_23-16-35)
Traceback (most recent call last):
  File "/home/xwm/anaconda3/envs/SV/lib/python3.6/site-packages/ray/tune/trial_runner.py", line 886, in _process_trial
    results = self.trial_executor.fetch_result(trial)
  File "/home/xwm/anaconda3/envs/SV/lib/python3.6/site-packages/ray/tune/ray_trial_executor.py", line 675, in fetch_result
    result = ray.get(trial_future[0], timeout=DEFAULT_GET_TIMEOUT)
  File "/home/xwm/anaconda3/envs/SV/lib/python3.6/site-packages/ray/_private/client_mode_hook.py", line 105, in wrapper
    return func(*args, **kwargs)
  File "/home/xwm/anaconda3/envs/SV/lib/python3.6/site-packages/ray/worker.py", line 1763, in get
    raise value.as_instanceof_cause()
ray.exceptions.RayTaskError(TuneError): [36mray::ImplicitFunc.train()[39m (pid=195495, ip=192.168.249.74, repr=train_tune)
  File "/home/xwm/anaconda3/envs/SV/lib/python3.6/site-packages/ray/tune/trainable.py", line 319, in train
    result = self.step()
  File "/home/xwm/anaconda3/envs/SV/lib/python3.6/site-packages/ray/tune/function_runner.py", line 381, in step
    self._report_thread_runner_error(block=True)
  File "/home/xwm/anaconda3/envs/SV/lib/python3.6/site-packages/ray/tune/function_runner.py", line 532, in _report_thread_runner_error
    ("Trial raised an exception. Traceback:\n{}".format(err_tb_str)
ray.tune.error.TuneError: Trial raised an exception. Traceback:
[36mray::ImplicitFunc.train()[39m (pid=195495, ip=192.168.249.74, repr=train_tune)
  File "/home/xwm/anaconda3/envs/SV/lib/python3.6/site-packages/ray/tune/function_runner.py", line 262, in run
    self._entrypoint()
  File "/home/xwm/anaconda3/envs/SV/lib/python3.6/site-packages/ray/tune/function_runner.py", line 331, in entrypoint
    self._status_reporter.get_checkpoint())
  File "/home/xwm/anaconda3/envs/SV/lib/python3.6/site-packages/ray/tune/function_runner.py", line 600, in _trainable_func
    output = fn()
  File "/home/xwm/anaconda3/envs/SV/lib/python3.6/site-packages/ray/tune/utils/trainable.py", line 371, in inner
    trainable(config, **fn_kwargs)
  File "train.py", line 572, in train_tune
    trainer.fit(model)
  File "/home/xwm/anaconda3/envs/SV/lib/python3.6/site-packages/pytorch_lightning/trainer/trainer.py", line 741, in fit
    self._fit_impl, model, train_dataloaders, val_dataloaders, datamodule, ckpt_path
  File "/home/xwm/anaconda3/envs/SV/lib/python3.6/site-packages/pytorch_lightning/trainer/trainer.py", line 685, in _call_and_handle_interrupt
    return trainer_fn(*args, **kwargs)
  File "/home/xwm/anaconda3/envs/SV/lib/python3.6/site-packages/pytorch_lightning/trainer/trainer.py", line 777, in _fit_impl
    self._run(model, ckpt_path=ckpt_path)
  File "/home/xwm/anaconda3/envs/SV/lib/python3.6/site-packages/pytorch_lightning/trainer/trainer.py", line 1145, in _run
    self.accelerator.setup(self)
  File "/home/xwm/anaconda3/envs/SV/lib/python3.6/site-packages/pytorch_lightning/accelerators/gpu.py", line 46, in setup
    return super().setup(trainer)
  File "/home/xwm/anaconda3/envs/SV/lib/python3.6/site-packages/pytorch_lightning/accelerators/accelerator.py", line 91, in setup
    self.setup_training_type_plugin()
  File "/home/xwm/anaconda3/envs/SV/lib/python3.6/site-packages/pytorch_lightning/accelerators/accelerator.py", line 363, in setup_training_type_plugin
    self.training_type_plugin.setup()
  File "/home/xwm/anaconda3/envs/SV/lib/python3.6/site-packages/pytorch_lightning/plugins/training_type/single_device.py", line 71, in setup
    self.model_to_device()
  File "/home/xwm/anaconda3/envs/SV/lib/python3.6/site-packages/pytorch_lightning/plugins/training_type/single_device.py", line 68, in model_to_device
    self._model.to(self.root_device)
  File "/home/xwm/anaconda3/envs/SV/lib/python3.6/site-packages/pytorch_lightning/core/mixins/device_dtype_mixin.py", line 111, in to
    return super().to(*args, **kwargs)
  File "/home/xwm/anaconda3/envs/SV/lib/python3.6/site-packages/torch/nn/modules/module.py", line 899, in to
    return self._apply(convert)
  File "/home/xwm/anaconda3/envs/SV/lib/python3.6/site-packages/torch/nn/modules/module.py", line 570, in _apply
    module._apply(fn)
  File "/home/xwm/anaconda3/envs/SV/lib/python3.6/site-packages/torch/nn/modules/module.py", line 570, in _apply
    module._apply(fn)
  File "/home/xwm/anaconda3/envs/SV/lib/python3.6/site-packages/torch/nn/modules/module.py", line 570, in _apply
    module._apply(fn)
  [Previous line repeated 1 more time]
  File "/home/xwm/anaconda3/envs/SV/lib/python3.6/site-packages/torch/nn/modules/module.py", line 593, in _apply
    param_applied = fn(param)
  File "/home/xwm/anaconda3/envs/SV/lib/python3.6/site-packages/torch/nn/modules/module.py", line 897, in convert
    return t.to(device, dtype if t.is_floating_point() or t.is_complex() else None, non_blocking)
RuntimeError: CUDA error: out of memory
CUDA kernel errors might be asynchronously reported at some other API call,so the stacktrace below might be incorrect.
For debugging consider passing CUDA_LAUNCH_BLOCKING=1.

Failure # 10 (occurred at 2022-06-14_23-17-47)
Traceback (most recent call last):
  File "/home/xwm/anaconda3/envs/SV/lib/python3.6/site-packages/ray/tune/trial_runner.py", line 886, in _process_trial
    results = self.trial_executor.fetch_result(trial)
  File "/home/xwm/anaconda3/envs/SV/lib/python3.6/site-packages/ray/tune/ray_trial_executor.py", line 675, in fetch_result
    result = ray.get(trial_future[0], timeout=DEFAULT_GET_TIMEOUT)
  File "/home/xwm/anaconda3/envs/SV/lib/python3.6/site-packages/ray/_private/client_mode_hook.py", line 105, in wrapper
    return func(*args, **kwargs)
  File "/home/xwm/anaconda3/envs/SV/lib/python3.6/site-packages/ray/worker.py", line 1763, in get
    raise value.as_instanceof_cause()
ray.exceptions.RayTaskError(TuneError): [36mray::ImplicitFunc.train()[39m (pid=196279, ip=192.168.249.74, repr=train_tune)
  File "/home/xwm/anaconda3/envs/SV/lib/python3.6/site-packages/ray/tune/trainable.py", line 319, in train
    result = self.step()
  File "/home/xwm/anaconda3/envs/SV/lib/python3.6/site-packages/ray/tune/function_runner.py", line 381, in step
    self._report_thread_runner_error(block=True)
  File "/home/xwm/anaconda3/envs/SV/lib/python3.6/site-packages/ray/tune/function_runner.py", line 532, in _report_thread_runner_error
    ("Trial raised an exception. Traceback:\n{}".format(err_tb_str)
ray.tune.error.TuneError: Trial raised an exception. Traceback:
[36mray::ImplicitFunc.train()[39m (pid=196279, ip=192.168.249.74, repr=train_tune)
  File "/home/xwm/anaconda3/envs/SV/lib/python3.6/site-packages/ray/tune/function_runner.py", line 262, in run
    self._entrypoint()
  File "/home/xwm/anaconda3/envs/SV/lib/python3.6/site-packages/ray/tune/function_runner.py", line 331, in entrypoint
    self._status_reporter.get_checkpoint())
  File "/home/xwm/anaconda3/envs/SV/lib/python3.6/site-packages/ray/tune/function_runner.py", line 600, in _trainable_func
    output = fn()
  File "/home/xwm/anaconda3/envs/SV/lib/python3.6/site-packages/ray/tune/utils/trainable.py", line 371, in inner
    trainable(config, **fn_kwargs)
  File "train.py", line 572, in train_tune
    trainer.fit(model)
  File "/home/xwm/anaconda3/envs/SV/lib/python3.6/site-packages/pytorch_lightning/trainer/trainer.py", line 741, in fit
    self._fit_impl, model, train_dataloaders, val_dataloaders, datamodule, ckpt_path
  File "/home/xwm/anaconda3/envs/SV/lib/python3.6/site-packages/pytorch_lightning/trainer/trainer.py", line 685, in _call_and_handle_interrupt
    return trainer_fn(*args, **kwargs)
  File "/home/xwm/anaconda3/envs/SV/lib/python3.6/site-packages/pytorch_lightning/trainer/trainer.py", line 777, in _fit_impl
    self._run(model, ckpt_path=ckpt_path)
  File "/home/xwm/anaconda3/envs/SV/lib/python3.6/site-packages/pytorch_lightning/trainer/trainer.py", line 1145, in _run
    self.accelerator.setup(self)
  File "/home/xwm/anaconda3/envs/SV/lib/python3.6/site-packages/pytorch_lightning/accelerators/gpu.py", line 46, in setup
    return super().setup(trainer)
  File "/home/xwm/anaconda3/envs/SV/lib/python3.6/site-packages/pytorch_lightning/accelerators/accelerator.py", line 91, in setup
    self.setup_training_type_plugin()
  File "/home/xwm/anaconda3/envs/SV/lib/python3.6/site-packages/pytorch_lightning/accelerators/accelerator.py", line 363, in setup_training_type_plugin
    self.training_type_plugin.setup()
  File "/home/xwm/anaconda3/envs/SV/lib/python3.6/site-packages/pytorch_lightning/plugins/training_type/single_device.py", line 71, in setup
    self.model_to_device()
  File "/home/xwm/anaconda3/envs/SV/lib/python3.6/site-packages/pytorch_lightning/plugins/training_type/single_device.py", line 68, in model_to_device
    self._model.to(self.root_device)
  File "/home/xwm/anaconda3/envs/SV/lib/python3.6/site-packages/pytorch_lightning/core/mixins/device_dtype_mixin.py", line 111, in to
    return super().to(*args, **kwargs)
  File "/home/xwm/anaconda3/envs/SV/lib/python3.6/site-packages/torch/nn/modules/module.py", line 899, in to
    return self._apply(convert)
  File "/home/xwm/anaconda3/envs/SV/lib/python3.6/site-packages/torch/nn/modules/module.py", line 570, in _apply
    module._apply(fn)
  File "/home/xwm/anaconda3/envs/SV/lib/python3.6/site-packages/torch/nn/modules/module.py", line 570, in _apply
    module._apply(fn)
  File "/home/xwm/anaconda3/envs/SV/lib/python3.6/site-packages/torch/nn/modules/module.py", line 570, in _apply
    module._apply(fn)
  [Previous line repeated 1 more time]
  File "/home/xwm/anaconda3/envs/SV/lib/python3.6/site-packages/torch/nn/modules/module.py", line 593, in _apply
    param_applied = fn(param)
  File "/home/xwm/anaconda3/envs/SV/lib/python3.6/site-packages/torch/nn/modules/module.py", line 897, in convert
    return t.to(device, dtype if t.is_floating_point() or t.is_complex() else None, non_blocking)
RuntimeError: CUDA error: out of memory
CUDA kernel errors might be asynchronously reported at some other API call,so the stacktrace below might be incorrect.
For debugging consider passing CUDA_LAUNCH_BLOCKING=1.

Failure # 11 (occurred at 2022-06-14_23-18-50)
Traceback (most recent call last):
  File "/home/xwm/anaconda3/envs/SV/lib/python3.6/site-packages/ray/tune/trial_runner.py", line 886, in _process_trial
    results = self.trial_executor.fetch_result(trial)
  File "/home/xwm/anaconda3/envs/SV/lib/python3.6/site-packages/ray/tune/ray_trial_executor.py", line 675, in fetch_result
    result = ray.get(trial_future[0], timeout=DEFAULT_GET_TIMEOUT)
  File "/home/xwm/anaconda3/envs/SV/lib/python3.6/site-packages/ray/_private/client_mode_hook.py", line 105, in wrapper
    return func(*args, **kwargs)
  File "/home/xwm/anaconda3/envs/SV/lib/python3.6/site-packages/ray/worker.py", line 1763, in get
    raise value.as_instanceof_cause()
ray.exceptions.RayTaskError(TuneError): [36mray::ImplicitFunc.train()[39m (pid=196634, ip=192.168.249.74, repr=train_tune)
  File "/home/xwm/anaconda3/envs/SV/lib/python3.6/site-packages/ray/tune/trainable.py", line 319, in train
    result = self.step()
  File "/home/xwm/anaconda3/envs/SV/lib/python3.6/site-packages/ray/tune/function_runner.py", line 381, in step
    self._report_thread_runner_error(block=True)
  File "/home/xwm/anaconda3/envs/SV/lib/python3.6/site-packages/ray/tune/function_runner.py", line 532, in _report_thread_runner_error
    ("Trial raised an exception. Traceback:\n{}".format(err_tb_str)
ray.tune.error.TuneError: Trial raised an exception. Traceback:
[36mray::ImplicitFunc.train()[39m (pid=196634, ip=192.168.249.74, repr=train_tune)
  File "/home/xwm/anaconda3/envs/SV/lib/python3.6/site-packages/ray/tune/function_runner.py", line 262, in run
    self._entrypoint()
  File "/home/xwm/anaconda3/envs/SV/lib/python3.6/site-packages/ray/tune/function_runner.py", line 331, in entrypoint
    self._status_reporter.get_checkpoint())
  File "/home/xwm/anaconda3/envs/SV/lib/python3.6/site-packages/ray/tune/function_runner.py", line 600, in _trainable_func
    output = fn()
  File "/home/xwm/anaconda3/envs/SV/lib/python3.6/site-packages/ray/tune/utils/trainable.py", line 371, in inner
    trainable(config, **fn_kwargs)
  File "train.py", line 572, in train_tune
    trainer.fit(model)
  File "/home/xwm/anaconda3/envs/SV/lib/python3.6/site-packages/pytorch_lightning/trainer/trainer.py", line 741, in fit
    self._fit_impl, model, train_dataloaders, val_dataloaders, datamodule, ckpt_path
  File "/home/xwm/anaconda3/envs/SV/lib/python3.6/site-packages/pytorch_lightning/trainer/trainer.py", line 685, in _call_and_handle_interrupt
    return trainer_fn(*args, **kwargs)
  File "/home/xwm/anaconda3/envs/SV/lib/python3.6/site-packages/pytorch_lightning/trainer/trainer.py", line 777, in _fit_impl
    self._run(model, ckpt_path=ckpt_path)
  File "/home/xwm/anaconda3/envs/SV/lib/python3.6/site-packages/pytorch_lightning/trainer/trainer.py", line 1145, in _run
    self.accelerator.setup(self)
  File "/home/xwm/anaconda3/envs/SV/lib/python3.6/site-packages/pytorch_lightning/accelerators/gpu.py", line 46, in setup
    return super().setup(trainer)
  File "/home/xwm/anaconda3/envs/SV/lib/python3.6/site-packages/pytorch_lightning/accelerators/accelerator.py", line 91, in setup
    self.setup_training_type_plugin()
  File "/home/xwm/anaconda3/envs/SV/lib/python3.6/site-packages/pytorch_lightning/accelerators/accelerator.py", line 363, in setup_training_type_plugin
    self.training_type_plugin.setup()
  File "/home/xwm/anaconda3/envs/SV/lib/python3.6/site-packages/pytorch_lightning/plugins/training_type/single_device.py", line 71, in setup
    self.model_to_device()
  File "/home/xwm/anaconda3/envs/SV/lib/python3.6/site-packages/pytorch_lightning/plugins/training_type/single_device.py", line 68, in model_to_device
    self._model.to(self.root_device)
  File "/home/xwm/anaconda3/envs/SV/lib/python3.6/site-packages/pytorch_lightning/core/mixins/device_dtype_mixin.py", line 111, in to
    return super().to(*args, **kwargs)
  File "/home/xwm/anaconda3/envs/SV/lib/python3.6/site-packages/torch/nn/modules/module.py", line 899, in to
    return self._apply(convert)
  File "/home/xwm/anaconda3/envs/SV/lib/python3.6/site-packages/torch/nn/modules/module.py", line 570, in _apply
    module._apply(fn)
  File "/home/xwm/anaconda3/envs/SV/lib/python3.6/site-packages/torch/nn/modules/module.py", line 570, in _apply
    module._apply(fn)
  File "/home/xwm/anaconda3/envs/SV/lib/python3.6/site-packages/torch/nn/modules/module.py", line 570, in _apply
    module._apply(fn)
  [Previous line repeated 1 more time]
  File "/home/xwm/anaconda3/envs/SV/lib/python3.6/site-packages/torch/nn/modules/module.py", line 593, in _apply
    param_applied = fn(param)
  File "/home/xwm/anaconda3/envs/SV/lib/python3.6/site-packages/torch/nn/modules/module.py", line 897, in convert
    return t.to(device, dtype if t.is_floating_point() or t.is_complex() else None, non_blocking)
RuntimeError: CUDA error: out of memory
CUDA kernel errors might be asynchronously reported at some other API call,so the stacktrace below might be incorrect.
For debugging consider passing CUDA_LAUNCH_BLOCKING=1.

Failure # 12 (occurred at 2022-06-14_23-19-55)
Traceback (most recent call last):
  File "/home/xwm/anaconda3/envs/SV/lib/python3.6/site-packages/ray/tune/trial_runner.py", line 886, in _process_trial
    results = self.trial_executor.fetch_result(trial)
  File "/home/xwm/anaconda3/envs/SV/lib/python3.6/site-packages/ray/tune/ray_trial_executor.py", line 675, in fetch_result
    result = ray.get(trial_future[0], timeout=DEFAULT_GET_TIMEOUT)
  File "/home/xwm/anaconda3/envs/SV/lib/python3.6/site-packages/ray/_private/client_mode_hook.py", line 105, in wrapper
    return func(*args, **kwargs)
  File "/home/xwm/anaconda3/envs/SV/lib/python3.6/site-packages/ray/worker.py", line 1763, in get
    raise value.as_instanceof_cause()
ray.exceptions.RayTaskError(TuneError): [36mray::ImplicitFunc.train()[39m (pid=197704, ip=192.168.249.74, repr=train_tune)
  File "/home/xwm/anaconda3/envs/SV/lib/python3.6/site-packages/ray/tune/trainable.py", line 319, in train
    result = self.step()
  File "/home/xwm/anaconda3/envs/SV/lib/python3.6/site-packages/ray/tune/function_runner.py", line 381, in step
    self._report_thread_runner_error(block=True)
  File "/home/xwm/anaconda3/envs/SV/lib/python3.6/site-packages/ray/tune/function_runner.py", line 532, in _report_thread_runner_error
    ("Trial raised an exception. Traceback:\n{}".format(err_tb_str)
ray.tune.error.TuneError: Trial raised an exception. Traceback:
[36mray::ImplicitFunc.train()[39m (pid=197704, ip=192.168.249.74, repr=train_tune)
  File "/home/xwm/anaconda3/envs/SV/lib/python3.6/site-packages/ray/tune/function_runner.py", line 262, in run
    self._entrypoint()
  File "/home/xwm/anaconda3/envs/SV/lib/python3.6/site-packages/ray/tune/function_runner.py", line 331, in entrypoint
    self._status_reporter.get_checkpoint())
  File "/home/xwm/anaconda3/envs/SV/lib/python3.6/site-packages/ray/tune/function_runner.py", line 600, in _trainable_func
    output = fn()
  File "/home/xwm/anaconda3/envs/SV/lib/python3.6/site-packages/ray/tune/utils/trainable.py", line 371, in inner
    trainable(config, **fn_kwargs)
  File "train.py", line 572, in train_tune
    trainer.fit(model)
  File "/home/xwm/anaconda3/envs/SV/lib/python3.6/site-packages/pytorch_lightning/trainer/trainer.py", line 741, in fit
    self._fit_impl, model, train_dataloaders, val_dataloaders, datamodule, ckpt_path
  File "/home/xwm/anaconda3/envs/SV/lib/python3.6/site-packages/pytorch_lightning/trainer/trainer.py", line 685, in _call_and_handle_interrupt
    return trainer_fn(*args, **kwargs)
  File "/home/xwm/anaconda3/envs/SV/lib/python3.6/site-packages/pytorch_lightning/trainer/trainer.py", line 777, in _fit_impl
    self._run(model, ckpt_path=ckpt_path)
  File "/home/xwm/anaconda3/envs/SV/lib/python3.6/site-packages/pytorch_lightning/trainer/trainer.py", line 1145, in _run
    self.accelerator.setup(self)
  File "/home/xwm/anaconda3/envs/SV/lib/python3.6/site-packages/pytorch_lightning/accelerators/gpu.py", line 46, in setup
    return super().setup(trainer)
  File "/home/xwm/anaconda3/envs/SV/lib/python3.6/site-packages/pytorch_lightning/accelerators/accelerator.py", line 91, in setup
    self.setup_training_type_plugin()
  File "/home/xwm/anaconda3/envs/SV/lib/python3.6/site-packages/pytorch_lightning/accelerators/accelerator.py", line 363, in setup_training_type_plugin
    self.training_type_plugin.setup()
  File "/home/xwm/anaconda3/envs/SV/lib/python3.6/site-packages/pytorch_lightning/plugins/training_type/single_device.py", line 71, in setup
    self.model_to_device()
  File "/home/xwm/anaconda3/envs/SV/lib/python3.6/site-packages/pytorch_lightning/plugins/training_type/single_device.py", line 68, in model_to_device
    self._model.to(self.root_device)
  File "/home/xwm/anaconda3/envs/SV/lib/python3.6/site-packages/pytorch_lightning/core/mixins/device_dtype_mixin.py", line 111, in to
    return super().to(*args, **kwargs)
  File "/home/xwm/anaconda3/envs/SV/lib/python3.6/site-packages/torch/nn/modules/module.py", line 899, in to
    return self._apply(convert)
  File "/home/xwm/anaconda3/envs/SV/lib/python3.6/site-packages/torch/nn/modules/module.py", line 570, in _apply
    module._apply(fn)
  File "/home/xwm/anaconda3/envs/SV/lib/python3.6/site-packages/torch/nn/modules/module.py", line 570, in _apply
    module._apply(fn)
  File "/home/xwm/anaconda3/envs/SV/lib/python3.6/site-packages/torch/nn/modules/module.py", line 570, in _apply
    module._apply(fn)
  [Previous line repeated 1 more time]
  File "/home/xwm/anaconda3/envs/SV/lib/python3.6/site-packages/torch/nn/modules/module.py", line 593, in _apply
    param_applied = fn(param)
  File "/home/xwm/anaconda3/envs/SV/lib/python3.6/site-packages/torch/nn/modules/module.py", line 897, in convert
    return t.to(device, dtype if t.is_floating_point() or t.is_complex() else None, non_blocking)
RuntimeError: CUDA error: out of memory
CUDA kernel errors might be asynchronously reported at some other API call,so the stacktrace below might be incorrect.
For debugging consider passing CUDA_LAUNCH_BLOCKING=1.

Failure # 13 (occurred at 2022-06-14_23-20-57)
Traceback (most recent call last):
  File "/home/xwm/anaconda3/envs/SV/lib/python3.6/site-packages/ray/tune/trial_runner.py", line 886, in _process_trial
    results = self.trial_executor.fetch_result(trial)
  File "/home/xwm/anaconda3/envs/SV/lib/python3.6/site-packages/ray/tune/ray_trial_executor.py", line 675, in fetch_result
    result = ray.get(trial_future[0], timeout=DEFAULT_GET_TIMEOUT)
  File "/home/xwm/anaconda3/envs/SV/lib/python3.6/site-packages/ray/_private/client_mode_hook.py", line 105, in wrapper
    return func(*args, **kwargs)
  File "/home/xwm/anaconda3/envs/SV/lib/python3.6/site-packages/ray/worker.py", line 1763, in get
    raise value.as_instanceof_cause()
ray.exceptions.RayTaskError(TuneError): [36mray::ImplicitFunc.train()[39m (pid=198397, ip=192.168.249.74, repr=train_tune)
  File "/home/xwm/anaconda3/envs/SV/lib/python3.6/site-packages/ray/tune/trainable.py", line 319, in train
    result = self.step()
  File "/home/xwm/anaconda3/envs/SV/lib/python3.6/site-packages/ray/tune/function_runner.py", line 381, in step
    self._report_thread_runner_error(block=True)
  File "/home/xwm/anaconda3/envs/SV/lib/python3.6/site-packages/ray/tune/function_runner.py", line 532, in _report_thread_runner_error
    ("Trial raised an exception. Traceback:\n{}".format(err_tb_str)
ray.tune.error.TuneError: Trial raised an exception. Traceback:
[36mray::ImplicitFunc.train()[39m (pid=198397, ip=192.168.249.74, repr=train_tune)
  File "/home/xwm/anaconda3/envs/SV/lib/python3.6/site-packages/ray/tune/function_runner.py", line 262, in run
    self._entrypoint()
  File "/home/xwm/anaconda3/envs/SV/lib/python3.6/site-packages/ray/tune/function_runner.py", line 331, in entrypoint
    self._status_reporter.get_checkpoint())
  File "/home/xwm/anaconda3/envs/SV/lib/python3.6/site-packages/ray/tune/function_runner.py", line 600, in _trainable_func
    output = fn()
  File "/home/xwm/anaconda3/envs/SV/lib/python3.6/site-packages/ray/tune/utils/trainable.py", line 371, in inner
    trainable(config, **fn_kwargs)
  File "train.py", line 572, in train_tune
    trainer.fit(model)
  File "/home/xwm/anaconda3/envs/SV/lib/python3.6/site-packages/pytorch_lightning/trainer/trainer.py", line 741, in fit
    self._fit_impl, model, train_dataloaders, val_dataloaders, datamodule, ckpt_path
  File "/home/xwm/anaconda3/envs/SV/lib/python3.6/site-packages/pytorch_lightning/trainer/trainer.py", line 685, in _call_and_handle_interrupt
    return trainer_fn(*args, **kwargs)
  File "/home/xwm/anaconda3/envs/SV/lib/python3.6/site-packages/pytorch_lightning/trainer/trainer.py", line 777, in _fit_impl
    self._run(model, ckpt_path=ckpt_path)
  File "/home/xwm/anaconda3/envs/SV/lib/python3.6/site-packages/pytorch_lightning/trainer/trainer.py", line 1145, in _run
    self.accelerator.setup(self)
  File "/home/xwm/anaconda3/envs/SV/lib/python3.6/site-packages/pytorch_lightning/accelerators/gpu.py", line 46, in setup
    return super().setup(trainer)
  File "/home/xwm/anaconda3/envs/SV/lib/python3.6/site-packages/pytorch_lightning/accelerators/accelerator.py", line 91, in setup
    self.setup_training_type_plugin()
  File "/home/xwm/anaconda3/envs/SV/lib/python3.6/site-packages/pytorch_lightning/accelerators/accelerator.py", line 363, in setup_training_type_plugin
    self.training_type_plugin.setup()
  File "/home/xwm/anaconda3/envs/SV/lib/python3.6/site-packages/pytorch_lightning/plugins/training_type/single_device.py", line 71, in setup
    self.model_to_device()
  File "/home/xwm/anaconda3/envs/SV/lib/python3.6/site-packages/pytorch_lightning/plugins/training_type/single_device.py", line 68, in model_to_device
    self._model.to(self.root_device)
  File "/home/xwm/anaconda3/envs/SV/lib/python3.6/site-packages/pytorch_lightning/core/mixins/device_dtype_mixin.py", line 111, in to
    return super().to(*args, **kwargs)
  File "/home/xwm/anaconda3/envs/SV/lib/python3.6/site-packages/torch/nn/modules/module.py", line 899, in to
    return self._apply(convert)
  File "/home/xwm/anaconda3/envs/SV/lib/python3.6/site-packages/torch/nn/modules/module.py", line 570, in _apply
    module._apply(fn)
  File "/home/xwm/anaconda3/envs/SV/lib/python3.6/site-packages/torch/nn/modules/module.py", line 570, in _apply
    module._apply(fn)
  File "/home/xwm/anaconda3/envs/SV/lib/python3.6/site-packages/torch/nn/modules/module.py", line 570, in _apply
    module._apply(fn)
  [Previous line repeated 1 more time]
  File "/home/xwm/anaconda3/envs/SV/lib/python3.6/site-packages/torch/nn/modules/module.py", line 593, in _apply
    param_applied = fn(param)
  File "/home/xwm/anaconda3/envs/SV/lib/python3.6/site-packages/torch/nn/modules/module.py", line 897, in convert
    return t.to(device, dtype if t.is_floating_point() or t.is_complex() else None, non_blocking)
RuntimeError: CUDA error: out of memory
CUDA kernel errors might be asynchronously reported at some other API call,so the stacktrace below might be incorrect.
For debugging consider passing CUDA_LAUNCH_BLOCKING=1.

Failure # 14 (occurred at 2022-06-14_23-22-01)
Traceback (most recent call last):
  File "/home/xwm/anaconda3/envs/SV/lib/python3.6/site-packages/ray/tune/trial_runner.py", line 886, in _process_trial
    results = self.trial_executor.fetch_result(trial)
  File "/home/xwm/anaconda3/envs/SV/lib/python3.6/site-packages/ray/tune/ray_trial_executor.py", line 675, in fetch_result
    result = ray.get(trial_future[0], timeout=DEFAULT_GET_TIMEOUT)
  File "/home/xwm/anaconda3/envs/SV/lib/python3.6/site-packages/ray/_private/client_mode_hook.py", line 105, in wrapper
    return func(*args, **kwargs)
  File "/home/xwm/anaconda3/envs/SV/lib/python3.6/site-packages/ray/worker.py", line 1763, in get
    raise value.as_instanceof_cause()
ray.exceptions.RayTaskError(TuneError): [36mray::ImplicitFunc.train()[39m (pid=199344, ip=192.168.249.74, repr=train_tune)
  File "/home/xwm/anaconda3/envs/SV/lib/python3.6/site-packages/ray/tune/trainable.py", line 319, in train
    result = self.step()
  File "/home/xwm/anaconda3/envs/SV/lib/python3.6/site-packages/ray/tune/function_runner.py", line 381, in step
    self._report_thread_runner_error(block=True)
  File "/home/xwm/anaconda3/envs/SV/lib/python3.6/site-packages/ray/tune/function_runner.py", line 532, in _report_thread_runner_error
    ("Trial raised an exception. Traceback:\n{}".format(err_tb_str)
ray.tune.error.TuneError: Trial raised an exception. Traceback:
[36mray::ImplicitFunc.train()[39m (pid=199344, ip=192.168.249.74, repr=train_tune)
  File "/home/xwm/anaconda3/envs/SV/lib/python3.6/site-packages/ray/tune/function_runner.py", line 262, in run
    self._entrypoint()
  File "/home/xwm/anaconda3/envs/SV/lib/python3.6/site-packages/ray/tune/function_runner.py", line 331, in entrypoint
    self._status_reporter.get_checkpoint())
  File "/home/xwm/anaconda3/envs/SV/lib/python3.6/site-packages/ray/tune/function_runner.py", line 600, in _trainable_func
    output = fn()
  File "/home/xwm/anaconda3/envs/SV/lib/python3.6/site-packages/ray/tune/utils/trainable.py", line 371, in inner
    trainable(config, **fn_kwargs)
  File "train.py", line 572, in train_tune
    trainer.fit(model)
  File "/home/xwm/anaconda3/envs/SV/lib/python3.6/site-packages/pytorch_lightning/trainer/trainer.py", line 741, in fit
    self._fit_impl, model, train_dataloaders, val_dataloaders, datamodule, ckpt_path
  File "/home/xwm/anaconda3/envs/SV/lib/python3.6/site-packages/pytorch_lightning/trainer/trainer.py", line 685, in _call_and_handle_interrupt
    return trainer_fn(*args, **kwargs)
  File "/home/xwm/anaconda3/envs/SV/lib/python3.6/site-packages/pytorch_lightning/trainer/trainer.py", line 777, in _fit_impl
    self._run(model, ckpt_path=ckpt_path)
  File "/home/xwm/anaconda3/envs/SV/lib/python3.6/site-packages/pytorch_lightning/trainer/trainer.py", line 1145, in _run
    self.accelerator.setup(self)
  File "/home/xwm/anaconda3/envs/SV/lib/python3.6/site-packages/pytorch_lightning/accelerators/gpu.py", line 46, in setup
    return super().setup(trainer)
  File "/home/xwm/anaconda3/envs/SV/lib/python3.6/site-packages/pytorch_lightning/accelerators/accelerator.py", line 91, in setup
    self.setup_training_type_plugin()
  File "/home/xwm/anaconda3/envs/SV/lib/python3.6/site-packages/pytorch_lightning/accelerators/accelerator.py", line 363, in setup_training_type_plugin
    self.training_type_plugin.setup()
  File "/home/xwm/anaconda3/envs/SV/lib/python3.6/site-packages/pytorch_lightning/plugins/training_type/single_device.py", line 71, in setup
    self.model_to_device()
  File "/home/xwm/anaconda3/envs/SV/lib/python3.6/site-packages/pytorch_lightning/plugins/training_type/single_device.py", line 68, in model_to_device
    self._model.to(self.root_device)
  File "/home/xwm/anaconda3/envs/SV/lib/python3.6/site-packages/pytorch_lightning/core/mixins/device_dtype_mixin.py", line 111, in to
    return super().to(*args, **kwargs)
  File "/home/xwm/anaconda3/envs/SV/lib/python3.6/site-packages/torch/nn/modules/module.py", line 899, in to
    return self._apply(convert)
  File "/home/xwm/anaconda3/envs/SV/lib/python3.6/site-packages/torch/nn/modules/module.py", line 570, in _apply
    module._apply(fn)
  File "/home/xwm/anaconda3/envs/SV/lib/python3.6/site-packages/torch/nn/modules/module.py", line 570, in _apply
    module._apply(fn)
  File "/home/xwm/anaconda3/envs/SV/lib/python3.6/site-packages/torch/nn/modules/module.py", line 570, in _apply
    module._apply(fn)
  [Previous line repeated 1 more time]
  File "/home/xwm/anaconda3/envs/SV/lib/python3.6/site-packages/torch/nn/modules/module.py", line 593, in _apply
    param_applied = fn(param)
  File "/home/xwm/anaconda3/envs/SV/lib/python3.6/site-packages/torch/nn/modules/module.py", line 897, in convert
    return t.to(device, dtype if t.is_floating_point() or t.is_complex() else None, non_blocking)
RuntimeError: CUDA error: out of memory
CUDA kernel errors might be asynchronously reported at some other API call,so the stacktrace below might be incorrect.
For debugging consider passing CUDA_LAUNCH_BLOCKING=1.

Failure # 15 (occurred at 2022-06-14_23-22-59)
Traceback (most recent call last):
  File "/home/xwm/anaconda3/envs/SV/lib/python3.6/site-packages/ray/tune/trial_runner.py", line 886, in _process_trial
    results = self.trial_executor.fetch_result(trial)
  File "/home/xwm/anaconda3/envs/SV/lib/python3.6/site-packages/ray/tune/ray_trial_executor.py", line 675, in fetch_result
    result = ray.get(trial_future[0], timeout=DEFAULT_GET_TIMEOUT)
  File "/home/xwm/anaconda3/envs/SV/lib/python3.6/site-packages/ray/_private/client_mode_hook.py", line 105, in wrapper
    return func(*args, **kwargs)
  File "/home/xwm/anaconda3/envs/SV/lib/python3.6/site-packages/ray/worker.py", line 1763, in get
    raise value.as_instanceof_cause()
ray.exceptions.RayTaskError(TuneError): [36mray::ImplicitFunc.train()[39m (pid=199779, ip=192.168.249.74, repr=train_tune)
  File "/home/xwm/anaconda3/envs/SV/lib/python3.6/site-packages/ray/tune/trainable.py", line 319, in train
    result = self.step()
  File "/home/xwm/anaconda3/envs/SV/lib/python3.6/site-packages/ray/tune/function_runner.py", line 381, in step
    self._report_thread_runner_error(block=True)
  File "/home/xwm/anaconda3/envs/SV/lib/python3.6/site-packages/ray/tune/function_runner.py", line 532, in _report_thread_runner_error
    ("Trial raised an exception. Traceback:\n{}".format(err_tb_str)
ray.tune.error.TuneError: Trial raised an exception. Traceback:
[36mray::ImplicitFunc.train()[39m (pid=199779, ip=192.168.249.74, repr=train_tune)
  File "/home/xwm/anaconda3/envs/SV/lib/python3.6/site-packages/ray/tune/function_runner.py", line 262, in run
    self._entrypoint()
  File "/home/xwm/anaconda3/envs/SV/lib/python3.6/site-packages/ray/tune/function_runner.py", line 331, in entrypoint
    self._status_reporter.get_checkpoint())
  File "/home/xwm/anaconda3/envs/SV/lib/python3.6/site-packages/ray/tune/function_runner.py", line 600, in _trainable_func
    output = fn()
  File "/home/xwm/anaconda3/envs/SV/lib/python3.6/site-packages/ray/tune/utils/trainable.py", line 371, in inner
    trainable(config, **fn_kwargs)
  File "train.py", line 572, in train_tune
    trainer.fit(model)
  File "/home/xwm/anaconda3/envs/SV/lib/python3.6/site-packages/pytorch_lightning/trainer/trainer.py", line 741, in fit
    self._fit_impl, model, train_dataloaders, val_dataloaders, datamodule, ckpt_path
  File "/home/xwm/anaconda3/envs/SV/lib/python3.6/site-packages/pytorch_lightning/trainer/trainer.py", line 685, in _call_and_handle_interrupt
    return trainer_fn(*args, **kwargs)
  File "/home/xwm/anaconda3/envs/SV/lib/python3.6/site-packages/pytorch_lightning/trainer/trainer.py", line 777, in _fit_impl
    self._run(model, ckpt_path=ckpt_path)
  File "/home/xwm/anaconda3/envs/SV/lib/python3.6/site-packages/pytorch_lightning/trainer/trainer.py", line 1145, in _run
    self.accelerator.setup(self)
  File "/home/xwm/anaconda3/envs/SV/lib/python3.6/site-packages/pytorch_lightning/accelerators/gpu.py", line 46, in setup
    return super().setup(trainer)
  File "/home/xwm/anaconda3/envs/SV/lib/python3.6/site-packages/pytorch_lightning/accelerators/accelerator.py", line 91, in setup
    self.setup_training_type_plugin()
  File "/home/xwm/anaconda3/envs/SV/lib/python3.6/site-packages/pytorch_lightning/accelerators/accelerator.py", line 363, in setup_training_type_plugin
    self.training_type_plugin.setup()
  File "/home/xwm/anaconda3/envs/SV/lib/python3.6/site-packages/pytorch_lightning/plugins/training_type/single_device.py", line 71, in setup
    self.model_to_device()
  File "/home/xwm/anaconda3/envs/SV/lib/python3.6/site-packages/pytorch_lightning/plugins/training_type/single_device.py", line 68, in model_to_device
    self._model.to(self.root_device)
  File "/home/xwm/anaconda3/envs/SV/lib/python3.6/site-packages/pytorch_lightning/core/mixins/device_dtype_mixin.py", line 111, in to
    return super().to(*args, **kwargs)
  File "/home/xwm/anaconda3/envs/SV/lib/python3.6/site-packages/torch/nn/modules/module.py", line 899, in to
    return self._apply(convert)
  File "/home/xwm/anaconda3/envs/SV/lib/python3.6/site-packages/torch/nn/modules/module.py", line 570, in _apply
    module._apply(fn)
  File "/home/xwm/anaconda3/envs/SV/lib/python3.6/site-packages/torch/nn/modules/module.py", line 570, in _apply
    module._apply(fn)
  File "/home/xwm/anaconda3/envs/SV/lib/python3.6/site-packages/torch/nn/modules/module.py", line 570, in _apply
    module._apply(fn)
  [Previous line repeated 1 more time]
  File "/home/xwm/anaconda3/envs/SV/lib/python3.6/site-packages/torch/nn/modules/module.py", line 593, in _apply
    param_applied = fn(param)
  File "/home/xwm/anaconda3/envs/SV/lib/python3.6/site-packages/torch/nn/modules/module.py", line 897, in convert
    return t.to(device, dtype if t.is_floating_point() or t.is_complex() else None, non_blocking)
RuntimeError: CUDA error: out of memory
CUDA kernel errors might be asynchronously reported at some other API call,so the stacktrace below might be incorrect.
For debugging consider passing CUDA_LAUNCH_BLOCKING=1.

Failure # 16 (occurred at 2022-06-14_23-24-01)
Traceback (most recent call last):
  File "/home/xwm/anaconda3/envs/SV/lib/python3.6/site-packages/ray/tune/trial_runner.py", line 886, in _process_trial
    results = self.trial_executor.fetch_result(trial)
  File "/home/xwm/anaconda3/envs/SV/lib/python3.6/site-packages/ray/tune/ray_trial_executor.py", line 675, in fetch_result
    result = ray.get(trial_future[0], timeout=DEFAULT_GET_TIMEOUT)
  File "/home/xwm/anaconda3/envs/SV/lib/python3.6/site-packages/ray/_private/client_mode_hook.py", line 105, in wrapper
    return func(*args, **kwargs)
  File "/home/xwm/anaconda3/envs/SV/lib/python3.6/site-packages/ray/worker.py", line 1763, in get
    raise value.as_instanceof_cause()
ray.exceptions.RayTaskError(TuneError): [36mray::ImplicitFunc.train()[39m (pid=200434, ip=192.168.249.74, repr=train_tune)
  File "/home/xwm/anaconda3/envs/SV/lib/python3.6/site-packages/ray/tune/trainable.py", line 319, in train
    result = self.step()
  File "/home/xwm/anaconda3/envs/SV/lib/python3.6/site-packages/ray/tune/function_runner.py", line 381, in step
    self._report_thread_runner_error(block=True)
  File "/home/xwm/anaconda3/envs/SV/lib/python3.6/site-packages/ray/tune/function_runner.py", line 532, in _report_thread_runner_error
    ("Trial raised an exception. Traceback:\n{}".format(err_tb_str)
ray.tune.error.TuneError: Trial raised an exception. Traceback:
[36mray::ImplicitFunc.train()[39m (pid=200434, ip=192.168.249.74, repr=train_tune)
  File "/home/xwm/anaconda3/envs/SV/lib/python3.6/site-packages/ray/tune/function_runner.py", line 262, in run
    self._entrypoint()
  File "/home/xwm/anaconda3/envs/SV/lib/python3.6/site-packages/ray/tune/function_runner.py", line 331, in entrypoint
    self._status_reporter.get_checkpoint())
  File "/home/xwm/anaconda3/envs/SV/lib/python3.6/site-packages/ray/tune/function_runner.py", line 600, in _trainable_func
    output = fn()
  File "/home/xwm/anaconda3/envs/SV/lib/python3.6/site-packages/ray/tune/utils/trainable.py", line 371, in inner
    trainable(config, **fn_kwargs)
  File "train.py", line 572, in train_tune
    trainer.fit(model)
  File "/home/xwm/anaconda3/envs/SV/lib/python3.6/site-packages/pytorch_lightning/trainer/trainer.py", line 741, in fit
    self._fit_impl, model, train_dataloaders, val_dataloaders, datamodule, ckpt_path
  File "/home/xwm/anaconda3/envs/SV/lib/python3.6/site-packages/pytorch_lightning/trainer/trainer.py", line 685, in _call_and_handle_interrupt
    return trainer_fn(*args, **kwargs)
  File "/home/xwm/anaconda3/envs/SV/lib/python3.6/site-packages/pytorch_lightning/trainer/trainer.py", line 777, in _fit_impl
    self._run(model, ckpt_path=ckpt_path)
  File "/home/xwm/anaconda3/envs/SV/lib/python3.6/site-packages/pytorch_lightning/trainer/trainer.py", line 1145, in _run
    self.accelerator.setup(self)
  File "/home/xwm/anaconda3/envs/SV/lib/python3.6/site-packages/pytorch_lightning/accelerators/gpu.py", line 46, in setup
    return super().setup(trainer)
  File "/home/xwm/anaconda3/envs/SV/lib/python3.6/site-packages/pytorch_lightning/accelerators/accelerator.py", line 91, in setup
    self.setup_training_type_plugin()
  File "/home/xwm/anaconda3/envs/SV/lib/python3.6/site-packages/pytorch_lightning/accelerators/accelerator.py", line 363, in setup_training_type_plugin
    self.training_type_plugin.setup()
  File "/home/xwm/anaconda3/envs/SV/lib/python3.6/site-packages/pytorch_lightning/plugins/training_type/single_device.py", line 71, in setup
    self.model_to_device()
  File "/home/xwm/anaconda3/envs/SV/lib/python3.6/site-packages/pytorch_lightning/plugins/training_type/single_device.py", line 68, in model_to_device
    self._model.to(self.root_device)
  File "/home/xwm/anaconda3/envs/SV/lib/python3.6/site-packages/pytorch_lightning/core/mixins/device_dtype_mixin.py", line 111, in to
    return super().to(*args, **kwargs)
  File "/home/xwm/anaconda3/envs/SV/lib/python3.6/site-packages/torch/nn/modules/module.py", line 899, in to
    return self._apply(convert)
  File "/home/xwm/anaconda3/envs/SV/lib/python3.6/site-packages/torch/nn/modules/module.py", line 570, in _apply
    module._apply(fn)
  File "/home/xwm/anaconda3/envs/SV/lib/python3.6/site-packages/torch/nn/modules/module.py", line 570, in _apply
    module._apply(fn)
  File "/home/xwm/anaconda3/envs/SV/lib/python3.6/site-packages/torch/nn/modules/module.py", line 570, in _apply
    module._apply(fn)
  [Previous line repeated 1 more time]
  File "/home/xwm/anaconda3/envs/SV/lib/python3.6/site-packages/torch/nn/modules/module.py", line 593, in _apply
    param_applied = fn(param)
  File "/home/xwm/anaconda3/envs/SV/lib/python3.6/site-packages/torch/nn/modules/module.py", line 897, in convert
    return t.to(device, dtype if t.is_floating_point() or t.is_complex() else None, non_blocking)
RuntimeError: CUDA error: out of memory
CUDA kernel errors might be asynchronously reported at some other API call,so the stacktrace below might be incorrect.
For debugging consider passing CUDA_LAUNCH_BLOCKING=1.

Failure # 17 (occurred at 2022-06-14_23-25-05)
Traceback (most recent call last):
  File "/home/xwm/anaconda3/envs/SV/lib/python3.6/site-packages/ray/tune/trial_runner.py", line 886, in _process_trial
    results = self.trial_executor.fetch_result(trial)
  File "/home/xwm/anaconda3/envs/SV/lib/python3.6/site-packages/ray/tune/ray_trial_executor.py", line 675, in fetch_result
    result = ray.get(trial_future[0], timeout=DEFAULT_GET_TIMEOUT)
  File "/home/xwm/anaconda3/envs/SV/lib/python3.6/site-packages/ray/_private/client_mode_hook.py", line 105, in wrapper
    return func(*args, **kwargs)
  File "/home/xwm/anaconda3/envs/SV/lib/python3.6/site-packages/ray/worker.py", line 1763, in get
    raise value.as_instanceof_cause()
ray.exceptions.RayTaskError(TuneError): [36mray::ImplicitFunc.train()[39m (pid=201488, ip=192.168.249.74, repr=train_tune)
  File "/home/xwm/anaconda3/envs/SV/lib/python3.6/site-packages/ray/tune/trainable.py", line 319, in train
    result = self.step()
  File "/home/xwm/anaconda3/envs/SV/lib/python3.6/site-packages/ray/tune/function_runner.py", line 381, in step
    self._report_thread_runner_error(block=True)
  File "/home/xwm/anaconda3/envs/SV/lib/python3.6/site-packages/ray/tune/function_runner.py", line 532, in _report_thread_runner_error
    ("Trial raised an exception. Traceback:\n{}".format(err_tb_str)
ray.tune.error.TuneError: Trial raised an exception. Traceback:
[36mray::ImplicitFunc.train()[39m (pid=201488, ip=192.168.249.74, repr=train_tune)
  File "/home/xwm/anaconda3/envs/SV/lib/python3.6/site-packages/ray/tune/function_runner.py", line 262, in run
    self._entrypoint()
  File "/home/xwm/anaconda3/envs/SV/lib/python3.6/site-packages/ray/tune/function_runner.py", line 331, in entrypoint
    self._status_reporter.get_checkpoint())
  File "/home/xwm/anaconda3/envs/SV/lib/python3.6/site-packages/ray/tune/function_runner.py", line 600, in _trainable_func
    output = fn()
  File "/home/xwm/anaconda3/envs/SV/lib/python3.6/site-packages/ray/tune/utils/trainable.py", line 371, in inner
    trainable(config, **fn_kwargs)
  File "train.py", line 572, in train_tune
    trainer.fit(model)
  File "/home/xwm/anaconda3/envs/SV/lib/python3.6/site-packages/pytorch_lightning/trainer/trainer.py", line 741, in fit
    self._fit_impl, model, train_dataloaders, val_dataloaders, datamodule, ckpt_path
  File "/home/xwm/anaconda3/envs/SV/lib/python3.6/site-packages/pytorch_lightning/trainer/trainer.py", line 685, in _call_and_handle_interrupt
    return trainer_fn(*args, **kwargs)
  File "/home/xwm/anaconda3/envs/SV/lib/python3.6/site-packages/pytorch_lightning/trainer/trainer.py", line 777, in _fit_impl
    self._run(model, ckpt_path=ckpt_path)
  File "/home/xwm/anaconda3/envs/SV/lib/python3.6/site-packages/pytorch_lightning/trainer/trainer.py", line 1145, in _run
    self.accelerator.setup(self)
  File "/home/xwm/anaconda3/envs/SV/lib/python3.6/site-packages/pytorch_lightning/accelerators/gpu.py", line 46, in setup
    return super().setup(trainer)
  File "/home/xwm/anaconda3/envs/SV/lib/python3.6/site-packages/pytorch_lightning/accelerators/accelerator.py", line 91, in setup
    self.setup_training_type_plugin()
  File "/home/xwm/anaconda3/envs/SV/lib/python3.6/site-packages/pytorch_lightning/accelerators/accelerator.py", line 363, in setup_training_type_plugin
    self.training_type_plugin.setup()
  File "/home/xwm/anaconda3/envs/SV/lib/python3.6/site-packages/pytorch_lightning/plugins/training_type/single_device.py", line 71, in setup
    self.model_to_device()
  File "/home/xwm/anaconda3/envs/SV/lib/python3.6/site-packages/pytorch_lightning/plugins/training_type/single_device.py", line 68, in model_to_device
    self._model.to(self.root_device)
  File "/home/xwm/anaconda3/envs/SV/lib/python3.6/site-packages/pytorch_lightning/core/mixins/device_dtype_mixin.py", line 111, in to
    return super().to(*args, **kwargs)
  File "/home/xwm/anaconda3/envs/SV/lib/python3.6/site-packages/torch/nn/modules/module.py", line 899, in to
    return self._apply(convert)
  File "/home/xwm/anaconda3/envs/SV/lib/python3.6/site-packages/torch/nn/modules/module.py", line 570, in _apply
    module._apply(fn)
  File "/home/xwm/anaconda3/envs/SV/lib/python3.6/site-packages/torch/nn/modules/module.py", line 570, in _apply
    module._apply(fn)
  File "/home/xwm/anaconda3/envs/SV/lib/python3.6/site-packages/torch/nn/modules/module.py", line 570, in _apply
    module._apply(fn)
  [Previous line repeated 1 more time]
  File "/home/xwm/anaconda3/envs/SV/lib/python3.6/site-packages/torch/nn/modules/module.py", line 593, in _apply
    param_applied = fn(param)
  File "/home/xwm/anaconda3/envs/SV/lib/python3.6/site-packages/torch/nn/modules/module.py", line 897, in convert
    return t.to(device, dtype if t.is_floating_point() or t.is_complex() else None, non_blocking)
RuntimeError: CUDA error: out of memory
CUDA kernel errors might be asynchronously reported at some other API call,so the stacktrace below might be incorrect.
For debugging consider passing CUDA_LAUNCH_BLOCKING=1.

Failure # 18 (occurred at 2022-06-14_23-26-06)
Traceback (most recent call last):
  File "/home/xwm/anaconda3/envs/SV/lib/python3.6/site-packages/ray/tune/trial_runner.py", line 886, in _process_trial
    results = self.trial_executor.fetch_result(trial)
  File "/home/xwm/anaconda3/envs/SV/lib/python3.6/site-packages/ray/tune/ray_trial_executor.py", line 675, in fetch_result
    result = ray.get(trial_future[0], timeout=DEFAULT_GET_TIMEOUT)
  File "/home/xwm/anaconda3/envs/SV/lib/python3.6/site-packages/ray/_private/client_mode_hook.py", line 105, in wrapper
    return func(*args, **kwargs)
  File "/home/xwm/anaconda3/envs/SV/lib/python3.6/site-packages/ray/worker.py", line 1763, in get
    raise value.as_instanceof_cause()
ray.exceptions.RayTaskError(TuneError): [36mray::ImplicitFunc.train()[39m (pid=201928, ip=192.168.249.74, repr=train_tune)
  File "/home/xwm/anaconda3/envs/SV/lib/python3.6/site-packages/ray/tune/trainable.py", line 319, in train
    result = self.step()
  File "/home/xwm/anaconda3/envs/SV/lib/python3.6/site-packages/ray/tune/function_runner.py", line 381, in step
    self._report_thread_runner_error(block=True)
  File "/home/xwm/anaconda3/envs/SV/lib/python3.6/site-packages/ray/tune/function_runner.py", line 532, in _report_thread_runner_error
    ("Trial raised an exception. Traceback:\n{}".format(err_tb_str)
ray.tune.error.TuneError: Trial raised an exception. Traceback:
[36mray::ImplicitFunc.train()[39m (pid=201928, ip=192.168.249.74, repr=train_tune)
  File "/home/xwm/anaconda3/envs/SV/lib/python3.6/site-packages/ray/tune/function_runner.py", line 262, in run
    self._entrypoint()
  File "/home/xwm/anaconda3/envs/SV/lib/python3.6/site-packages/ray/tune/function_runner.py", line 331, in entrypoint
    self._status_reporter.get_checkpoint())
  File "/home/xwm/anaconda3/envs/SV/lib/python3.6/site-packages/ray/tune/function_runner.py", line 600, in _trainable_func
    output = fn()
  File "/home/xwm/anaconda3/envs/SV/lib/python3.6/site-packages/ray/tune/utils/trainable.py", line 371, in inner
    trainable(config, **fn_kwargs)
  File "train.py", line 572, in train_tune
    trainer.fit(model)
  File "/home/xwm/anaconda3/envs/SV/lib/python3.6/site-packages/pytorch_lightning/trainer/trainer.py", line 741, in fit
    self._fit_impl, model, train_dataloaders, val_dataloaders, datamodule, ckpt_path
  File "/home/xwm/anaconda3/envs/SV/lib/python3.6/site-packages/pytorch_lightning/trainer/trainer.py", line 685, in _call_and_handle_interrupt
    return trainer_fn(*args, **kwargs)
  File "/home/xwm/anaconda3/envs/SV/lib/python3.6/site-packages/pytorch_lightning/trainer/trainer.py", line 777, in _fit_impl
    self._run(model, ckpt_path=ckpt_path)
  File "/home/xwm/anaconda3/envs/SV/lib/python3.6/site-packages/pytorch_lightning/trainer/trainer.py", line 1145, in _run
    self.accelerator.setup(self)
  File "/home/xwm/anaconda3/envs/SV/lib/python3.6/site-packages/pytorch_lightning/accelerators/gpu.py", line 46, in setup
    return super().setup(trainer)
  File "/home/xwm/anaconda3/envs/SV/lib/python3.6/site-packages/pytorch_lightning/accelerators/accelerator.py", line 91, in setup
    self.setup_training_type_plugin()
  File "/home/xwm/anaconda3/envs/SV/lib/python3.6/site-packages/pytorch_lightning/accelerators/accelerator.py", line 363, in setup_training_type_plugin
    self.training_type_plugin.setup()
  File "/home/xwm/anaconda3/envs/SV/lib/python3.6/site-packages/pytorch_lightning/plugins/training_type/single_device.py", line 71, in setup
    self.model_to_device()
  File "/home/xwm/anaconda3/envs/SV/lib/python3.6/site-packages/pytorch_lightning/plugins/training_type/single_device.py", line 68, in model_to_device
    self._model.to(self.root_device)
  File "/home/xwm/anaconda3/envs/SV/lib/python3.6/site-packages/pytorch_lightning/core/mixins/device_dtype_mixin.py", line 111, in to
    return super().to(*args, **kwargs)
  File "/home/xwm/anaconda3/envs/SV/lib/python3.6/site-packages/torch/nn/modules/module.py", line 899, in to
    return self._apply(convert)
  File "/home/xwm/anaconda3/envs/SV/lib/python3.6/site-packages/torch/nn/modules/module.py", line 570, in _apply
    module._apply(fn)
  File "/home/xwm/anaconda3/envs/SV/lib/python3.6/site-packages/torch/nn/modules/module.py", line 570, in _apply
    module._apply(fn)
  File "/home/xwm/anaconda3/envs/SV/lib/python3.6/site-packages/torch/nn/modules/module.py", line 570, in _apply
    module._apply(fn)
  [Previous line repeated 1 more time]
  File "/home/xwm/anaconda3/envs/SV/lib/python3.6/site-packages/torch/nn/modules/module.py", line 593, in _apply
    param_applied = fn(param)
  File "/home/xwm/anaconda3/envs/SV/lib/python3.6/site-packages/torch/nn/modules/module.py", line 897, in convert
    return t.to(device, dtype if t.is_floating_point() or t.is_complex() else None, non_blocking)
RuntimeError: CUDA error: out of memory
CUDA kernel errors might be asynchronously reported at some other API call,so the stacktrace below might be incorrect.
For debugging consider passing CUDA_LAUNCH_BLOCKING=1.

Failure # 19 (occurred at 2022-06-14_23-27-11)
Traceback (most recent call last):
  File "/home/xwm/anaconda3/envs/SV/lib/python3.6/site-packages/ray/tune/trial_runner.py", line 886, in _process_trial
    results = self.trial_executor.fetch_result(trial)
  File "/home/xwm/anaconda3/envs/SV/lib/python3.6/site-packages/ray/tune/ray_trial_executor.py", line 675, in fetch_result
    result = ray.get(trial_future[0], timeout=DEFAULT_GET_TIMEOUT)
  File "/home/xwm/anaconda3/envs/SV/lib/python3.6/site-packages/ray/_private/client_mode_hook.py", line 105, in wrapper
    return func(*args, **kwargs)
  File "/home/xwm/anaconda3/envs/SV/lib/python3.6/site-packages/ray/worker.py", line 1763, in get
    raise value.as_instanceof_cause()
ray.exceptions.RayTaskError(TuneError): [36mray::ImplicitFunc.train()[39m (pid=203189, ip=192.168.249.74, repr=train_tune)
  File "/home/xwm/anaconda3/envs/SV/lib/python3.6/site-packages/ray/tune/trainable.py", line 319, in train
    result = self.step()
  File "/home/xwm/anaconda3/envs/SV/lib/python3.6/site-packages/ray/tune/function_runner.py", line 381, in step
    self._report_thread_runner_error(block=True)
  File "/home/xwm/anaconda3/envs/SV/lib/python3.6/site-packages/ray/tune/function_runner.py", line 532, in _report_thread_runner_error
    ("Trial raised an exception. Traceback:\n{}".format(err_tb_str)
ray.tune.error.TuneError: Trial raised an exception. Traceback:
[36mray::ImplicitFunc.train()[39m (pid=203189, ip=192.168.249.74, repr=train_tune)
  File "/home/xwm/anaconda3/envs/SV/lib/python3.6/site-packages/ray/tune/function_runner.py", line 262, in run
    self._entrypoint()
  File "/home/xwm/anaconda3/envs/SV/lib/python3.6/site-packages/ray/tune/function_runner.py", line 331, in entrypoint
    self._status_reporter.get_checkpoint())
  File "/home/xwm/anaconda3/envs/SV/lib/python3.6/site-packages/ray/tune/function_runner.py", line 600, in _trainable_func
    output = fn()
  File "/home/xwm/anaconda3/envs/SV/lib/python3.6/site-packages/ray/tune/utils/trainable.py", line 371, in inner
    trainable(config, **fn_kwargs)
  File "train.py", line 572, in train_tune
    trainer.fit(model)
  File "/home/xwm/anaconda3/envs/SV/lib/python3.6/site-packages/pytorch_lightning/trainer/trainer.py", line 741, in fit
    self._fit_impl, model, train_dataloaders, val_dataloaders, datamodule, ckpt_path
  File "/home/xwm/anaconda3/envs/SV/lib/python3.6/site-packages/pytorch_lightning/trainer/trainer.py", line 685, in _call_and_handle_interrupt
    return trainer_fn(*args, **kwargs)
  File "/home/xwm/anaconda3/envs/SV/lib/python3.6/site-packages/pytorch_lightning/trainer/trainer.py", line 777, in _fit_impl
    self._run(model, ckpt_path=ckpt_path)
  File "/home/xwm/anaconda3/envs/SV/lib/python3.6/site-packages/pytorch_lightning/trainer/trainer.py", line 1145, in _run
    self.accelerator.setup(self)
  File "/home/xwm/anaconda3/envs/SV/lib/python3.6/site-packages/pytorch_lightning/accelerators/gpu.py", line 46, in setup
    return super().setup(trainer)
  File "/home/xwm/anaconda3/envs/SV/lib/python3.6/site-packages/pytorch_lightning/accelerators/accelerator.py", line 91, in setup
    self.setup_training_type_plugin()
  File "/home/xwm/anaconda3/envs/SV/lib/python3.6/site-packages/pytorch_lightning/accelerators/accelerator.py", line 363, in setup_training_type_plugin
    self.training_type_plugin.setup()
  File "/home/xwm/anaconda3/envs/SV/lib/python3.6/site-packages/pytorch_lightning/plugins/training_type/single_device.py", line 71, in setup
    self.model_to_device()
  File "/home/xwm/anaconda3/envs/SV/lib/python3.6/site-packages/pytorch_lightning/plugins/training_type/single_device.py", line 68, in model_to_device
    self._model.to(self.root_device)
  File "/home/xwm/anaconda3/envs/SV/lib/python3.6/site-packages/pytorch_lightning/core/mixins/device_dtype_mixin.py", line 111, in to
    return super().to(*args, **kwargs)
  File "/home/xwm/anaconda3/envs/SV/lib/python3.6/site-packages/torch/nn/modules/module.py", line 899, in to
    return self._apply(convert)
  File "/home/xwm/anaconda3/envs/SV/lib/python3.6/site-packages/torch/nn/modules/module.py", line 570, in _apply
    module._apply(fn)
  File "/home/xwm/anaconda3/envs/SV/lib/python3.6/site-packages/torch/nn/modules/module.py", line 570, in _apply
    module._apply(fn)
  File "/home/xwm/anaconda3/envs/SV/lib/python3.6/site-packages/torch/nn/modules/module.py", line 570, in _apply
    module._apply(fn)
  [Previous line repeated 1 more time]
  File "/home/xwm/anaconda3/envs/SV/lib/python3.6/site-packages/torch/nn/modules/module.py", line 593, in _apply
    param_applied = fn(param)
  File "/home/xwm/anaconda3/envs/SV/lib/python3.6/site-packages/torch/nn/modules/module.py", line 897, in convert
    return t.to(device, dtype if t.is_floating_point() or t.is_complex() else None, non_blocking)
RuntimeError: CUDA error: out of memory
CUDA kernel errors might be asynchronously reported at some other API call,so the stacktrace below might be incorrect.
For debugging consider passing CUDA_LAUNCH_BLOCKING=1.

Failure # 20 (occurred at 2022-06-14_23-28-09)
Traceback (most recent call last):
  File "/home/xwm/anaconda3/envs/SV/lib/python3.6/site-packages/ray/tune/trial_runner.py", line 886, in _process_trial
    results = self.trial_executor.fetch_result(trial)
  File "/home/xwm/anaconda3/envs/SV/lib/python3.6/site-packages/ray/tune/ray_trial_executor.py", line 675, in fetch_result
    result = ray.get(trial_future[0], timeout=DEFAULT_GET_TIMEOUT)
  File "/home/xwm/anaconda3/envs/SV/lib/python3.6/site-packages/ray/_private/client_mode_hook.py", line 105, in wrapper
    return func(*args, **kwargs)
  File "/home/xwm/anaconda3/envs/SV/lib/python3.6/site-packages/ray/worker.py", line 1763, in get
    raise value.as_instanceof_cause()
ray.exceptions.RayTaskError(TuneError): [36mray::ImplicitFunc.train()[39m (pid=203666, ip=192.168.249.74, repr=train_tune)
  File "/home/xwm/anaconda3/envs/SV/lib/python3.6/site-packages/ray/tune/trainable.py", line 319, in train
    result = self.step()
  File "/home/xwm/anaconda3/envs/SV/lib/python3.6/site-packages/ray/tune/function_runner.py", line 381, in step
    self._report_thread_runner_error(block=True)
  File "/home/xwm/anaconda3/envs/SV/lib/python3.6/site-packages/ray/tune/function_runner.py", line 532, in _report_thread_runner_error
    ("Trial raised an exception. Traceback:\n{}".format(err_tb_str)
ray.tune.error.TuneError: Trial raised an exception. Traceback:
[36mray::ImplicitFunc.train()[39m (pid=203666, ip=192.168.249.74, repr=train_tune)
  File "/home/xwm/anaconda3/envs/SV/lib/python3.6/site-packages/ray/tune/function_runner.py", line 262, in run
    self._entrypoint()
  File "/home/xwm/anaconda3/envs/SV/lib/python3.6/site-packages/ray/tune/function_runner.py", line 331, in entrypoint
    self._status_reporter.get_checkpoint())
  File "/home/xwm/anaconda3/envs/SV/lib/python3.6/site-packages/ray/tune/function_runner.py", line 600, in _trainable_func
    output = fn()
  File "/home/xwm/anaconda3/envs/SV/lib/python3.6/site-packages/ray/tune/utils/trainable.py", line 371, in inner
    trainable(config, **fn_kwargs)
  File "train.py", line 572, in train_tune
    trainer.fit(model)
  File "/home/xwm/anaconda3/envs/SV/lib/python3.6/site-packages/pytorch_lightning/trainer/trainer.py", line 741, in fit
    self._fit_impl, model, train_dataloaders, val_dataloaders, datamodule, ckpt_path
  File "/home/xwm/anaconda3/envs/SV/lib/python3.6/site-packages/pytorch_lightning/trainer/trainer.py", line 685, in _call_and_handle_interrupt
    return trainer_fn(*args, **kwargs)
  File "/home/xwm/anaconda3/envs/SV/lib/python3.6/site-packages/pytorch_lightning/trainer/trainer.py", line 777, in _fit_impl
    self._run(model, ckpt_path=ckpt_path)
  File "/home/xwm/anaconda3/envs/SV/lib/python3.6/site-packages/pytorch_lightning/trainer/trainer.py", line 1145, in _run
    self.accelerator.setup(self)
  File "/home/xwm/anaconda3/envs/SV/lib/python3.6/site-packages/pytorch_lightning/accelerators/gpu.py", line 46, in setup
    return super().setup(trainer)
  File "/home/xwm/anaconda3/envs/SV/lib/python3.6/site-packages/pytorch_lightning/accelerators/accelerator.py", line 91, in setup
    self.setup_training_type_plugin()
  File "/home/xwm/anaconda3/envs/SV/lib/python3.6/site-packages/pytorch_lightning/accelerators/accelerator.py", line 363, in setup_training_type_plugin
    self.training_type_plugin.setup()
  File "/home/xwm/anaconda3/envs/SV/lib/python3.6/site-packages/pytorch_lightning/plugins/training_type/single_device.py", line 71, in setup
    self.model_to_device()
  File "/home/xwm/anaconda3/envs/SV/lib/python3.6/site-packages/pytorch_lightning/plugins/training_type/single_device.py", line 68, in model_to_device
    self._model.to(self.root_device)
  File "/home/xwm/anaconda3/envs/SV/lib/python3.6/site-packages/pytorch_lightning/core/mixins/device_dtype_mixin.py", line 111, in to
    return super().to(*args, **kwargs)
  File "/home/xwm/anaconda3/envs/SV/lib/python3.6/site-packages/torch/nn/modules/module.py", line 899, in to
    return self._apply(convert)
  File "/home/xwm/anaconda3/envs/SV/lib/python3.6/site-packages/torch/nn/modules/module.py", line 570, in _apply
    module._apply(fn)
  File "/home/xwm/anaconda3/envs/SV/lib/python3.6/site-packages/torch/nn/modules/module.py", line 570, in _apply
    module._apply(fn)
  File "/home/xwm/anaconda3/envs/SV/lib/python3.6/site-packages/torch/nn/modules/module.py", line 570, in _apply
    module._apply(fn)
  [Previous line repeated 1 more time]
  File "/home/xwm/anaconda3/envs/SV/lib/python3.6/site-packages/torch/nn/modules/module.py", line 593, in _apply
    param_applied = fn(param)
  File "/home/xwm/anaconda3/envs/SV/lib/python3.6/site-packages/torch/nn/modules/module.py", line 897, in convert
    return t.to(device, dtype if t.is_floating_point() or t.is_complex() else None, non_blocking)
RuntimeError: CUDA error: out of memory
CUDA kernel errors might be asynchronously reported at some other API call,so the stacktrace below might be incorrect.
For debugging consider passing CUDA_LAUNCH_BLOCKING=1.

Failure # 21 (occurred at 2022-06-14_23-29-12)
Traceback (most recent call last):
  File "/home/xwm/anaconda3/envs/SV/lib/python3.6/site-packages/ray/tune/trial_runner.py", line 886, in _process_trial
    results = self.trial_executor.fetch_result(trial)
  File "/home/xwm/anaconda3/envs/SV/lib/python3.6/site-packages/ray/tune/ray_trial_executor.py", line 675, in fetch_result
    result = ray.get(trial_future[0], timeout=DEFAULT_GET_TIMEOUT)
  File "/home/xwm/anaconda3/envs/SV/lib/python3.6/site-packages/ray/_private/client_mode_hook.py", line 105, in wrapper
    return func(*args, **kwargs)
  File "/home/xwm/anaconda3/envs/SV/lib/python3.6/site-packages/ray/worker.py", line 1763, in get
    raise value.as_instanceof_cause()
ray.exceptions.RayTaskError(TuneError): [36mray::ImplicitFunc.train()[39m (pid=204913, ip=192.168.249.74, repr=train_tune)
  File "/home/xwm/anaconda3/envs/SV/lib/python3.6/site-packages/ray/tune/trainable.py", line 319, in train
    result = self.step()
  File "/home/xwm/anaconda3/envs/SV/lib/python3.6/site-packages/ray/tune/function_runner.py", line 381, in step
    self._report_thread_runner_error(block=True)
  File "/home/xwm/anaconda3/envs/SV/lib/python3.6/site-packages/ray/tune/function_runner.py", line 532, in _report_thread_runner_error
    ("Trial raised an exception. Traceback:\n{}".format(err_tb_str)
ray.tune.error.TuneError: Trial raised an exception. Traceback:
[36mray::ImplicitFunc.train()[39m (pid=204913, ip=192.168.249.74, repr=train_tune)
  File "/home/xwm/anaconda3/envs/SV/lib/python3.6/site-packages/ray/tune/function_runner.py", line 262, in run
    self._entrypoint()
  File "/home/xwm/anaconda3/envs/SV/lib/python3.6/site-packages/ray/tune/function_runner.py", line 331, in entrypoint
    self._status_reporter.get_checkpoint())
  File "/home/xwm/anaconda3/envs/SV/lib/python3.6/site-packages/ray/tune/function_runner.py", line 600, in _trainable_func
    output = fn()
  File "/home/xwm/anaconda3/envs/SV/lib/python3.6/site-packages/ray/tune/utils/trainable.py", line 371, in inner
    trainable(config, **fn_kwargs)
  File "train.py", line 572, in train_tune
    trainer.fit(model)
  File "/home/xwm/anaconda3/envs/SV/lib/python3.6/site-packages/pytorch_lightning/trainer/trainer.py", line 741, in fit
    self._fit_impl, model, train_dataloaders, val_dataloaders, datamodule, ckpt_path
  File "/home/xwm/anaconda3/envs/SV/lib/python3.6/site-packages/pytorch_lightning/trainer/trainer.py", line 685, in _call_and_handle_interrupt
    return trainer_fn(*args, **kwargs)
  File "/home/xwm/anaconda3/envs/SV/lib/python3.6/site-packages/pytorch_lightning/trainer/trainer.py", line 777, in _fit_impl
    self._run(model, ckpt_path=ckpt_path)
  File "/home/xwm/anaconda3/envs/SV/lib/python3.6/site-packages/pytorch_lightning/trainer/trainer.py", line 1145, in _run
    self.accelerator.setup(self)
  File "/home/xwm/anaconda3/envs/SV/lib/python3.6/site-packages/pytorch_lightning/accelerators/gpu.py", line 46, in setup
    return super().setup(trainer)
  File "/home/xwm/anaconda3/envs/SV/lib/python3.6/site-packages/pytorch_lightning/accelerators/accelerator.py", line 91, in setup
    self.setup_training_type_plugin()
  File "/home/xwm/anaconda3/envs/SV/lib/python3.6/site-packages/pytorch_lightning/accelerators/accelerator.py", line 363, in setup_training_type_plugin
    self.training_type_plugin.setup()
  File "/home/xwm/anaconda3/envs/SV/lib/python3.6/site-packages/pytorch_lightning/plugins/training_type/single_device.py", line 71, in setup
    self.model_to_device()
  File "/home/xwm/anaconda3/envs/SV/lib/python3.6/site-packages/pytorch_lightning/plugins/training_type/single_device.py", line 68, in model_to_device
    self._model.to(self.root_device)
  File "/home/xwm/anaconda3/envs/SV/lib/python3.6/site-packages/pytorch_lightning/core/mixins/device_dtype_mixin.py", line 111, in to
    return super().to(*args, **kwargs)
  File "/home/xwm/anaconda3/envs/SV/lib/python3.6/site-packages/torch/nn/modules/module.py", line 899, in to
    return self._apply(convert)
  File "/home/xwm/anaconda3/envs/SV/lib/python3.6/site-packages/torch/nn/modules/module.py", line 570, in _apply
    module._apply(fn)
  File "/home/xwm/anaconda3/envs/SV/lib/python3.6/site-packages/torch/nn/modules/module.py", line 570, in _apply
    module._apply(fn)
  File "/home/xwm/anaconda3/envs/SV/lib/python3.6/site-packages/torch/nn/modules/module.py", line 570, in _apply
    module._apply(fn)
  [Previous line repeated 1 more time]
  File "/home/xwm/anaconda3/envs/SV/lib/python3.6/site-packages/torch/nn/modules/module.py", line 593, in _apply
    param_applied = fn(param)
  File "/home/xwm/anaconda3/envs/SV/lib/python3.6/site-packages/torch/nn/modules/module.py", line 897, in convert
    return t.to(device, dtype if t.is_floating_point() or t.is_complex() else None, non_blocking)
RuntimeError: CUDA error: out of memory
CUDA kernel errors might be asynchronously reported at some other API call,so the stacktrace below might be incorrect.
For debugging consider passing CUDA_LAUNCH_BLOCKING=1.

Failure # 22 (occurred at 2022-06-14_23-30-14)
Traceback (most recent call last):
  File "/home/xwm/anaconda3/envs/SV/lib/python3.6/site-packages/ray/tune/trial_runner.py", line 886, in _process_trial
    results = self.trial_executor.fetch_result(trial)
  File "/home/xwm/anaconda3/envs/SV/lib/python3.6/site-packages/ray/tune/ray_trial_executor.py", line 675, in fetch_result
    result = ray.get(trial_future[0], timeout=DEFAULT_GET_TIMEOUT)
  File "/home/xwm/anaconda3/envs/SV/lib/python3.6/site-packages/ray/_private/client_mode_hook.py", line 105, in wrapper
    return func(*args, **kwargs)
  File "/home/xwm/anaconda3/envs/SV/lib/python3.6/site-packages/ray/worker.py", line 1763, in get
    raise value.as_instanceof_cause()
ray.exceptions.RayTaskError(TuneError): [36mray::ImplicitFunc.train()[39m (pid=205895, ip=192.168.249.74, repr=train_tune)
  File "/home/xwm/anaconda3/envs/SV/lib/python3.6/site-packages/ray/tune/trainable.py", line 319, in train
    result = self.step()
  File "/home/xwm/anaconda3/envs/SV/lib/python3.6/site-packages/ray/tune/function_runner.py", line 381, in step
    self._report_thread_runner_error(block=True)
  File "/home/xwm/anaconda3/envs/SV/lib/python3.6/site-packages/ray/tune/function_runner.py", line 532, in _report_thread_runner_error
    ("Trial raised an exception. Traceback:\n{}".format(err_tb_str)
ray.tune.error.TuneError: Trial raised an exception. Traceback:
[36mray::ImplicitFunc.train()[39m (pid=205895, ip=192.168.249.74, repr=train_tune)
  File "/home/xwm/anaconda3/envs/SV/lib/python3.6/site-packages/ray/tune/function_runner.py", line 262, in run
    self._entrypoint()
  File "/home/xwm/anaconda3/envs/SV/lib/python3.6/site-packages/ray/tune/function_runner.py", line 331, in entrypoint
    self._status_reporter.get_checkpoint())
  File "/home/xwm/anaconda3/envs/SV/lib/python3.6/site-packages/ray/tune/function_runner.py", line 600, in _trainable_func
    output = fn()
  File "/home/xwm/anaconda3/envs/SV/lib/python3.6/site-packages/ray/tune/utils/trainable.py", line 371, in inner
    trainable(config, **fn_kwargs)
  File "train.py", line 572, in train_tune
    trainer.fit(model)
  File "/home/xwm/anaconda3/envs/SV/lib/python3.6/site-packages/pytorch_lightning/trainer/trainer.py", line 741, in fit
    self._fit_impl, model, train_dataloaders, val_dataloaders, datamodule, ckpt_path
  File "/home/xwm/anaconda3/envs/SV/lib/python3.6/site-packages/pytorch_lightning/trainer/trainer.py", line 685, in _call_and_handle_interrupt
    return trainer_fn(*args, **kwargs)
  File "/home/xwm/anaconda3/envs/SV/lib/python3.6/site-packages/pytorch_lightning/trainer/trainer.py", line 777, in _fit_impl
    self._run(model, ckpt_path=ckpt_path)
  File "/home/xwm/anaconda3/envs/SV/lib/python3.6/site-packages/pytorch_lightning/trainer/trainer.py", line 1145, in _run
    self.accelerator.setup(self)
  File "/home/xwm/anaconda3/envs/SV/lib/python3.6/site-packages/pytorch_lightning/accelerators/gpu.py", line 46, in setup
    return super().setup(trainer)
  File "/home/xwm/anaconda3/envs/SV/lib/python3.6/site-packages/pytorch_lightning/accelerators/accelerator.py", line 91, in setup
    self.setup_training_type_plugin()
  File "/home/xwm/anaconda3/envs/SV/lib/python3.6/site-packages/pytorch_lightning/accelerators/accelerator.py", line 363, in setup_training_type_plugin
    self.training_type_plugin.setup()
  File "/home/xwm/anaconda3/envs/SV/lib/python3.6/site-packages/pytorch_lightning/plugins/training_type/single_device.py", line 71, in setup
    self.model_to_device()
  File "/home/xwm/anaconda3/envs/SV/lib/python3.6/site-packages/pytorch_lightning/plugins/training_type/single_device.py", line 68, in model_to_device
    self._model.to(self.root_device)
  File "/home/xwm/anaconda3/envs/SV/lib/python3.6/site-packages/pytorch_lightning/core/mixins/device_dtype_mixin.py", line 111, in to
    return super().to(*args, **kwargs)
  File "/home/xwm/anaconda3/envs/SV/lib/python3.6/site-packages/torch/nn/modules/module.py", line 899, in to
    return self._apply(convert)
  File "/home/xwm/anaconda3/envs/SV/lib/python3.6/site-packages/torch/nn/modules/module.py", line 570, in _apply
    module._apply(fn)
  File "/home/xwm/anaconda3/envs/SV/lib/python3.6/site-packages/torch/nn/modules/module.py", line 570, in _apply
    module._apply(fn)
  File "/home/xwm/anaconda3/envs/SV/lib/python3.6/site-packages/torch/nn/modules/module.py", line 570, in _apply
    module._apply(fn)
  [Previous line repeated 1 more time]
  File "/home/xwm/anaconda3/envs/SV/lib/python3.6/site-packages/torch/nn/modules/module.py", line 593, in _apply
    param_applied = fn(param)
  File "/home/xwm/anaconda3/envs/SV/lib/python3.6/site-packages/torch/nn/modules/module.py", line 897, in convert
    return t.to(device, dtype if t.is_floating_point() or t.is_complex() else None, non_blocking)
RuntimeError: CUDA error: out of memory
CUDA kernel errors might be asynchronously reported at some other API call,so the stacktrace below might be incorrect.
For debugging consider passing CUDA_LAUNCH_BLOCKING=1.

Failure # 23 (occurred at 2022-06-14_23-31-10)
Traceback (most recent call last):
  File "/home/xwm/anaconda3/envs/SV/lib/python3.6/site-packages/ray/tune/trial_runner.py", line 886, in _process_trial
    results = self.trial_executor.fetch_result(trial)
  File "/home/xwm/anaconda3/envs/SV/lib/python3.6/site-packages/ray/tune/ray_trial_executor.py", line 675, in fetch_result
    result = ray.get(trial_future[0], timeout=DEFAULT_GET_TIMEOUT)
  File "/home/xwm/anaconda3/envs/SV/lib/python3.6/site-packages/ray/_private/client_mode_hook.py", line 105, in wrapper
    return func(*args, **kwargs)
  File "/home/xwm/anaconda3/envs/SV/lib/python3.6/site-packages/ray/worker.py", line 1763, in get
    raise value.as_instanceof_cause()
ray.exceptions.RayTaskError(TuneError): [36mray::ImplicitFunc.train()[39m (pid=206571, ip=192.168.249.74, repr=train_tune)
  File "/home/xwm/anaconda3/envs/SV/lib/python3.6/site-packages/ray/tune/trainable.py", line 319, in train
    result = self.step()
  File "/home/xwm/anaconda3/envs/SV/lib/python3.6/site-packages/ray/tune/function_runner.py", line 381, in step
    self._report_thread_runner_error(block=True)
  File "/home/xwm/anaconda3/envs/SV/lib/python3.6/site-packages/ray/tune/function_runner.py", line 532, in _report_thread_runner_error
    ("Trial raised an exception. Traceback:\n{}".format(err_tb_str)
ray.tune.error.TuneError: Trial raised an exception. Traceback:
[36mray::ImplicitFunc.train()[39m (pid=206571, ip=192.168.249.74, repr=train_tune)
  File "/home/xwm/anaconda3/envs/SV/lib/python3.6/site-packages/ray/tune/function_runner.py", line 262, in run
    self._entrypoint()
  File "/home/xwm/anaconda3/envs/SV/lib/python3.6/site-packages/ray/tune/function_runner.py", line 331, in entrypoint
    self._status_reporter.get_checkpoint())
  File "/home/xwm/anaconda3/envs/SV/lib/python3.6/site-packages/ray/tune/function_runner.py", line 600, in _trainable_func
    output = fn()
  File "/home/xwm/anaconda3/envs/SV/lib/python3.6/site-packages/ray/tune/utils/trainable.py", line 371, in inner
    trainable(config, **fn_kwargs)
  File "train.py", line 572, in train_tune
    trainer.fit(model)
  File "/home/xwm/anaconda3/envs/SV/lib/python3.6/site-packages/pytorch_lightning/trainer/trainer.py", line 741, in fit
    self._fit_impl, model, train_dataloaders, val_dataloaders, datamodule, ckpt_path
  File "/home/xwm/anaconda3/envs/SV/lib/python3.6/site-packages/pytorch_lightning/trainer/trainer.py", line 685, in _call_and_handle_interrupt
    return trainer_fn(*args, **kwargs)
  File "/home/xwm/anaconda3/envs/SV/lib/python3.6/site-packages/pytorch_lightning/trainer/trainer.py", line 777, in _fit_impl
    self._run(model, ckpt_path=ckpt_path)
  File "/home/xwm/anaconda3/envs/SV/lib/python3.6/site-packages/pytorch_lightning/trainer/trainer.py", line 1145, in _run
    self.accelerator.setup(self)
  File "/home/xwm/anaconda3/envs/SV/lib/python3.6/site-packages/pytorch_lightning/accelerators/gpu.py", line 46, in setup
    return super().setup(trainer)
  File "/home/xwm/anaconda3/envs/SV/lib/python3.6/site-packages/pytorch_lightning/accelerators/accelerator.py", line 91, in setup
    self.setup_training_type_plugin()
  File "/home/xwm/anaconda3/envs/SV/lib/python3.6/site-packages/pytorch_lightning/accelerators/accelerator.py", line 363, in setup_training_type_plugin
    self.training_type_plugin.setup()
  File "/home/xwm/anaconda3/envs/SV/lib/python3.6/site-packages/pytorch_lightning/plugins/training_type/single_device.py", line 71, in setup
    self.model_to_device()
  File "/home/xwm/anaconda3/envs/SV/lib/python3.6/site-packages/pytorch_lightning/plugins/training_type/single_device.py", line 68, in model_to_device
    self._model.to(self.root_device)
  File "/home/xwm/anaconda3/envs/SV/lib/python3.6/site-packages/pytorch_lightning/core/mixins/device_dtype_mixin.py", line 111, in to
    return super().to(*args, **kwargs)
  File "/home/xwm/anaconda3/envs/SV/lib/python3.6/site-packages/torch/nn/modules/module.py", line 899, in to
    return self._apply(convert)
  File "/home/xwm/anaconda3/envs/SV/lib/python3.6/site-packages/torch/nn/modules/module.py", line 570, in _apply
    module._apply(fn)
  File "/home/xwm/anaconda3/envs/SV/lib/python3.6/site-packages/torch/nn/modules/module.py", line 570, in _apply
    module._apply(fn)
  File "/home/xwm/anaconda3/envs/SV/lib/python3.6/site-packages/torch/nn/modules/module.py", line 570, in _apply
    module._apply(fn)
  [Previous line repeated 1 more time]
  File "/home/xwm/anaconda3/envs/SV/lib/python3.6/site-packages/torch/nn/modules/module.py", line 593, in _apply
    param_applied = fn(param)
  File "/home/xwm/anaconda3/envs/SV/lib/python3.6/site-packages/torch/nn/modules/module.py", line 897, in convert
    return t.to(device, dtype if t.is_floating_point() or t.is_complex() else None, non_blocking)
RuntimeError: CUDA error: out of memory
CUDA kernel errors might be asynchronously reported at some other API call,so the stacktrace below might be incorrect.
For debugging consider passing CUDA_LAUNCH_BLOCKING=1.

Failure # 24 (occurred at 2022-06-14_23-32-11)
Traceback (most recent call last):
  File "/home/xwm/anaconda3/envs/SV/lib/python3.6/site-packages/ray/tune/trial_runner.py", line 886, in _process_trial
    results = self.trial_executor.fetch_result(trial)
  File "/home/xwm/anaconda3/envs/SV/lib/python3.6/site-packages/ray/tune/ray_trial_executor.py", line 675, in fetch_result
    result = ray.get(trial_future[0], timeout=DEFAULT_GET_TIMEOUT)
  File "/home/xwm/anaconda3/envs/SV/lib/python3.6/site-packages/ray/_private/client_mode_hook.py", line 105, in wrapper
    return func(*args, **kwargs)
  File "/home/xwm/anaconda3/envs/SV/lib/python3.6/site-packages/ray/worker.py", line 1763, in get
    raise value.as_instanceof_cause()
ray.exceptions.RayTaskError(TuneError): [36mray::ImplicitFunc.train()[39m (pid=207232, ip=192.168.249.74, repr=train_tune)
  File "/home/xwm/anaconda3/envs/SV/lib/python3.6/site-packages/ray/tune/trainable.py", line 319, in train
    result = self.step()
  File "/home/xwm/anaconda3/envs/SV/lib/python3.6/site-packages/ray/tune/function_runner.py", line 381, in step
    self._report_thread_runner_error(block=True)
  File "/home/xwm/anaconda3/envs/SV/lib/python3.6/site-packages/ray/tune/function_runner.py", line 532, in _report_thread_runner_error
    ("Trial raised an exception. Traceback:\n{}".format(err_tb_str)
ray.tune.error.TuneError: Trial raised an exception. Traceback:
[36mray::ImplicitFunc.train()[39m (pid=207232, ip=192.168.249.74, repr=train_tune)
  File "/home/xwm/anaconda3/envs/SV/lib/python3.6/site-packages/ray/tune/function_runner.py", line 262, in run
    self._entrypoint()
  File "/home/xwm/anaconda3/envs/SV/lib/python3.6/site-packages/ray/tune/function_runner.py", line 331, in entrypoint
    self._status_reporter.get_checkpoint())
  File "/home/xwm/anaconda3/envs/SV/lib/python3.6/site-packages/ray/tune/function_runner.py", line 600, in _trainable_func
    output = fn()
  File "/home/xwm/anaconda3/envs/SV/lib/python3.6/site-packages/ray/tune/utils/trainable.py", line 371, in inner
    trainable(config, **fn_kwargs)
  File "train.py", line 572, in train_tune
    trainer.fit(model)
  File "/home/xwm/anaconda3/envs/SV/lib/python3.6/site-packages/pytorch_lightning/trainer/trainer.py", line 741, in fit
    self._fit_impl, model, train_dataloaders, val_dataloaders, datamodule, ckpt_path
  File "/home/xwm/anaconda3/envs/SV/lib/python3.6/site-packages/pytorch_lightning/trainer/trainer.py", line 685, in _call_and_handle_interrupt
    return trainer_fn(*args, **kwargs)
  File "/home/xwm/anaconda3/envs/SV/lib/python3.6/site-packages/pytorch_lightning/trainer/trainer.py", line 777, in _fit_impl
    self._run(model, ckpt_path=ckpt_path)
  File "/home/xwm/anaconda3/envs/SV/lib/python3.6/site-packages/pytorch_lightning/trainer/trainer.py", line 1145, in _run
    self.accelerator.setup(self)
  File "/home/xwm/anaconda3/envs/SV/lib/python3.6/site-packages/pytorch_lightning/accelerators/gpu.py", line 46, in setup
    return super().setup(trainer)
  File "/home/xwm/anaconda3/envs/SV/lib/python3.6/site-packages/pytorch_lightning/accelerators/accelerator.py", line 91, in setup
    self.setup_training_type_plugin()
  File "/home/xwm/anaconda3/envs/SV/lib/python3.6/site-packages/pytorch_lightning/accelerators/accelerator.py", line 363, in setup_training_type_plugin
    self.training_type_plugin.setup()
  File "/home/xwm/anaconda3/envs/SV/lib/python3.6/site-packages/pytorch_lightning/plugins/training_type/single_device.py", line 71, in setup
    self.model_to_device()
  File "/home/xwm/anaconda3/envs/SV/lib/python3.6/site-packages/pytorch_lightning/plugins/training_type/single_device.py", line 68, in model_to_device
    self._model.to(self.root_device)
  File "/home/xwm/anaconda3/envs/SV/lib/python3.6/site-packages/pytorch_lightning/core/mixins/device_dtype_mixin.py", line 111, in to
    return super().to(*args, **kwargs)
  File "/home/xwm/anaconda3/envs/SV/lib/python3.6/site-packages/torch/nn/modules/module.py", line 899, in to
    return self._apply(convert)
  File "/home/xwm/anaconda3/envs/SV/lib/python3.6/site-packages/torch/nn/modules/module.py", line 570, in _apply
    module._apply(fn)
  File "/home/xwm/anaconda3/envs/SV/lib/python3.6/site-packages/torch/nn/modules/module.py", line 570, in _apply
    module._apply(fn)
  File "/home/xwm/anaconda3/envs/SV/lib/python3.6/site-packages/torch/nn/modules/module.py", line 570, in _apply
    module._apply(fn)
  [Previous line repeated 1 more time]
  File "/home/xwm/anaconda3/envs/SV/lib/python3.6/site-packages/torch/nn/modules/module.py", line 593, in _apply
    param_applied = fn(param)
  File "/home/xwm/anaconda3/envs/SV/lib/python3.6/site-packages/torch/nn/modules/module.py", line 897, in convert
    return t.to(device, dtype if t.is_floating_point() or t.is_complex() else None, non_blocking)
RuntimeError: CUDA error: out of memory
CUDA kernel errors might be asynchronously reported at some other API call,so the stacktrace below might be incorrect.
For debugging consider passing CUDA_LAUNCH_BLOCKING=1.

Failure # 25 (occurred at 2022-06-14_23-33-08)
Traceback (most recent call last):
  File "/home/xwm/anaconda3/envs/SV/lib/python3.6/site-packages/ray/tune/trial_runner.py", line 886, in _process_trial
    results = self.trial_executor.fetch_result(trial)
  File "/home/xwm/anaconda3/envs/SV/lib/python3.6/site-packages/ray/tune/ray_trial_executor.py", line 675, in fetch_result
    result = ray.get(trial_future[0], timeout=DEFAULT_GET_TIMEOUT)
  File "/home/xwm/anaconda3/envs/SV/lib/python3.6/site-packages/ray/_private/client_mode_hook.py", line 105, in wrapper
    return func(*args, **kwargs)
  File "/home/xwm/anaconda3/envs/SV/lib/python3.6/site-packages/ray/worker.py", line 1763, in get
    raise value.as_instanceof_cause()
ray.exceptions.RayTaskError(TuneError): [36mray::ImplicitFunc.train()[39m (pid=207920, ip=192.168.249.74, repr=train_tune)
  File "/home/xwm/anaconda3/envs/SV/lib/python3.6/site-packages/ray/tune/trainable.py", line 319, in train
    result = self.step()
  File "/home/xwm/anaconda3/envs/SV/lib/python3.6/site-packages/ray/tune/function_runner.py", line 381, in step
    self._report_thread_runner_error(block=True)
  File "/home/xwm/anaconda3/envs/SV/lib/python3.6/site-packages/ray/tune/function_runner.py", line 532, in _report_thread_runner_error
    ("Trial raised an exception. Traceback:\n{}".format(err_tb_str)
ray.tune.error.TuneError: Trial raised an exception. Traceback:
[36mray::ImplicitFunc.train()[39m (pid=207920, ip=192.168.249.74, repr=train_tune)
  File "/home/xwm/anaconda3/envs/SV/lib/python3.6/site-packages/ray/tune/function_runner.py", line 262, in run
    self._entrypoint()
  File "/home/xwm/anaconda3/envs/SV/lib/python3.6/site-packages/ray/tune/function_runner.py", line 331, in entrypoint
    self._status_reporter.get_checkpoint())
  File "/home/xwm/anaconda3/envs/SV/lib/python3.6/site-packages/ray/tune/function_runner.py", line 600, in _trainable_func
    output = fn()
  File "/home/xwm/anaconda3/envs/SV/lib/python3.6/site-packages/ray/tune/utils/trainable.py", line 371, in inner
    trainable(config, **fn_kwargs)
  File "train.py", line 572, in train_tune
    trainer.fit(model)
  File "/home/xwm/anaconda3/envs/SV/lib/python3.6/site-packages/pytorch_lightning/trainer/trainer.py", line 741, in fit
    self._fit_impl, model, train_dataloaders, val_dataloaders, datamodule, ckpt_path
  File "/home/xwm/anaconda3/envs/SV/lib/python3.6/site-packages/pytorch_lightning/trainer/trainer.py", line 685, in _call_and_handle_interrupt
    return trainer_fn(*args, **kwargs)
  File "/home/xwm/anaconda3/envs/SV/lib/python3.6/site-packages/pytorch_lightning/trainer/trainer.py", line 777, in _fit_impl
    self._run(model, ckpt_path=ckpt_path)
  File "/home/xwm/anaconda3/envs/SV/lib/python3.6/site-packages/pytorch_lightning/trainer/trainer.py", line 1145, in _run
    self.accelerator.setup(self)
  File "/home/xwm/anaconda3/envs/SV/lib/python3.6/site-packages/pytorch_lightning/accelerators/gpu.py", line 46, in setup
    return super().setup(trainer)
  File "/home/xwm/anaconda3/envs/SV/lib/python3.6/site-packages/pytorch_lightning/accelerators/accelerator.py", line 91, in setup
    self.setup_training_type_plugin()
  File "/home/xwm/anaconda3/envs/SV/lib/python3.6/site-packages/pytorch_lightning/accelerators/accelerator.py", line 363, in setup_training_type_plugin
    self.training_type_plugin.setup()
  File "/home/xwm/anaconda3/envs/SV/lib/python3.6/site-packages/pytorch_lightning/plugins/training_type/single_device.py", line 71, in setup
    self.model_to_device()
  File "/home/xwm/anaconda3/envs/SV/lib/python3.6/site-packages/pytorch_lightning/plugins/training_type/single_device.py", line 68, in model_to_device
    self._model.to(self.root_device)
  File "/home/xwm/anaconda3/envs/SV/lib/python3.6/site-packages/pytorch_lightning/core/mixins/device_dtype_mixin.py", line 111, in to
    return super().to(*args, **kwargs)
  File "/home/xwm/anaconda3/envs/SV/lib/python3.6/site-packages/torch/nn/modules/module.py", line 899, in to
    return self._apply(convert)
  File "/home/xwm/anaconda3/envs/SV/lib/python3.6/site-packages/torch/nn/modules/module.py", line 570, in _apply
    module._apply(fn)
  File "/home/xwm/anaconda3/envs/SV/lib/python3.6/site-packages/torch/nn/modules/module.py", line 570, in _apply
    module._apply(fn)
  File "/home/xwm/anaconda3/envs/SV/lib/python3.6/site-packages/torch/nn/modules/module.py", line 570, in _apply
    module._apply(fn)
  [Previous line repeated 1 more time]
  File "/home/xwm/anaconda3/envs/SV/lib/python3.6/site-packages/torch/nn/modules/module.py", line 593, in _apply
    param_applied = fn(param)
  File "/home/xwm/anaconda3/envs/SV/lib/python3.6/site-packages/torch/nn/modules/module.py", line 897, in convert
    return t.to(device, dtype if t.is_floating_point() or t.is_complex() else None, non_blocking)
RuntimeError: CUDA error: out of memory
CUDA kernel errors might be asynchronously reported at some other API call,so the stacktrace below might be incorrect.
For debugging consider passing CUDA_LAUNCH_BLOCKING=1.

Failure # 26 (occurred at 2022-06-14_23-34-13)
Traceback (most recent call last):
  File "/home/xwm/anaconda3/envs/SV/lib/python3.6/site-packages/ray/tune/trial_runner.py", line 886, in _process_trial
    results = self.trial_executor.fetch_result(trial)
  File "/home/xwm/anaconda3/envs/SV/lib/python3.6/site-packages/ray/tune/ray_trial_executor.py", line 675, in fetch_result
    result = ray.get(trial_future[0], timeout=DEFAULT_GET_TIMEOUT)
  File "/home/xwm/anaconda3/envs/SV/lib/python3.6/site-packages/ray/_private/client_mode_hook.py", line 105, in wrapper
    return func(*args, **kwargs)
  File "/home/xwm/anaconda3/envs/SV/lib/python3.6/site-packages/ray/worker.py", line 1763, in get
    raise value.as_instanceof_cause()
ray.exceptions.RayTaskError(TuneError): [36mray::ImplicitFunc.train()[39m (pid=208561, ip=192.168.249.74, repr=train_tune)
  File "/home/xwm/anaconda3/envs/SV/lib/python3.6/site-packages/ray/tune/trainable.py", line 319, in train
    result = self.step()
  File "/home/xwm/anaconda3/envs/SV/lib/python3.6/site-packages/ray/tune/function_runner.py", line 381, in step
    self._report_thread_runner_error(block=True)
  File "/home/xwm/anaconda3/envs/SV/lib/python3.6/site-packages/ray/tune/function_runner.py", line 532, in _report_thread_runner_error
    ("Trial raised an exception. Traceback:\n{}".format(err_tb_str)
ray.tune.error.TuneError: Trial raised an exception. Traceback:
[36mray::ImplicitFunc.train()[39m (pid=208561, ip=192.168.249.74, repr=train_tune)
  File "/home/xwm/anaconda3/envs/SV/lib/python3.6/site-packages/ray/tune/function_runner.py", line 262, in run
    self._entrypoint()
  File "/home/xwm/anaconda3/envs/SV/lib/python3.6/site-packages/ray/tune/function_runner.py", line 331, in entrypoint
    self._status_reporter.get_checkpoint())
  File "/home/xwm/anaconda3/envs/SV/lib/python3.6/site-packages/ray/tune/function_runner.py", line 600, in _trainable_func
    output = fn()
  File "/home/xwm/anaconda3/envs/SV/lib/python3.6/site-packages/ray/tune/utils/trainable.py", line 371, in inner
    trainable(config, **fn_kwargs)
  File "train.py", line 572, in train_tune
    trainer.fit(model)
  File "/home/xwm/anaconda3/envs/SV/lib/python3.6/site-packages/pytorch_lightning/trainer/trainer.py", line 741, in fit
    self._fit_impl, model, train_dataloaders, val_dataloaders, datamodule, ckpt_path
  File "/home/xwm/anaconda3/envs/SV/lib/python3.6/site-packages/pytorch_lightning/trainer/trainer.py", line 685, in _call_and_handle_interrupt
    return trainer_fn(*args, **kwargs)
  File "/home/xwm/anaconda3/envs/SV/lib/python3.6/site-packages/pytorch_lightning/trainer/trainer.py", line 777, in _fit_impl
    self._run(model, ckpt_path=ckpt_path)
  File "/home/xwm/anaconda3/envs/SV/lib/python3.6/site-packages/pytorch_lightning/trainer/trainer.py", line 1145, in _run
    self.accelerator.setup(self)
  File "/home/xwm/anaconda3/envs/SV/lib/python3.6/site-packages/pytorch_lightning/accelerators/gpu.py", line 46, in setup
    return super().setup(trainer)
  File "/home/xwm/anaconda3/envs/SV/lib/python3.6/site-packages/pytorch_lightning/accelerators/accelerator.py", line 91, in setup
    self.setup_training_type_plugin()
  File "/home/xwm/anaconda3/envs/SV/lib/python3.6/site-packages/pytorch_lightning/accelerators/accelerator.py", line 363, in setup_training_type_plugin
    self.training_type_plugin.setup()
  File "/home/xwm/anaconda3/envs/SV/lib/python3.6/site-packages/pytorch_lightning/plugins/training_type/single_device.py", line 71, in setup
    self.model_to_device()
  File "/home/xwm/anaconda3/envs/SV/lib/python3.6/site-packages/pytorch_lightning/plugins/training_type/single_device.py", line 68, in model_to_device
    self._model.to(self.root_device)
  File "/home/xwm/anaconda3/envs/SV/lib/python3.6/site-packages/pytorch_lightning/core/mixins/device_dtype_mixin.py", line 111, in to
    return super().to(*args, **kwargs)
  File "/home/xwm/anaconda3/envs/SV/lib/python3.6/site-packages/torch/nn/modules/module.py", line 899, in to
    return self._apply(convert)
  File "/home/xwm/anaconda3/envs/SV/lib/python3.6/site-packages/torch/nn/modules/module.py", line 570, in _apply
    module._apply(fn)
  File "/home/xwm/anaconda3/envs/SV/lib/python3.6/site-packages/torch/nn/modules/module.py", line 570, in _apply
    module._apply(fn)
  File "/home/xwm/anaconda3/envs/SV/lib/python3.6/site-packages/torch/nn/modules/module.py", line 570, in _apply
    module._apply(fn)
  [Previous line repeated 1 more time]
  File "/home/xwm/anaconda3/envs/SV/lib/python3.6/site-packages/torch/nn/modules/module.py", line 593, in _apply
    param_applied = fn(param)
  File "/home/xwm/anaconda3/envs/SV/lib/python3.6/site-packages/torch/nn/modules/module.py", line 897, in convert
    return t.to(device, dtype if t.is_floating_point() or t.is_complex() else None, non_blocking)
RuntimeError: CUDA error: out of memory
CUDA kernel errors might be asynchronously reported at some other API call,so the stacktrace below might be incorrect.
For debugging consider passing CUDA_LAUNCH_BLOCKING=1.

Failure # 27 (occurred at 2022-06-14_23-35-17)
Traceback (most recent call last):
  File "/home/xwm/anaconda3/envs/SV/lib/python3.6/site-packages/ray/tune/trial_runner.py", line 886, in _process_trial
    results = self.trial_executor.fetch_result(trial)
  File "/home/xwm/anaconda3/envs/SV/lib/python3.6/site-packages/ray/tune/ray_trial_executor.py", line 675, in fetch_result
    result = ray.get(trial_future[0], timeout=DEFAULT_GET_TIMEOUT)
  File "/home/xwm/anaconda3/envs/SV/lib/python3.6/site-packages/ray/_private/client_mode_hook.py", line 105, in wrapper
    return func(*args, **kwargs)
  File "/home/xwm/anaconda3/envs/SV/lib/python3.6/site-packages/ray/worker.py", line 1763, in get
    raise value.as_instanceof_cause()
ray.exceptions.RayTaskError(TuneError): [36mray::ImplicitFunc.train()[39m (pid=209294, ip=192.168.249.74, repr=train_tune)
  File "/home/xwm/anaconda3/envs/SV/lib/python3.6/site-packages/ray/tune/trainable.py", line 319, in train
    result = self.step()
  File "/home/xwm/anaconda3/envs/SV/lib/python3.6/site-packages/ray/tune/function_runner.py", line 381, in step
    self._report_thread_runner_error(block=True)
  File "/home/xwm/anaconda3/envs/SV/lib/python3.6/site-packages/ray/tune/function_runner.py", line 532, in _report_thread_runner_error
    ("Trial raised an exception. Traceback:\n{}".format(err_tb_str)
ray.tune.error.TuneError: Trial raised an exception. Traceback:
[36mray::ImplicitFunc.train()[39m (pid=209294, ip=192.168.249.74, repr=train_tune)
  File "/home/xwm/anaconda3/envs/SV/lib/python3.6/site-packages/ray/tune/function_runner.py", line 262, in run
    self._entrypoint()
  File "/home/xwm/anaconda3/envs/SV/lib/python3.6/site-packages/ray/tune/function_runner.py", line 331, in entrypoint
    self._status_reporter.get_checkpoint())
  File "/home/xwm/anaconda3/envs/SV/lib/python3.6/site-packages/ray/tune/function_runner.py", line 600, in _trainable_func
    output = fn()
  File "/home/xwm/anaconda3/envs/SV/lib/python3.6/site-packages/ray/tune/utils/trainable.py", line 371, in inner
    trainable(config, **fn_kwargs)
  File "train.py", line 572, in train_tune
    trainer.fit(model)
  File "/home/xwm/anaconda3/envs/SV/lib/python3.6/site-packages/pytorch_lightning/trainer/trainer.py", line 741, in fit
    self._fit_impl, model, train_dataloaders, val_dataloaders, datamodule, ckpt_path
  File "/home/xwm/anaconda3/envs/SV/lib/python3.6/site-packages/pytorch_lightning/trainer/trainer.py", line 685, in _call_and_handle_interrupt
    return trainer_fn(*args, **kwargs)
  File "/home/xwm/anaconda3/envs/SV/lib/python3.6/site-packages/pytorch_lightning/trainer/trainer.py", line 777, in _fit_impl
    self._run(model, ckpt_path=ckpt_path)
  File "/home/xwm/anaconda3/envs/SV/lib/python3.6/site-packages/pytorch_lightning/trainer/trainer.py", line 1145, in _run
    self.accelerator.setup(self)
  File "/home/xwm/anaconda3/envs/SV/lib/python3.6/site-packages/pytorch_lightning/accelerators/gpu.py", line 46, in setup
    return super().setup(trainer)
  File "/home/xwm/anaconda3/envs/SV/lib/python3.6/site-packages/pytorch_lightning/accelerators/accelerator.py", line 91, in setup
    self.setup_training_type_plugin()
  File "/home/xwm/anaconda3/envs/SV/lib/python3.6/site-packages/pytorch_lightning/accelerators/accelerator.py", line 363, in setup_training_type_plugin
    self.training_type_plugin.setup()
  File "/home/xwm/anaconda3/envs/SV/lib/python3.6/site-packages/pytorch_lightning/plugins/training_type/single_device.py", line 71, in setup
    self.model_to_device()
  File "/home/xwm/anaconda3/envs/SV/lib/python3.6/site-packages/pytorch_lightning/plugins/training_type/single_device.py", line 68, in model_to_device
    self._model.to(self.root_device)
  File "/home/xwm/anaconda3/envs/SV/lib/python3.6/site-packages/pytorch_lightning/core/mixins/device_dtype_mixin.py", line 111, in to
    return super().to(*args, **kwargs)
  File "/home/xwm/anaconda3/envs/SV/lib/python3.6/site-packages/torch/nn/modules/module.py", line 899, in to
    return self._apply(convert)
  File "/home/xwm/anaconda3/envs/SV/lib/python3.6/site-packages/torch/nn/modules/module.py", line 570, in _apply
    module._apply(fn)
  File "/home/xwm/anaconda3/envs/SV/lib/python3.6/site-packages/torch/nn/modules/module.py", line 570, in _apply
    module._apply(fn)
  File "/home/xwm/anaconda3/envs/SV/lib/python3.6/site-packages/torch/nn/modules/module.py", line 570, in _apply
    module._apply(fn)
  [Previous line repeated 1 more time]
  File "/home/xwm/anaconda3/envs/SV/lib/python3.6/site-packages/torch/nn/modules/module.py", line 593, in _apply
    param_applied = fn(param)
  File "/home/xwm/anaconda3/envs/SV/lib/python3.6/site-packages/torch/nn/modules/module.py", line 897, in convert
    return t.to(device, dtype if t.is_floating_point() or t.is_complex() else None, non_blocking)
RuntimeError: CUDA error: out of memory
CUDA kernel errors might be asynchronously reported at some other API call,so the stacktrace below might be incorrect.
For debugging consider passing CUDA_LAUNCH_BLOCKING=1.

Failure # 28 (occurred at 2022-06-14_23-36-22)
Traceback (most recent call last):
  File "/home/xwm/anaconda3/envs/SV/lib/python3.6/site-packages/ray/tune/trial_runner.py", line 886, in _process_trial
    results = self.trial_executor.fetch_result(trial)
  File "/home/xwm/anaconda3/envs/SV/lib/python3.6/site-packages/ray/tune/ray_trial_executor.py", line 675, in fetch_result
    result = ray.get(trial_future[0], timeout=DEFAULT_GET_TIMEOUT)
  File "/home/xwm/anaconda3/envs/SV/lib/python3.6/site-packages/ray/_private/client_mode_hook.py", line 105, in wrapper
    return func(*args, **kwargs)
  File "/home/xwm/anaconda3/envs/SV/lib/python3.6/site-packages/ray/worker.py", line 1763, in get
    raise value.as_instanceof_cause()
ray.exceptions.RayTaskError(TuneError): [36mray::ImplicitFunc.train()[39m (pid=209985, ip=192.168.249.74, repr=train_tune)
  File "/home/xwm/anaconda3/envs/SV/lib/python3.6/site-packages/ray/tune/trainable.py", line 319, in train
    result = self.step()
  File "/home/xwm/anaconda3/envs/SV/lib/python3.6/site-packages/ray/tune/function_runner.py", line 381, in step
    self._report_thread_runner_error(block=True)
  File "/home/xwm/anaconda3/envs/SV/lib/python3.6/site-packages/ray/tune/function_runner.py", line 532, in _report_thread_runner_error
    ("Trial raised an exception. Traceback:\n{}".format(err_tb_str)
ray.tune.error.TuneError: Trial raised an exception. Traceback:
[36mray::ImplicitFunc.train()[39m (pid=209985, ip=192.168.249.74, repr=train_tune)
  File "/home/xwm/anaconda3/envs/SV/lib/python3.6/site-packages/ray/tune/function_runner.py", line 262, in run
    self._entrypoint()
  File "/home/xwm/anaconda3/envs/SV/lib/python3.6/site-packages/ray/tune/function_runner.py", line 331, in entrypoint
    self._status_reporter.get_checkpoint())
  File "/home/xwm/anaconda3/envs/SV/lib/python3.6/site-packages/ray/tune/function_runner.py", line 600, in _trainable_func
    output = fn()
  File "/home/xwm/anaconda3/envs/SV/lib/python3.6/site-packages/ray/tune/utils/trainable.py", line 371, in inner
    trainable(config, **fn_kwargs)
  File "train.py", line 572, in train_tune
    trainer.fit(model)
  File "/home/xwm/anaconda3/envs/SV/lib/python3.6/site-packages/pytorch_lightning/trainer/trainer.py", line 741, in fit
    self._fit_impl, model, train_dataloaders, val_dataloaders, datamodule, ckpt_path
  File "/home/xwm/anaconda3/envs/SV/lib/python3.6/site-packages/pytorch_lightning/trainer/trainer.py", line 685, in _call_and_handle_interrupt
    return trainer_fn(*args, **kwargs)
  File "/home/xwm/anaconda3/envs/SV/lib/python3.6/site-packages/pytorch_lightning/trainer/trainer.py", line 777, in _fit_impl
    self._run(model, ckpt_path=ckpt_path)
  File "/home/xwm/anaconda3/envs/SV/lib/python3.6/site-packages/pytorch_lightning/trainer/trainer.py", line 1145, in _run
    self.accelerator.setup(self)
  File "/home/xwm/anaconda3/envs/SV/lib/python3.6/site-packages/pytorch_lightning/accelerators/gpu.py", line 46, in setup
    return super().setup(trainer)
  File "/home/xwm/anaconda3/envs/SV/lib/python3.6/site-packages/pytorch_lightning/accelerators/accelerator.py", line 91, in setup
    self.setup_training_type_plugin()
  File "/home/xwm/anaconda3/envs/SV/lib/python3.6/site-packages/pytorch_lightning/accelerators/accelerator.py", line 363, in setup_training_type_plugin
    self.training_type_plugin.setup()
  File "/home/xwm/anaconda3/envs/SV/lib/python3.6/site-packages/pytorch_lightning/plugins/training_type/single_device.py", line 71, in setup
    self.model_to_device()
  File "/home/xwm/anaconda3/envs/SV/lib/python3.6/site-packages/pytorch_lightning/plugins/training_type/single_device.py", line 68, in model_to_device
    self._model.to(self.root_device)
  File "/home/xwm/anaconda3/envs/SV/lib/python3.6/site-packages/pytorch_lightning/core/mixins/device_dtype_mixin.py", line 111, in to
    return super().to(*args, **kwargs)
  File "/home/xwm/anaconda3/envs/SV/lib/python3.6/site-packages/torch/nn/modules/module.py", line 899, in to
    return self._apply(convert)
  File "/home/xwm/anaconda3/envs/SV/lib/python3.6/site-packages/torch/nn/modules/module.py", line 570, in _apply
    module._apply(fn)
  File "/home/xwm/anaconda3/envs/SV/lib/python3.6/site-packages/torch/nn/modules/module.py", line 570, in _apply
    module._apply(fn)
  File "/home/xwm/anaconda3/envs/SV/lib/python3.6/site-packages/torch/nn/modules/module.py", line 570, in _apply
    module._apply(fn)
  [Previous line repeated 1 more time]
  File "/home/xwm/anaconda3/envs/SV/lib/python3.6/site-packages/torch/nn/modules/module.py", line 593, in _apply
    param_applied = fn(param)
  File "/home/xwm/anaconda3/envs/SV/lib/python3.6/site-packages/torch/nn/modules/module.py", line 897, in convert
    return t.to(device, dtype if t.is_floating_point() or t.is_complex() else None, non_blocking)
RuntimeError: CUDA error: out of memory
CUDA kernel errors might be asynchronously reported at some other API call,so the stacktrace below might be incorrect.
For debugging consider passing CUDA_LAUNCH_BLOCKING=1.

Failure # 29 (occurred at 2022-06-14_23-37-21)
Traceback (most recent call last):
  File "/home/xwm/anaconda3/envs/SV/lib/python3.6/site-packages/ray/tune/trial_runner.py", line 886, in _process_trial
    results = self.trial_executor.fetch_result(trial)
  File "/home/xwm/anaconda3/envs/SV/lib/python3.6/site-packages/ray/tune/ray_trial_executor.py", line 675, in fetch_result
    result = ray.get(trial_future[0], timeout=DEFAULT_GET_TIMEOUT)
  File "/home/xwm/anaconda3/envs/SV/lib/python3.6/site-packages/ray/_private/client_mode_hook.py", line 105, in wrapper
    return func(*args, **kwargs)
  File "/home/xwm/anaconda3/envs/SV/lib/python3.6/site-packages/ray/worker.py", line 1763, in get
    raise value.as_instanceof_cause()
ray.exceptions.RayTaskError(TuneError): [36mray::ImplicitFunc.train()[39m (pid=210628, ip=192.168.249.74, repr=train_tune)
  File "/home/xwm/anaconda3/envs/SV/lib/python3.6/site-packages/ray/tune/trainable.py", line 319, in train
    result = self.step()
  File "/home/xwm/anaconda3/envs/SV/lib/python3.6/site-packages/ray/tune/function_runner.py", line 381, in step
    self._report_thread_runner_error(block=True)
  File "/home/xwm/anaconda3/envs/SV/lib/python3.6/site-packages/ray/tune/function_runner.py", line 532, in _report_thread_runner_error
    ("Trial raised an exception. Traceback:\n{}".format(err_tb_str)
ray.tune.error.TuneError: Trial raised an exception. Traceback:
[36mray::ImplicitFunc.train()[39m (pid=210628, ip=192.168.249.74, repr=train_tune)
  File "/home/xwm/anaconda3/envs/SV/lib/python3.6/site-packages/ray/tune/function_runner.py", line 262, in run
    self._entrypoint()
  File "/home/xwm/anaconda3/envs/SV/lib/python3.6/site-packages/ray/tune/function_runner.py", line 331, in entrypoint
    self._status_reporter.get_checkpoint())
  File "/home/xwm/anaconda3/envs/SV/lib/python3.6/site-packages/ray/tune/function_runner.py", line 600, in _trainable_func
    output = fn()
  File "/home/xwm/anaconda3/envs/SV/lib/python3.6/site-packages/ray/tune/utils/trainable.py", line 371, in inner
    trainable(config, **fn_kwargs)
  File "train.py", line 572, in train_tune
    trainer.fit(model)
  File "/home/xwm/anaconda3/envs/SV/lib/python3.6/site-packages/pytorch_lightning/trainer/trainer.py", line 741, in fit
    self._fit_impl, model, train_dataloaders, val_dataloaders, datamodule, ckpt_path
  File "/home/xwm/anaconda3/envs/SV/lib/python3.6/site-packages/pytorch_lightning/trainer/trainer.py", line 685, in _call_and_handle_interrupt
    return trainer_fn(*args, **kwargs)
  File "/home/xwm/anaconda3/envs/SV/lib/python3.6/site-packages/pytorch_lightning/trainer/trainer.py", line 777, in _fit_impl
    self._run(model, ckpt_path=ckpt_path)
  File "/home/xwm/anaconda3/envs/SV/lib/python3.6/site-packages/pytorch_lightning/trainer/trainer.py", line 1145, in _run
    self.accelerator.setup(self)
  File "/home/xwm/anaconda3/envs/SV/lib/python3.6/site-packages/pytorch_lightning/accelerators/gpu.py", line 46, in setup
    return super().setup(trainer)
  File "/home/xwm/anaconda3/envs/SV/lib/python3.6/site-packages/pytorch_lightning/accelerators/accelerator.py", line 91, in setup
    self.setup_training_type_plugin()
  File "/home/xwm/anaconda3/envs/SV/lib/python3.6/site-packages/pytorch_lightning/accelerators/accelerator.py", line 363, in setup_training_type_plugin
    self.training_type_plugin.setup()
  File "/home/xwm/anaconda3/envs/SV/lib/python3.6/site-packages/pytorch_lightning/plugins/training_type/single_device.py", line 71, in setup
    self.model_to_device()
  File "/home/xwm/anaconda3/envs/SV/lib/python3.6/site-packages/pytorch_lightning/plugins/training_type/single_device.py", line 68, in model_to_device
    self._model.to(self.root_device)
  File "/home/xwm/anaconda3/envs/SV/lib/python3.6/site-packages/pytorch_lightning/core/mixins/device_dtype_mixin.py", line 111, in to
    return super().to(*args, **kwargs)
  File "/home/xwm/anaconda3/envs/SV/lib/python3.6/site-packages/torch/nn/modules/module.py", line 899, in to
    return self._apply(convert)
  File "/home/xwm/anaconda3/envs/SV/lib/python3.6/site-packages/torch/nn/modules/module.py", line 570, in _apply
    module._apply(fn)
  File "/home/xwm/anaconda3/envs/SV/lib/python3.6/site-packages/torch/nn/modules/module.py", line 570, in _apply
    module._apply(fn)
  File "/home/xwm/anaconda3/envs/SV/lib/python3.6/site-packages/torch/nn/modules/module.py", line 570, in _apply
    module._apply(fn)
  [Previous line repeated 1 more time]
  File "/home/xwm/anaconda3/envs/SV/lib/python3.6/site-packages/torch/nn/modules/module.py", line 593, in _apply
    param_applied = fn(param)
  File "/home/xwm/anaconda3/envs/SV/lib/python3.6/site-packages/torch/nn/modules/module.py", line 897, in convert
    return t.to(device, dtype if t.is_floating_point() or t.is_complex() else None, non_blocking)
RuntimeError: CUDA error: out of memory
CUDA kernel errors might be asynchronously reported at some other API call,so the stacktrace below might be incorrect.
For debugging consider passing CUDA_LAUNCH_BLOCKING=1.

Failure # 30 (occurred at 2022-06-14_23-38-19)
Traceback (most recent call last):
  File "/home/xwm/anaconda3/envs/SV/lib/python3.6/site-packages/ray/tune/trial_runner.py", line 886, in _process_trial
    results = self.trial_executor.fetch_result(trial)
  File "/home/xwm/anaconda3/envs/SV/lib/python3.6/site-packages/ray/tune/ray_trial_executor.py", line 675, in fetch_result
    result = ray.get(trial_future[0], timeout=DEFAULT_GET_TIMEOUT)
  File "/home/xwm/anaconda3/envs/SV/lib/python3.6/site-packages/ray/_private/client_mode_hook.py", line 105, in wrapper
    return func(*args, **kwargs)
  File "/home/xwm/anaconda3/envs/SV/lib/python3.6/site-packages/ray/worker.py", line 1763, in get
    raise value.as_instanceof_cause()
ray.exceptions.RayTaskError(TuneError): [36mray::ImplicitFunc.train()[39m (pid=211300, ip=192.168.249.74, repr=train_tune)
  File "/home/xwm/anaconda3/envs/SV/lib/python3.6/site-packages/ray/tune/trainable.py", line 319, in train
    result = self.step()
  File "/home/xwm/anaconda3/envs/SV/lib/python3.6/site-packages/ray/tune/function_runner.py", line 381, in step
    self._report_thread_runner_error(block=True)
  File "/home/xwm/anaconda3/envs/SV/lib/python3.6/site-packages/ray/tune/function_runner.py", line 532, in _report_thread_runner_error
    ("Trial raised an exception. Traceback:\n{}".format(err_tb_str)
ray.tune.error.TuneError: Trial raised an exception. Traceback:
[36mray::ImplicitFunc.train()[39m (pid=211300, ip=192.168.249.74, repr=train_tune)
  File "/home/xwm/anaconda3/envs/SV/lib/python3.6/site-packages/ray/tune/function_runner.py", line 262, in run
    self._entrypoint()
  File "/home/xwm/anaconda3/envs/SV/lib/python3.6/site-packages/ray/tune/function_runner.py", line 331, in entrypoint
    self._status_reporter.get_checkpoint())
  File "/home/xwm/anaconda3/envs/SV/lib/python3.6/site-packages/ray/tune/function_runner.py", line 600, in _trainable_func
    output = fn()
  File "/home/xwm/anaconda3/envs/SV/lib/python3.6/site-packages/ray/tune/utils/trainable.py", line 371, in inner
    trainable(config, **fn_kwargs)
  File "train.py", line 572, in train_tune
    trainer.fit(model)
  File "/home/xwm/anaconda3/envs/SV/lib/python3.6/site-packages/pytorch_lightning/trainer/trainer.py", line 741, in fit
    self._fit_impl, model, train_dataloaders, val_dataloaders, datamodule, ckpt_path
  File "/home/xwm/anaconda3/envs/SV/lib/python3.6/site-packages/pytorch_lightning/trainer/trainer.py", line 685, in _call_and_handle_interrupt
    return trainer_fn(*args, **kwargs)
  File "/home/xwm/anaconda3/envs/SV/lib/python3.6/site-packages/pytorch_lightning/trainer/trainer.py", line 777, in _fit_impl
    self._run(model, ckpt_path=ckpt_path)
  File "/home/xwm/anaconda3/envs/SV/lib/python3.6/site-packages/pytorch_lightning/trainer/trainer.py", line 1145, in _run
    self.accelerator.setup(self)
  File "/home/xwm/anaconda3/envs/SV/lib/python3.6/site-packages/pytorch_lightning/accelerators/gpu.py", line 46, in setup
    return super().setup(trainer)
  File "/home/xwm/anaconda3/envs/SV/lib/python3.6/site-packages/pytorch_lightning/accelerators/accelerator.py", line 91, in setup
    self.setup_training_type_plugin()
  File "/home/xwm/anaconda3/envs/SV/lib/python3.6/site-packages/pytorch_lightning/accelerators/accelerator.py", line 363, in setup_training_type_plugin
    self.training_type_plugin.setup()
  File "/home/xwm/anaconda3/envs/SV/lib/python3.6/site-packages/pytorch_lightning/plugins/training_type/single_device.py", line 71, in setup
    self.model_to_device()
  File "/home/xwm/anaconda3/envs/SV/lib/python3.6/site-packages/pytorch_lightning/plugins/training_type/single_device.py", line 68, in model_to_device
    self._model.to(self.root_device)
  File "/home/xwm/anaconda3/envs/SV/lib/python3.6/site-packages/pytorch_lightning/core/mixins/device_dtype_mixin.py", line 111, in to
    return super().to(*args, **kwargs)
  File "/home/xwm/anaconda3/envs/SV/lib/python3.6/site-packages/torch/nn/modules/module.py", line 899, in to
    return self._apply(convert)
  File "/home/xwm/anaconda3/envs/SV/lib/python3.6/site-packages/torch/nn/modules/module.py", line 570, in _apply
    module._apply(fn)
  File "/home/xwm/anaconda3/envs/SV/lib/python3.6/site-packages/torch/nn/modules/module.py", line 570, in _apply
    module._apply(fn)
  File "/home/xwm/anaconda3/envs/SV/lib/python3.6/site-packages/torch/nn/modules/module.py", line 570, in _apply
    module._apply(fn)
  [Previous line repeated 1 more time]
  File "/home/xwm/anaconda3/envs/SV/lib/python3.6/site-packages/torch/nn/modules/module.py", line 593, in _apply
    param_applied = fn(param)
  File "/home/xwm/anaconda3/envs/SV/lib/python3.6/site-packages/torch/nn/modules/module.py", line 897, in convert
    return t.to(device, dtype if t.is_floating_point() or t.is_complex() else None, non_blocking)
RuntimeError: CUDA error: out of memory
CUDA kernel errors might be asynchronously reported at some other API call,so the stacktrace below might be incorrect.
For debugging consider passing CUDA_LAUNCH_BLOCKING=1.

Failure # 31 (occurred at 2022-06-14_23-39-18)
Traceback (most recent call last):
  File "/home/xwm/anaconda3/envs/SV/lib/python3.6/site-packages/ray/tune/trial_runner.py", line 886, in _process_trial
    results = self.trial_executor.fetch_result(trial)
  File "/home/xwm/anaconda3/envs/SV/lib/python3.6/site-packages/ray/tune/ray_trial_executor.py", line 675, in fetch_result
    result = ray.get(trial_future[0], timeout=DEFAULT_GET_TIMEOUT)
  File "/home/xwm/anaconda3/envs/SV/lib/python3.6/site-packages/ray/_private/client_mode_hook.py", line 105, in wrapper
    return func(*args, **kwargs)
  File "/home/xwm/anaconda3/envs/SV/lib/python3.6/site-packages/ray/worker.py", line 1763, in get
    raise value.as_instanceof_cause()
ray.exceptions.RayTaskError(TuneError): [36mray::ImplicitFunc.train()[39m (pid=211969, ip=192.168.249.74, repr=train_tune)
  File "/home/xwm/anaconda3/envs/SV/lib/python3.6/site-packages/ray/tune/trainable.py", line 319, in train
    result = self.step()
  File "/home/xwm/anaconda3/envs/SV/lib/python3.6/site-packages/ray/tune/function_runner.py", line 381, in step
    self._report_thread_runner_error(block=True)
  File "/home/xwm/anaconda3/envs/SV/lib/python3.6/site-packages/ray/tune/function_runner.py", line 532, in _report_thread_runner_error
    ("Trial raised an exception. Traceback:\n{}".format(err_tb_str)
ray.tune.error.TuneError: Trial raised an exception. Traceback:
[36mray::ImplicitFunc.train()[39m (pid=211969, ip=192.168.249.74, repr=train_tune)
  File "/home/xwm/anaconda3/envs/SV/lib/python3.6/site-packages/ray/tune/function_runner.py", line 262, in run
    self._entrypoint()
  File "/home/xwm/anaconda3/envs/SV/lib/python3.6/site-packages/ray/tune/function_runner.py", line 331, in entrypoint
    self._status_reporter.get_checkpoint())
  File "/home/xwm/anaconda3/envs/SV/lib/python3.6/site-packages/ray/tune/function_runner.py", line 600, in _trainable_func
    output = fn()
  File "/home/xwm/anaconda3/envs/SV/lib/python3.6/site-packages/ray/tune/utils/trainable.py", line 371, in inner
    trainable(config, **fn_kwargs)
  File "train.py", line 572, in train_tune
    trainer.fit(model)
  File "/home/xwm/anaconda3/envs/SV/lib/python3.6/site-packages/pytorch_lightning/trainer/trainer.py", line 741, in fit
    self._fit_impl, model, train_dataloaders, val_dataloaders, datamodule, ckpt_path
  File "/home/xwm/anaconda3/envs/SV/lib/python3.6/site-packages/pytorch_lightning/trainer/trainer.py", line 685, in _call_and_handle_interrupt
    return trainer_fn(*args, **kwargs)
  File "/home/xwm/anaconda3/envs/SV/lib/python3.6/site-packages/pytorch_lightning/trainer/trainer.py", line 777, in _fit_impl
    self._run(model, ckpt_path=ckpt_path)
  File "/home/xwm/anaconda3/envs/SV/lib/python3.6/site-packages/pytorch_lightning/trainer/trainer.py", line 1145, in _run
    self.accelerator.setup(self)
  File "/home/xwm/anaconda3/envs/SV/lib/python3.6/site-packages/pytorch_lightning/accelerators/gpu.py", line 46, in setup
    return super().setup(trainer)
  File "/home/xwm/anaconda3/envs/SV/lib/python3.6/site-packages/pytorch_lightning/accelerators/accelerator.py", line 91, in setup
    self.setup_training_type_plugin()
  File "/home/xwm/anaconda3/envs/SV/lib/python3.6/site-packages/pytorch_lightning/accelerators/accelerator.py", line 363, in setup_training_type_plugin
    self.training_type_plugin.setup()
  File "/home/xwm/anaconda3/envs/SV/lib/python3.6/site-packages/pytorch_lightning/plugins/training_type/single_device.py", line 71, in setup
    self.model_to_device()
  File "/home/xwm/anaconda3/envs/SV/lib/python3.6/site-packages/pytorch_lightning/plugins/training_type/single_device.py", line 68, in model_to_device
    self._model.to(self.root_device)
  File "/home/xwm/anaconda3/envs/SV/lib/python3.6/site-packages/pytorch_lightning/core/mixins/device_dtype_mixin.py", line 111, in to
    return super().to(*args, **kwargs)
  File "/home/xwm/anaconda3/envs/SV/lib/python3.6/site-packages/torch/nn/modules/module.py", line 899, in to
    return self._apply(convert)
  File "/home/xwm/anaconda3/envs/SV/lib/python3.6/site-packages/torch/nn/modules/module.py", line 570, in _apply
    module._apply(fn)
  File "/home/xwm/anaconda3/envs/SV/lib/python3.6/site-packages/torch/nn/modules/module.py", line 570, in _apply
    module._apply(fn)
  File "/home/xwm/anaconda3/envs/SV/lib/python3.6/site-packages/torch/nn/modules/module.py", line 570, in _apply
    module._apply(fn)
  [Previous line repeated 1 more time]
  File "/home/xwm/anaconda3/envs/SV/lib/python3.6/site-packages/torch/nn/modules/module.py", line 593, in _apply
    param_applied = fn(param)
  File "/home/xwm/anaconda3/envs/SV/lib/python3.6/site-packages/torch/nn/modules/module.py", line 897, in convert
    return t.to(device, dtype if t.is_floating_point() or t.is_complex() else None, non_blocking)
RuntimeError: CUDA error: out of memory
CUDA kernel errors might be asynchronously reported at some other API call,so the stacktrace below might be incorrect.
For debugging consider passing CUDA_LAUNCH_BLOCKING=1.

