Failure # 1 (occurred at 2022-06-15_22-34-48)
Traceback (most recent call last):
  File "/home/xwm/anaconda3/envs/SV/lib/python3.6/site-packages/ray/tune/trial_runner.py", line 886, in _process_trial
    results = self.trial_executor.fetch_result(trial)
  File "/home/xwm/anaconda3/envs/SV/lib/python3.6/site-packages/ray/tune/ray_trial_executor.py", line 675, in fetch_result
    result = ray.get(trial_future[0], timeout=DEFAULT_GET_TIMEOUT)
  File "/home/xwm/anaconda3/envs/SV/lib/python3.6/site-packages/ray/_private/client_mode_hook.py", line 105, in wrapper
    return func(*args, **kwargs)
  File "/home/xwm/anaconda3/envs/SV/lib/python3.6/site-packages/ray/worker.py", line 1763, in get
    raise value.as_instanceof_cause()
ray.exceptions.RayTaskError(TuneError): [36mray::ImplicitFunc.train()[39m (pid=219919, ip=192.168.249.74, repr=train_tune)
  File "/home/xwm/anaconda3/envs/SV/lib/python3.6/site-packages/ray/tune/trainable.py", line 319, in train
    result = self.step()
  File "/home/xwm/anaconda3/envs/SV/lib/python3.6/site-packages/ray/tune/function_runner.py", line 381, in step
    self._report_thread_runner_error(block=True)
  File "/home/xwm/anaconda3/envs/SV/lib/python3.6/site-packages/ray/tune/function_runner.py", line 532, in _report_thread_runner_error
    ("Trial raised an exception. Traceback:\n{}".format(err_tb_str)
ray.tune.error.TuneError: Trial raised an exception. Traceback:
[36mray::ImplicitFunc.train()[39m (pid=219919, ip=192.168.249.74, repr=train_tune)
  File "/home/xwm/anaconda3/envs/SV/lib/python3.6/site-packages/ray/tune/function_runner.py", line 262, in run
    self._entrypoint()
  File "/home/xwm/anaconda3/envs/SV/lib/python3.6/site-packages/ray/tune/function_runner.py", line 331, in entrypoint
    self._status_reporter.get_checkpoint())
  File "/home/xwm/anaconda3/envs/SV/lib/python3.6/site-packages/ray/tune/function_runner.py", line 600, in _trainable_func
    output = fn()
  File "/home/xwm/anaconda3/envs/SV/lib/python3.6/site-packages/ray/tune/utils/trainable.py", line 371, in inner
    trainable(config, **fn_kwargs)
  File "train.py", line 572, in train_tune
    on="validation_end"),
  File "/home/xwm/anaconda3/envs/SV/lib/python3.6/site-packages/pytorch_lightning/trainer/trainer.py", line 741, in fit
    self._fit_impl, model, train_dataloaders, val_dataloaders, datamodule, ckpt_path
  File "/home/xwm/anaconda3/envs/SV/lib/python3.6/site-packages/pytorch_lightning/trainer/trainer.py", line 685, in _call_and_handle_interrupt
    return trainer_fn(*args, **kwargs)
  File "/home/xwm/anaconda3/envs/SV/lib/python3.6/site-packages/pytorch_lightning/trainer/trainer.py", line 777, in _fit_impl
    self._run(model, ckpt_path=ckpt_path)
  File "/home/xwm/anaconda3/envs/SV/lib/python3.6/site-packages/pytorch_lightning/trainer/trainer.py", line 1145, in _run
    self.accelerator.setup(self)
  File "/home/xwm/anaconda3/envs/SV/lib/python3.6/site-packages/pytorch_lightning/accelerators/gpu.py", line 46, in setup
    return super().setup(trainer)
  File "/home/xwm/anaconda3/envs/SV/lib/python3.6/site-packages/pytorch_lightning/accelerators/accelerator.py", line 91, in setup
    self.setup_training_type_plugin()
  File "/home/xwm/anaconda3/envs/SV/lib/python3.6/site-packages/pytorch_lightning/accelerators/accelerator.py", line 363, in setup_training_type_plugin
    self.training_type_plugin.setup()
  File "/home/xwm/anaconda3/envs/SV/lib/python3.6/site-packages/pytorch_lightning/plugins/training_type/single_device.py", line 71, in setup
    self.model_to_device()
  File "/home/xwm/anaconda3/envs/SV/lib/python3.6/site-packages/pytorch_lightning/plugins/training_type/single_device.py", line 68, in model_to_device
    self._model.to(self.root_device)
  File "/home/xwm/anaconda3/envs/SV/lib/python3.6/site-packages/pytorch_lightning/core/mixins/device_dtype_mixin.py", line 111, in to
    return super().to(*args, **kwargs)
  File "/home/xwm/anaconda3/envs/SV/lib/python3.6/site-packages/torch/nn/modules/module.py", line 899, in to
    return self._apply(convert)
  File "/home/xwm/anaconda3/envs/SV/lib/python3.6/site-packages/torch/nn/modules/module.py", line 570, in _apply
    module._apply(fn)
  File "/home/xwm/anaconda3/envs/SV/lib/python3.6/site-packages/torch/nn/modules/module.py", line 570, in _apply
    module._apply(fn)
  File "/home/xwm/anaconda3/envs/SV/lib/python3.6/site-packages/torch/nn/modules/module.py", line 570, in _apply
    module._apply(fn)
  [Previous line repeated 1 more time]
  File "/home/xwm/anaconda3/envs/SV/lib/python3.6/site-packages/torch/nn/modules/module.py", line 593, in _apply
    param_applied = fn(param)
  File "/home/xwm/anaconda3/envs/SV/lib/python3.6/site-packages/torch/nn/modules/module.py", line 897, in convert
    return t.to(device, dtype if t.is_floating_point() or t.is_complex() else None, non_blocking)
RuntimeError: CUDA error: out of memory
CUDA kernel errors might be asynchronously reported at some other API call,so the stacktrace below might be incorrect.
For debugging consider passing CUDA_LAUNCH_BLOCKING=1.

Failure # 2 (occurred at 2022-06-15_22-35-50)
Traceback (most recent call last):
  File "/home/xwm/anaconda3/envs/SV/lib/python3.6/site-packages/ray/tune/trial_runner.py", line 886, in _process_trial
    results = self.trial_executor.fetch_result(trial)
  File "/home/xwm/anaconda3/envs/SV/lib/python3.6/site-packages/ray/tune/ray_trial_executor.py", line 675, in fetch_result
    result = ray.get(trial_future[0], timeout=DEFAULT_GET_TIMEOUT)
  File "/home/xwm/anaconda3/envs/SV/lib/python3.6/site-packages/ray/_private/client_mode_hook.py", line 105, in wrapper
    return func(*args, **kwargs)
  File "/home/xwm/anaconda3/envs/SV/lib/python3.6/site-packages/ray/worker.py", line 1763, in get
    raise value.as_instanceof_cause()
ray.exceptions.RayTaskError(TuneError): [36mray::ImplicitFunc.train()[39m (pid=219931, ip=192.168.249.74, repr=train_tune)
  File "/home/xwm/anaconda3/envs/SV/lib/python3.6/site-packages/ray/tune/trainable.py", line 319, in train
    result = self.step()
  File "/home/xwm/anaconda3/envs/SV/lib/python3.6/site-packages/ray/tune/function_runner.py", line 381, in step
    self._report_thread_runner_error(block=True)
  File "/home/xwm/anaconda3/envs/SV/lib/python3.6/site-packages/ray/tune/function_runner.py", line 532, in _report_thread_runner_error
    ("Trial raised an exception. Traceback:\n{}".format(err_tb_str)
ray.tune.error.TuneError: Trial raised an exception. Traceback:
[36mray::ImplicitFunc.train()[39m (pid=219931, ip=192.168.249.74, repr=train_tune)
  File "/home/xwm/anaconda3/envs/SV/lib/python3.6/site-packages/ray/tune/function_runner.py", line 262, in run
    self._entrypoint()
  File "/home/xwm/anaconda3/envs/SV/lib/python3.6/site-packages/ray/tune/function_runner.py", line 331, in entrypoint
    self._status_reporter.get_checkpoint())
  File "/home/xwm/anaconda3/envs/SV/lib/python3.6/site-packages/ray/tune/function_runner.py", line 600, in _trainable_func
    output = fn()
  File "/home/xwm/anaconda3/envs/SV/lib/python3.6/site-packages/ray/tune/utils/trainable.py", line 371, in inner
    trainable(config, **fn_kwargs)
  File "train.py", line 572, in train_tune
    on="validation_end"),
  File "/home/xwm/anaconda3/envs/SV/lib/python3.6/site-packages/pytorch_lightning/trainer/trainer.py", line 741, in fit
    self._fit_impl, model, train_dataloaders, val_dataloaders, datamodule, ckpt_path
  File "/home/xwm/anaconda3/envs/SV/lib/python3.6/site-packages/pytorch_lightning/trainer/trainer.py", line 685, in _call_and_handle_interrupt
    return trainer_fn(*args, **kwargs)
  File "/home/xwm/anaconda3/envs/SV/lib/python3.6/site-packages/pytorch_lightning/trainer/trainer.py", line 777, in _fit_impl
    self._run(model, ckpt_path=ckpt_path)
  File "/home/xwm/anaconda3/envs/SV/lib/python3.6/site-packages/pytorch_lightning/trainer/trainer.py", line 1145, in _run
    self.accelerator.setup(self)
  File "/home/xwm/anaconda3/envs/SV/lib/python3.6/site-packages/pytorch_lightning/accelerators/gpu.py", line 46, in setup
    return super().setup(trainer)
  File "/home/xwm/anaconda3/envs/SV/lib/python3.6/site-packages/pytorch_lightning/accelerators/accelerator.py", line 91, in setup
    self.setup_training_type_plugin()
  File "/home/xwm/anaconda3/envs/SV/lib/python3.6/site-packages/pytorch_lightning/accelerators/accelerator.py", line 363, in setup_training_type_plugin
    self.training_type_plugin.setup()
  File "/home/xwm/anaconda3/envs/SV/lib/python3.6/site-packages/pytorch_lightning/plugins/training_type/single_device.py", line 71, in setup
    self.model_to_device()
  File "/home/xwm/anaconda3/envs/SV/lib/python3.6/site-packages/pytorch_lightning/plugins/training_type/single_device.py", line 68, in model_to_device
    self._model.to(self.root_device)
  File "/home/xwm/anaconda3/envs/SV/lib/python3.6/site-packages/pytorch_lightning/core/mixins/device_dtype_mixin.py", line 111, in to
    return super().to(*args, **kwargs)
  File "/home/xwm/anaconda3/envs/SV/lib/python3.6/site-packages/torch/nn/modules/module.py", line 899, in to
    return self._apply(convert)
  File "/home/xwm/anaconda3/envs/SV/lib/python3.6/site-packages/torch/nn/modules/module.py", line 570, in _apply
    module._apply(fn)
  File "/home/xwm/anaconda3/envs/SV/lib/python3.6/site-packages/torch/nn/modules/module.py", line 570, in _apply
    module._apply(fn)
  File "/home/xwm/anaconda3/envs/SV/lib/python3.6/site-packages/torch/nn/modules/module.py", line 570, in _apply
    module._apply(fn)
  [Previous line repeated 1 more time]
  File "/home/xwm/anaconda3/envs/SV/lib/python3.6/site-packages/torch/nn/modules/module.py", line 593, in _apply
    param_applied = fn(param)
  File "/home/xwm/anaconda3/envs/SV/lib/python3.6/site-packages/torch/nn/modules/module.py", line 897, in convert
    return t.to(device, dtype if t.is_floating_point() or t.is_complex() else None, non_blocking)
RuntimeError: CUDA error: out of memory
CUDA kernel errors might be asynchronously reported at some other API call,so the stacktrace below might be incorrect.
For debugging consider passing CUDA_LAUNCH_BLOCKING=1.

Failure # 3 (occurred at 2022-06-15_22-36-58)
Traceback (most recent call last):
  File "/home/xwm/anaconda3/envs/SV/lib/python3.6/site-packages/ray/tune/trial_runner.py", line 886, in _process_trial
    results = self.trial_executor.fetch_result(trial)
  File "/home/xwm/anaconda3/envs/SV/lib/python3.6/site-packages/ray/tune/ray_trial_executor.py", line 675, in fetch_result
    result = ray.get(trial_future[0], timeout=DEFAULT_GET_TIMEOUT)
  File "/home/xwm/anaconda3/envs/SV/lib/python3.6/site-packages/ray/_private/client_mode_hook.py", line 105, in wrapper
    return func(*args, **kwargs)
  File "/home/xwm/anaconda3/envs/SV/lib/python3.6/site-packages/ray/worker.py", line 1763, in get
    raise value.as_instanceof_cause()
ray.exceptions.RayTaskError(TuneError): [36mray::ImplicitFunc.train()[39m (pid=219926, ip=192.168.249.74, repr=train_tune)
  File "/home/xwm/anaconda3/envs/SV/lib/python3.6/site-packages/ray/tune/trainable.py", line 319, in train
    result = self.step()
  File "/home/xwm/anaconda3/envs/SV/lib/python3.6/site-packages/ray/tune/function_runner.py", line 381, in step
    self._report_thread_runner_error(block=True)
  File "/home/xwm/anaconda3/envs/SV/lib/python3.6/site-packages/ray/tune/function_runner.py", line 532, in _report_thread_runner_error
    ("Trial raised an exception. Traceback:\n{}".format(err_tb_str)
ray.tune.error.TuneError: Trial raised an exception. Traceback:
[36mray::ImplicitFunc.train()[39m (pid=219926, ip=192.168.249.74, repr=train_tune)
  File "/home/xwm/anaconda3/envs/SV/lib/python3.6/site-packages/ray/tune/function_runner.py", line 262, in run
    self._entrypoint()
  File "/home/xwm/anaconda3/envs/SV/lib/python3.6/site-packages/ray/tune/function_runner.py", line 331, in entrypoint
    self._status_reporter.get_checkpoint())
  File "/home/xwm/anaconda3/envs/SV/lib/python3.6/site-packages/ray/tune/function_runner.py", line 600, in _trainable_func
    output = fn()
  File "/home/xwm/anaconda3/envs/SV/lib/python3.6/site-packages/ray/tune/utils/trainable.py", line 371, in inner
    trainable(config, **fn_kwargs)
  File "train.py", line 572, in train_tune
    on="validation_end"),
  File "/home/xwm/anaconda3/envs/SV/lib/python3.6/site-packages/pytorch_lightning/trainer/trainer.py", line 741, in fit
    self._fit_impl, model, train_dataloaders, val_dataloaders, datamodule, ckpt_path
  File "/home/xwm/anaconda3/envs/SV/lib/python3.6/site-packages/pytorch_lightning/trainer/trainer.py", line 685, in _call_and_handle_interrupt
    return trainer_fn(*args, **kwargs)
  File "/home/xwm/anaconda3/envs/SV/lib/python3.6/site-packages/pytorch_lightning/trainer/trainer.py", line 777, in _fit_impl
    self._run(model, ckpt_path=ckpt_path)
  File "/home/xwm/anaconda3/envs/SV/lib/python3.6/site-packages/pytorch_lightning/trainer/trainer.py", line 1145, in _run
    self.accelerator.setup(self)
  File "/home/xwm/anaconda3/envs/SV/lib/python3.6/site-packages/pytorch_lightning/accelerators/gpu.py", line 46, in setup
    return super().setup(trainer)
  File "/home/xwm/anaconda3/envs/SV/lib/python3.6/site-packages/pytorch_lightning/accelerators/accelerator.py", line 91, in setup
    self.setup_training_type_plugin()
  File "/home/xwm/anaconda3/envs/SV/lib/python3.6/site-packages/pytorch_lightning/accelerators/accelerator.py", line 363, in setup_training_type_plugin
    self.training_type_plugin.setup()
  File "/home/xwm/anaconda3/envs/SV/lib/python3.6/site-packages/pytorch_lightning/plugins/training_type/single_device.py", line 71, in setup
    self.model_to_device()
  File "/home/xwm/anaconda3/envs/SV/lib/python3.6/site-packages/pytorch_lightning/plugins/training_type/single_device.py", line 68, in model_to_device
    self._model.to(self.root_device)
  File "/home/xwm/anaconda3/envs/SV/lib/python3.6/site-packages/pytorch_lightning/core/mixins/device_dtype_mixin.py", line 111, in to
    return super().to(*args, **kwargs)
  File "/home/xwm/anaconda3/envs/SV/lib/python3.6/site-packages/torch/nn/modules/module.py", line 899, in to
    return self._apply(convert)
  File "/home/xwm/anaconda3/envs/SV/lib/python3.6/site-packages/torch/nn/modules/module.py", line 570, in _apply
    module._apply(fn)
  File "/home/xwm/anaconda3/envs/SV/lib/python3.6/site-packages/torch/nn/modules/module.py", line 570, in _apply
    module._apply(fn)
  File "/home/xwm/anaconda3/envs/SV/lib/python3.6/site-packages/torch/nn/modules/module.py", line 570, in _apply
    module._apply(fn)
  [Previous line repeated 1 more time]
  File "/home/xwm/anaconda3/envs/SV/lib/python3.6/site-packages/torch/nn/modules/module.py", line 593, in _apply
    param_applied = fn(param)
  File "/home/xwm/anaconda3/envs/SV/lib/python3.6/site-packages/torch/nn/modules/module.py", line 897, in convert
    return t.to(device, dtype if t.is_floating_point() or t.is_complex() else None, non_blocking)
RuntimeError: CUDA error: out of memory
CUDA kernel errors might be asynchronously reported at some other API call,so the stacktrace below might be incorrect.
For debugging consider passing CUDA_LAUNCH_BLOCKING=1.

Failure # 4 (occurred at 2022-06-15_22-38-56)
Traceback (most recent call last):
  File "/home/xwm/anaconda3/envs/SV/lib/python3.6/site-packages/ray/tune/trial_runner.py", line 886, in _process_trial
    results = self.trial_executor.fetch_result(trial)
  File "/home/xwm/anaconda3/envs/SV/lib/python3.6/site-packages/ray/tune/ray_trial_executor.py", line 675, in fetch_result
    result = ray.get(trial_future[0], timeout=DEFAULT_GET_TIMEOUT)
  File "/home/xwm/anaconda3/envs/SV/lib/python3.6/site-packages/ray/_private/client_mode_hook.py", line 105, in wrapper
    return func(*args, **kwargs)
  File "/home/xwm/anaconda3/envs/SV/lib/python3.6/site-packages/ray/worker.py", line 1763, in get
    raise value.as_instanceof_cause()
ray.exceptions.RayTaskError(TuneError): [36mray::ImplicitFunc.train()[39m (pid=37857, ip=192.168.249.74, repr=train_tune)
  File "/home/xwm/anaconda3/envs/SV/lib/python3.6/site-packages/ray/tune/trainable.py", line 319, in train
    result = self.step()
  File "/home/xwm/anaconda3/envs/SV/lib/python3.6/site-packages/ray/tune/function_runner.py", line 381, in step
    self._report_thread_runner_error(block=True)
  File "/home/xwm/anaconda3/envs/SV/lib/python3.6/site-packages/ray/tune/function_runner.py", line 532, in _report_thread_runner_error
    ("Trial raised an exception. Traceback:\n{}".format(err_tb_str)
ray.tune.error.TuneError: Trial raised an exception. Traceback:
[36mray::ImplicitFunc.train()[39m (pid=37857, ip=192.168.249.74, repr=train_tune)
  File "/home/xwm/anaconda3/envs/SV/lib/python3.6/site-packages/ray/tune/function_runner.py", line 262, in run
    self._entrypoint()
  File "/home/xwm/anaconda3/envs/SV/lib/python3.6/site-packages/ray/tune/function_runner.py", line 331, in entrypoint
    self._status_reporter.get_checkpoint())
  File "/home/xwm/anaconda3/envs/SV/lib/python3.6/site-packages/ray/tune/function_runner.py", line 600, in _trainable_func
    output = fn()
  File "/home/xwm/anaconda3/envs/SV/lib/python3.6/site-packages/ray/tune/utils/trainable.py", line 371, in inner
    trainable(config, **fn_kwargs)
  File "train.py", line 572, in train_tune
    on="validation_end"),
  File "/home/xwm/anaconda3/envs/SV/lib/python3.6/site-packages/pytorch_lightning/trainer/trainer.py", line 741, in fit
    self._fit_impl, model, train_dataloaders, val_dataloaders, datamodule, ckpt_path
  File "/home/xwm/anaconda3/envs/SV/lib/python3.6/site-packages/pytorch_lightning/trainer/trainer.py", line 685, in _call_and_handle_interrupt
    return trainer_fn(*args, **kwargs)
  File "/home/xwm/anaconda3/envs/SV/lib/python3.6/site-packages/pytorch_lightning/trainer/trainer.py", line 777, in _fit_impl
    self._run(model, ckpt_path=ckpt_path)
  File "/home/xwm/anaconda3/envs/SV/lib/python3.6/site-packages/pytorch_lightning/trainer/trainer.py", line 1145, in _run
    self.accelerator.setup(self)
  File "/home/xwm/anaconda3/envs/SV/lib/python3.6/site-packages/pytorch_lightning/accelerators/gpu.py", line 46, in setup
    return super().setup(trainer)
  File "/home/xwm/anaconda3/envs/SV/lib/python3.6/site-packages/pytorch_lightning/accelerators/accelerator.py", line 91, in setup
    self.setup_training_type_plugin()
  File "/home/xwm/anaconda3/envs/SV/lib/python3.6/site-packages/pytorch_lightning/accelerators/accelerator.py", line 363, in setup_training_type_plugin
    self.training_type_plugin.setup()
  File "/home/xwm/anaconda3/envs/SV/lib/python3.6/site-packages/pytorch_lightning/plugins/training_type/single_device.py", line 71, in setup
    self.model_to_device()
  File "/home/xwm/anaconda3/envs/SV/lib/python3.6/site-packages/pytorch_lightning/plugins/training_type/single_device.py", line 68, in model_to_device
    self._model.to(self.root_device)
  File "/home/xwm/anaconda3/envs/SV/lib/python3.6/site-packages/pytorch_lightning/core/mixins/device_dtype_mixin.py", line 111, in to
    return super().to(*args, **kwargs)
  File "/home/xwm/anaconda3/envs/SV/lib/python3.6/site-packages/torch/nn/modules/module.py", line 899, in to
    return self._apply(convert)
  File "/home/xwm/anaconda3/envs/SV/lib/python3.6/site-packages/torch/nn/modules/module.py", line 570, in _apply
    module._apply(fn)
  File "/home/xwm/anaconda3/envs/SV/lib/python3.6/site-packages/torch/nn/modules/module.py", line 570, in _apply
    module._apply(fn)
  File "/home/xwm/anaconda3/envs/SV/lib/python3.6/site-packages/torch/nn/modules/module.py", line 570, in _apply
    module._apply(fn)
  [Previous line repeated 1 more time]
  File "/home/xwm/anaconda3/envs/SV/lib/python3.6/site-packages/torch/nn/modules/module.py", line 593, in _apply
    param_applied = fn(param)
  File "/home/xwm/anaconda3/envs/SV/lib/python3.6/site-packages/torch/nn/modules/module.py", line 897, in convert
    return t.to(device, dtype if t.is_floating_point() or t.is_complex() else None, non_blocking)
RuntimeError: CUDA error: out of memory
CUDA kernel errors might be asynchronously reported at some other API call,so the stacktrace below might be incorrect.
For debugging consider passing CUDA_LAUNCH_BLOCKING=1.

Failure # 5 (occurred at 2022-06-15_22-40-08)
Traceback (most recent call last):
  File "/home/xwm/anaconda3/envs/SV/lib/python3.6/site-packages/ray/tune/trial_runner.py", line 886, in _process_trial
    results = self.trial_executor.fetch_result(trial)
  File "/home/xwm/anaconda3/envs/SV/lib/python3.6/site-packages/ray/tune/ray_trial_executor.py", line 675, in fetch_result
    result = ray.get(trial_future[0], timeout=DEFAULT_GET_TIMEOUT)
  File "/home/xwm/anaconda3/envs/SV/lib/python3.6/site-packages/ray/_private/client_mode_hook.py", line 105, in wrapper
    return func(*args, **kwargs)
  File "/home/xwm/anaconda3/envs/SV/lib/python3.6/site-packages/ray/worker.py", line 1763, in get
    raise value.as_instanceof_cause()
ray.exceptions.RayTaskError(TuneError): [36mray::ImplicitFunc.train()[39m (pid=43932, ip=192.168.249.74, repr=train_tune)
  File "/home/xwm/anaconda3/envs/SV/lib/python3.6/site-packages/ray/tune/trainable.py", line 319, in train
    result = self.step()
  File "/home/xwm/anaconda3/envs/SV/lib/python3.6/site-packages/ray/tune/function_runner.py", line 381, in step
    self._report_thread_runner_error(block=True)
  File "/home/xwm/anaconda3/envs/SV/lib/python3.6/site-packages/ray/tune/function_runner.py", line 532, in _report_thread_runner_error
    ("Trial raised an exception. Traceback:\n{}".format(err_tb_str)
ray.tune.error.TuneError: Trial raised an exception. Traceback:
[36mray::ImplicitFunc.train()[39m (pid=43932, ip=192.168.249.74, repr=train_tune)
  File "/home/xwm/anaconda3/envs/SV/lib/python3.6/site-packages/ray/tune/function_runner.py", line 262, in run
    self._entrypoint()
  File "/home/xwm/anaconda3/envs/SV/lib/python3.6/site-packages/ray/tune/function_runner.py", line 331, in entrypoint
    self._status_reporter.get_checkpoint())
  File "/home/xwm/anaconda3/envs/SV/lib/python3.6/site-packages/ray/tune/function_runner.py", line 600, in _trainable_func
    output = fn()
  File "/home/xwm/anaconda3/envs/SV/lib/python3.6/site-packages/ray/tune/utils/trainable.py", line 371, in inner
    trainable(config, **fn_kwargs)
  File "train.py", line 572, in train_tune
    on="validation_end"),
  File "/home/xwm/anaconda3/envs/SV/lib/python3.6/site-packages/pytorch_lightning/trainer/trainer.py", line 741, in fit
    self._fit_impl, model, train_dataloaders, val_dataloaders, datamodule, ckpt_path
  File "/home/xwm/anaconda3/envs/SV/lib/python3.6/site-packages/pytorch_lightning/trainer/trainer.py", line 685, in _call_and_handle_interrupt
    return trainer_fn(*args, **kwargs)
  File "/home/xwm/anaconda3/envs/SV/lib/python3.6/site-packages/pytorch_lightning/trainer/trainer.py", line 777, in _fit_impl
    self._run(model, ckpt_path=ckpt_path)
  File "/home/xwm/anaconda3/envs/SV/lib/python3.6/site-packages/pytorch_lightning/trainer/trainer.py", line 1145, in _run
    self.accelerator.setup(self)
  File "/home/xwm/anaconda3/envs/SV/lib/python3.6/site-packages/pytorch_lightning/accelerators/gpu.py", line 46, in setup
    return super().setup(trainer)
  File "/home/xwm/anaconda3/envs/SV/lib/python3.6/site-packages/pytorch_lightning/accelerators/accelerator.py", line 91, in setup
    self.setup_training_type_plugin()
  File "/home/xwm/anaconda3/envs/SV/lib/python3.6/site-packages/pytorch_lightning/accelerators/accelerator.py", line 363, in setup_training_type_plugin
    self.training_type_plugin.setup()
  File "/home/xwm/anaconda3/envs/SV/lib/python3.6/site-packages/pytorch_lightning/plugins/training_type/single_device.py", line 71, in setup
    self.model_to_device()
  File "/home/xwm/anaconda3/envs/SV/lib/python3.6/site-packages/pytorch_lightning/plugins/training_type/single_device.py", line 68, in model_to_device
    self._model.to(self.root_device)
  File "/home/xwm/anaconda3/envs/SV/lib/python3.6/site-packages/pytorch_lightning/core/mixins/device_dtype_mixin.py", line 111, in to
    return super().to(*args, **kwargs)
  File "/home/xwm/anaconda3/envs/SV/lib/python3.6/site-packages/torch/nn/modules/module.py", line 899, in to
    return self._apply(convert)
  File "/home/xwm/anaconda3/envs/SV/lib/python3.6/site-packages/torch/nn/modules/module.py", line 570, in _apply
    module._apply(fn)
  File "/home/xwm/anaconda3/envs/SV/lib/python3.6/site-packages/torch/nn/modules/module.py", line 570, in _apply
    module._apply(fn)
  File "/home/xwm/anaconda3/envs/SV/lib/python3.6/site-packages/torch/nn/modules/module.py", line 570, in _apply
    module._apply(fn)
  [Previous line repeated 1 more time]
  File "/home/xwm/anaconda3/envs/SV/lib/python3.6/site-packages/torch/nn/modules/module.py", line 593, in _apply
    param_applied = fn(param)
  File "/home/xwm/anaconda3/envs/SV/lib/python3.6/site-packages/torch/nn/modules/module.py", line 897, in convert
    return t.to(device, dtype if t.is_floating_point() or t.is_complex() else None, non_blocking)
RuntimeError: CUDA error: out of memory
CUDA kernel errors might be asynchronously reported at some other API call,so the stacktrace below might be incorrect.
For debugging consider passing CUDA_LAUNCH_BLOCKING=1.

Failure # 6 (occurred at 2022-06-15_22-41-12)
Traceback (most recent call last):
  File "/home/xwm/anaconda3/envs/SV/lib/python3.6/site-packages/ray/tune/trial_runner.py", line 886, in _process_trial
    results = self.trial_executor.fetch_result(trial)
  File "/home/xwm/anaconda3/envs/SV/lib/python3.6/site-packages/ray/tune/ray_trial_executor.py", line 675, in fetch_result
    result = ray.get(trial_future[0], timeout=DEFAULT_GET_TIMEOUT)
  File "/home/xwm/anaconda3/envs/SV/lib/python3.6/site-packages/ray/_private/client_mode_hook.py", line 105, in wrapper
    return func(*args, **kwargs)
  File "/home/xwm/anaconda3/envs/SV/lib/python3.6/site-packages/ray/worker.py", line 1763, in get
    raise value.as_instanceof_cause()
ray.exceptions.RayTaskError(TuneError): [36mray::ImplicitFunc.train()[39m (pid=48000, ip=192.168.249.74, repr=train_tune)
  File "/home/xwm/anaconda3/envs/SV/lib/python3.6/site-packages/ray/tune/trainable.py", line 319, in train
    result = self.step()
  File "/home/xwm/anaconda3/envs/SV/lib/python3.6/site-packages/ray/tune/function_runner.py", line 381, in step
    self._report_thread_runner_error(block=True)
  File "/home/xwm/anaconda3/envs/SV/lib/python3.6/site-packages/ray/tune/function_runner.py", line 532, in _report_thread_runner_error
    ("Trial raised an exception. Traceback:\n{}".format(err_tb_str)
ray.tune.error.TuneError: Trial raised an exception. Traceback:
[36mray::ImplicitFunc.train()[39m (pid=48000, ip=192.168.249.74, repr=train_tune)
  File "/home/xwm/anaconda3/envs/SV/lib/python3.6/site-packages/ray/tune/function_runner.py", line 262, in run
    self._entrypoint()
  File "/home/xwm/anaconda3/envs/SV/lib/python3.6/site-packages/ray/tune/function_runner.py", line 331, in entrypoint
    self._status_reporter.get_checkpoint())
  File "/home/xwm/anaconda3/envs/SV/lib/python3.6/site-packages/ray/tune/function_runner.py", line 600, in _trainable_func
    output = fn()
  File "/home/xwm/anaconda3/envs/SV/lib/python3.6/site-packages/ray/tune/utils/trainable.py", line 371, in inner
    trainable(config, **fn_kwargs)
  File "train.py", line 572, in train_tune
    on="validation_end"),
  File "/home/xwm/anaconda3/envs/SV/lib/python3.6/site-packages/pytorch_lightning/trainer/trainer.py", line 741, in fit
    self._fit_impl, model, train_dataloaders, val_dataloaders, datamodule, ckpt_path
  File "/home/xwm/anaconda3/envs/SV/lib/python3.6/site-packages/pytorch_lightning/trainer/trainer.py", line 685, in _call_and_handle_interrupt
    return trainer_fn(*args, **kwargs)
  File "/home/xwm/anaconda3/envs/SV/lib/python3.6/site-packages/pytorch_lightning/trainer/trainer.py", line 777, in _fit_impl
    self._run(model, ckpt_path=ckpt_path)
  File "/home/xwm/anaconda3/envs/SV/lib/python3.6/site-packages/pytorch_lightning/trainer/trainer.py", line 1145, in _run
    self.accelerator.setup(self)
  File "/home/xwm/anaconda3/envs/SV/lib/python3.6/site-packages/pytorch_lightning/accelerators/gpu.py", line 46, in setup
    return super().setup(trainer)
  File "/home/xwm/anaconda3/envs/SV/lib/python3.6/site-packages/pytorch_lightning/accelerators/accelerator.py", line 91, in setup
    self.setup_training_type_plugin()
  File "/home/xwm/anaconda3/envs/SV/lib/python3.6/site-packages/pytorch_lightning/accelerators/accelerator.py", line 363, in setup_training_type_plugin
    self.training_type_plugin.setup()
  File "/home/xwm/anaconda3/envs/SV/lib/python3.6/site-packages/pytorch_lightning/plugins/training_type/single_device.py", line 71, in setup
    self.model_to_device()
  File "/home/xwm/anaconda3/envs/SV/lib/python3.6/site-packages/pytorch_lightning/plugins/training_type/single_device.py", line 68, in model_to_device
    self._model.to(self.root_device)
  File "/home/xwm/anaconda3/envs/SV/lib/python3.6/site-packages/pytorch_lightning/core/mixins/device_dtype_mixin.py", line 111, in to
    return super().to(*args, **kwargs)
  File "/home/xwm/anaconda3/envs/SV/lib/python3.6/site-packages/torch/nn/modules/module.py", line 899, in to
    return self._apply(convert)
  File "/home/xwm/anaconda3/envs/SV/lib/python3.6/site-packages/torch/nn/modules/module.py", line 570, in _apply
    module._apply(fn)
  File "/home/xwm/anaconda3/envs/SV/lib/python3.6/site-packages/torch/nn/modules/module.py", line 570, in _apply
    module._apply(fn)
  File "/home/xwm/anaconda3/envs/SV/lib/python3.6/site-packages/torch/nn/modules/module.py", line 570, in _apply
    module._apply(fn)
  [Previous line repeated 1 more time]
  File "/home/xwm/anaconda3/envs/SV/lib/python3.6/site-packages/torch/nn/modules/module.py", line 593, in _apply
    param_applied = fn(param)
  File "/home/xwm/anaconda3/envs/SV/lib/python3.6/site-packages/torch/nn/modules/module.py", line 897, in convert
    return t.to(device, dtype if t.is_floating_point() or t.is_complex() else None, non_blocking)
RuntimeError: CUDA error: out of memory
CUDA kernel errors might be asynchronously reported at some other API call,so the stacktrace below might be incorrect.
For debugging consider passing CUDA_LAUNCH_BLOCKING=1.

Failure # 7 (occurred at 2022-06-15_22-42-18)
Traceback (most recent call last):
  File "/home/xwm/anaconda3/envs/SV/lib/python3.6/site-packages/ray/tune/trial_runner.py", line 886, in _process_trial
    results = self.trial_executor.fetch_result(trial)
  File "/home/xwm/anaconda3/envs/SV/lib/python3.6/site-packages/ray/tune/ray_trial_executor.py", line 675, in fetch_result
    result = ray.get(trial_future[0], timeout=DEFAULT_GET_TIMEOUT)
  File "/home/xwm/anaconda3/envs/SV/lib/python3.6/site-packages/ray/_private/client_mode_hook.py", line 105, in wrapper
    return func(*args, **kwargs)
  File "/home/xwm/anaconda3/envs/SV/lib/python3.6/site-packages/ray/worker.py", line 1763, in get
    raise value.as_instanceof_cause()
ray.exceptions.RayTaskError(TuneError): [36mray::ImplicitFunc.train()[39m (pid=50231, ip=192.168.249.74, repr=train_tune)
  File "/home/xwm/anaconda3/envs/SV/lib/python3.6/site-packages/ray/tune/trainable.py", line 319, in train
    result = self.step()
  File "/home/xwm/anaconda3/envs/SV/lib/python3.6/site-packages/ray/tune/function_runner.py", line 381, in step
    self._report_thread_runner_error(block=True)
  File "/home/xwm/anaconda3/envs/SV/lib/python3.6/site-packages/ray/tune/function_runner.py", line 532, in _report_thread_runner_error
    ("Trial raised an exception. Traceback:\n{}".format(err_tb_str)
ray.tune.error.TuneError: Trial raised an exception. Traceback:
[36mray::ImplicitFunc.train()[39m (pid=50231, ip=192.168.249.74, repr=train_tune)
  File "/home/xwm/anaconda3/envs/SV/lib/python3.6/site-packages/ray/tune/function_runner.py", line 262, in run
    self._entrypoint()
  File "/home/xwm/anaconda3/envs/SV/lib/python3.6/site-packages/ray/tune/function_runner.py", line 331, in entrypoint
    self._status_reporter.get_checkpoint())
  File "/home/xwm/anaconda3/envs/SV/lib/python3.6/site-packages/ray/tune/function_runner.py", line 600, in _trainable_func
    output = fn()
  File "/home/xwm/anaconda3/envs/SV/lib/python3.6/site-packages/ray/tune/utils/trainable.py", line 371, in inner
    trainable(config, **fn_kwargs)
  File "train.py", line 572, in train_tune
    on="validation_end"),
  File "/home/xwm/anaconda3/envs/SV/lib/python3.6/site-packages/pytorch_lightning/trainer/trainer.py", line 741, in fit
    self._fit_impl, model, train_dataloaders, val_dataloaders, datamodule, ckpt_path
  File "/home/xwm/anaconda3/envs/SV/lib/python3.6/site-packages/pytorch_lightning/trainer/trainer.py", line 685, in _call_and_handle_interrupt
    return trainer_fn(*args, **kwargs)
  File "/home/xwm/anaconda3/envs/SV/lib/python3.6/site-packages/pytorch_lightning/trainer/trainer.py", line 777, in _fit_impl
    self._run(model, ckpt_path=ckpt_path)
  File "/home/xwm/anaconda3/envs/SV/lib/python3.6/site-packages/pytorch_lightning/trainer/trainer.py", line 1145, in _run
    self.accelerator.setup(self)
  File "/home/xwm/anaconda3/envs/SV/lib/python3.6/site-packages/pytorch_lightning/accelerators/gpu.py", line 46, in setup
    return super().setup(trainer)
  File "/home/xwm/anaconda3/envs/SV/lib/python3.6/site-packages/pytorch_lightning/accelerators/accelerator.py", line 91, in setup
    self.setup_training_type_plugin()
  File "/home/xwm/anaconda3/envs/SV/lib/python3.6/site-packages/pytorch_lightning/accelerators/accelerator.py", line 363, in setup_training_type_plugin
    self.training_type_plugin.setup()
  File "/home/xwm/anaconda3/envs/SV/lib/python3.6/site-packages/pytorch_lightning/plugins/training_type/single_device.py", line 71, in setup
    self.model_to_device()
  File "/home/xwm/anaconda3/envs/SV/lib/python3.6/site-packages/pytorch_lightning/plugins/training_type/single_device.py", line 68, in model_to_device
    self._model.to(self.root_device)
  File "/home/xwm/anaconda3/envs/SV/lib/python3.6/site-packages/pytorch_lightning/core/mixins/device_dtype_mixin.py", line 111, in to
    return super().to(*args, **kwargs)
  File "/home/xwm/anaconda3/envs/SV/lib/python3.6/site-packages/torch/nn/modules/module.py", line 899, in to
    return self._apply(convert)
  File "/home/xwm/anaconda3/envs/SV/lib/python3.6/site-packages/torch/nn/modules/module.py", line 570, in _apply
    module._apply(fn)
  File "/home/xwm/anaconda3/envs/SV/lib/python3.6/site-packages/torch/nn/modules/module.py", line 570, in _apply
    module._apply(fn)
  File "/home/xwm/anaconda3/envs/SV/lib/python3.6/site-packages/torch/nn/modules/module.py", line 570, in _apply
    module._apply(fn)
  [Previous line repeated 1 more time]
  File "/home/xwm/anaconda3/envs/SV/lib/python3.6/site-packages/torch/nn/modules/module.py", line 593, in _apply
    param_applied = fn(param)
  File "/home/xwm/anaconda3/envs/SV/lib/python3.6/site-packages/torch/nn/modules/module.py", line 897, in convert
    return t.to(device, dtype if t.is_floating_point() or t.is_complex() else None, non_blocking)
RuntimeError: CUDA error: out of memory
CUDA kernel errors might be asynchronously reported at some other API call,so the stacktrace below might be incorrect.
For debugging consider passing CUDA_LAUNCH_BLOCKING=1.

Failure # 8 (occurred at 2022-06-15_22-43-30)
Traceback (most recent call last):
  File "/home/xwm/anaconda3/envs/SV/lib/python3.6/site-packages/ray/tune/trial_runner.py", line 886, in _process_trial
    results = self.trial_executor.fetch_result(trial)
  File "/home/xwm/anaconda3/envs/SV/lib/python3.6/site-packages/ray/tune/ray_trial_executor.py", line 675, in fetch_result
    result = ray.get(trial_future[0], timeout=DEFAULT_GET_TIMEOUT)
  File "/home/xwm/anaconda3/envs/SV/lib/python3.6/site-packages/ray/_private/client_mode_hook.py", line 105, in wrapper
    return func(*args, **kwargs)
  File "/home/xwm/anaconda3/envs/SV/lib/python3.6/site-packages/ray/worker.py", line 1763, in get
    raise value.as_instanceof_cause()
ray.exceptions.RayTaskError(TuneError): [36mray::ImplicitFunc.train()[39m (pid=54449, ip=192.168.249.74, repr=train_tune)
  File "/home/xwm/anaconda3/envs/SV/lib/python3.6/site-packages/ray/tune/trainable.py", line 319, in train
    result = self.step()
  File "/home/xwm/anaconda3/envs/SV/lib/python3.6/site-packages/ray/tune/function_runner.py", line 381, in step
    self._report_thread_runner_error(block=True)
  File "/home/xwm/anaconda3/envs/SV/lib/python3.6/site-packages/ray/tune/function_runner.py", line 532, in _report_thread_runner_error
    ("Trial raised an exception. Traceback:\n{}".format(err_tb_str)
ray.tune.error.TuneError: Trial raised an exception. Traceback:
[36mray::ImplicitFunc.train()[39m (pid=54449, ip=192.168.249.74, repr=train_tune)
  File "/home/xwm/anaconda3/envs/SV/lib/python3.6/site-packages/ray/tune/function_runner.py", line 262, in run
    self._entrypoint()
  File "/home/xwm/anaconda3/envs/SV/lib/python3.6/site-packages/ray/tune/function_runner.py", line 331, in entrypoint
    self._status_reporter.get_checkpoint())
  File "/home/xwm/anaconda3/envs/SV/lib/python3.6/site-packages/ray/tune/function_runner.py", line 600, in _trainable_func
    output = fn()
  File "/home/xwm/anaconda3/envs/SV/lib/python3.6/site-packages/ray/tune/utils/trainable.py", line 371, in inner
    trainable(config, **fn_kwargs)
  File "train.py", line 572, in train_tune
    on="validation_end"),
  File "/home/xwm/anaconda3/envs/SV/lib/python3.6/site-packages/pytorch_lightning/trainer/trainer.py", line 741, in fit
    self._fit_impl, model, train_dataloaders, val_dataloaders, datamodule, ckpt_path
  File "/home/xwm/anaconda3/envs/SV/lib/python3.6/site-packages/pytorch_lightning/trainer/trainer.py", line 685, in _call_and_handle_interrupt
    return trainer_fn(*args, **kwargs)
  File "/home/xwm/anaconda3/envs/SV/lib/python3.6/site-packages/pytorch_lightning/trainer/trainer.py", line 777, in _fit_impl
    self._run(model, ckpt_path=ckpt_path)
  File "/home/xwm/anaconda3/envs/SV/lib/python3.6/site-packages/pytorch_lightning/trainer/trainer.py", line 1145, in _run
    self.accelerator.setup(self)
  File "/home/xwm/anaconda3/envs/SV/lib/python3.6/site-packages/pytorch_lightning/accelerators/gpu.py", line 46, in setup
    return super().setup(trainer)
  File "/home/xwm/anaconda3/envs/SV/lib/python3.6/site-packages/pytorch_lightning/accelerators/accelerator.py", line 91, in setup
    self.setup_training_type_plugin()
  File "/home/xwm/anaconda3/envs/SV/lib/python3.6/site-packages/pytorch_lightning/accelerators/accelerator.py", line 363, in setup_training_type_plugin
    self.training_type_plugin.setup()
  File "/home/xwm/anaconda3/envs/SV/lib/python3.6/site-packages/pytorch_lightning/plugins/training_type/single_device.py", line 71, in setup
    self.model_to_device()
  File "/home/xwm/anaconda3/envs/SV/lib/python3.6/site-packages/pytorch_lightning/plugins/training_type/single_device.py", line 68, in model_to_device
    self._model.to(self.root_device)
  File "/home/xwm/anaconda3/envs/SV/lib/python3.6/site-packages/pytorch_lightning/core/mixins/device_dtype_mixin.py", line 111, in to
    return super().to(*args, **kwargs)
  File "/home/xwm/anaconda3/envs/SV/lib/python3.6/site-packages/torch/nn/modules/module.py", line 899, in to
    return self._apply(convert)
  File "/home/xwm/anaconda3/envs/SV/lib/python3.6/site-packages/torch/nn/modules/module.py", line 570, in _apply
    module._apply(fn)
  File "/home/xwm/anaconda3/envs/SV/lib/python3.6/site-packages/torch/nn/modules/module.py", line 570, in _apply
    module._apply(fn)
  File "/home/xwm/anaconda3/envs/SV/lib/python3.6/site-packages/torch/nn/modules/module.py", line 570, in _apply
    module._apply(fn)
  [Previous line repeated 1 more time]
  File "/home/xwm/anaconda3/envs/SV/lib/python3.6/site-packages/torch/nn/modules/module.py", line 593, in _apply
    param_applied = fn(param)
  File "/home/xwm/anaconda3/envs/SV/lib/python3.6/site-packages/torch/nn/modules/module.py", line 897, in convert
    return t.to(device, dtype if t.is_floating_point() or t.is_complex() else None, non_blocking)
RuntimeError: CUDA error: out of memory
CUDA kernel errors might be asynchronously reported at some other API call,so the stacktrace below might be incorrect.
For debugging consider passing CUDA_LAUNCH_BLOCKING=1.

Failure # 9 (occurred at 2022-06-15_22-44-41)
Traceback (most recent call last):
  File "/home/xwm/anaconda3/envs/SV/lib/python3.6/site-packages/ray/tune/trial_runner.py", line 886, in _process_trial
    results = self.trial_executor.fetch_result(trial)
  File "/home/xwm/anaconda3/envs/SV/lib/python3.6/site-packages/ray/tune/ray_trial_executor.py", line 675, in fetch_result
    result = ray.get(trial_future[0], timeout=DEFAULT_GET_TIMEOUT)
  File "/home/xwm/anaconda3/envs/SV/lib/python3.6/site-packages/ray/_private/client_mode_hook.py", line 105, in wrapper
    return func(*args, **kwargs)
  File "/home/xwm/anaconda3/envs/SV/lib/python3.6/site-packages/ray/worker.py", line 1763, in get
    raise value.as_instanceof_cause()
ray.exceptions.RayTaskError(TuneError): [36mray::ImplicitFunc.train()[39m (pid=58801, ip=192.168.249.74, repr=train_tune)
  File "/home/xwm/anaconda3/envs/SV/lib/python3.6/site-packages/ray/tune/trainable.py", line 319, in train
    result = self.step()
  File "/home/xwm/anaconda3/envs/SV/lib/python3.6/site-packages/ray/tune/function_runner.py", line 381, in step
    self._report_thread_runner_error(block=True)
  File "/home/xwm/anaconda3/envs/SV/lib/python3.6/site-packages/ray/tune/function_runner.py", line 532, in _report_thread_runner_error
    ("Trial raised an exception. Traceback:\n{}".format(err_tb_str)
ray.tune.error.TuneError: Trial raised an exception. Traceback:
[36mray::ImplicitFunc.train()[39m (pid=58801, ip=192.168.249.74, repr=train_tune)
  File "/home/xwm/anaconda3/envs/SV/lib/python3.6/site-packages/ray/tune/function_runner.py", line 262, in run
    self._entrypoint()
  File "/home/xwm/anaconda3/envs/SV/lib/python3.6/site-packages/ray/tune/function_runner.py", line 331, in entrypoint
    self._status_reporter.get_checkpoint())
  File "/home/xwm/anaconda3/envs/SV/lib/python3.6/site-packages/ray/tune/function_runner.py", line 600, in _trainable_func
    output = fn()
  File "/home/xwm/anaconda3/envs/SV/lib/python3.6/site-packages/ray/tune/utils/trainable.py", line 371, in inner
    trainable(config, **fn_kwargs)
  File "train.py", line 572, in train_tune
    on="validation_end"),
  File "/home/xwm/anaconda3/envs/SV/lib/python3.6/site-packages/pytorch_lightning/trainer/trainer.py", line 741, in fit
    self._fit_impl, model, train_dataloaders, val_dataloaders, datamodule, ckpt_path
  File "/home/xwm/anaconda3/envs/SV/lib/python3.6/site-packages/pytorch_lightning/trainer/trainer.py", line 685, in _call_and_handle_interrupt
    return trainer_fn(*args, **kwargs)
  File "/home/xwm/anaconda3/envs/SV/lib/python3.6/site-packages/pytorch_lightning/trainer/trainer.py", line 777, in _fit_impl
    self._run(model, ckpt_path=ckpt_path)
  File "/home/xwm/anaconda3/envs/SV/lib/python3.6/site-packages/pytorch_lightning/trainer/trainer.py", line 1145, in _run
    self.accelerator.setup(self)
  File "/home/xwm/anaconda3/envs/SV/lib/python3.6/site-packages/pytorch_lightning/accelerators/gpu.py", line 46, in setup
    return super().setup(trainer)
  File "/home/xwm/anaconda3/envs/SV/lib/python3.6/site-packages/pytorch_lightning/accelerators/accelerator.py", line 91, in setup
    self.setup_training_type_plugin()
  File "/home/xwm/anaconda3/envs/SV/lib/python3.6/site-packages/pytorch_lightning/accelerators/accelerator.py", line 363, in setup_training_type_plugin
    self.training_type_plugin.setup()
  File "/home/xwm/anaconda3/envs/SV/lib/python3.6/site-packages/pytorch_lightning/plugins/training_type/single_device.py", line 71, in setup
    self.model_to_device()
  File "/home/xwm/anaconda3/envs/SV/lib/python3.6/site-packages/pytorch_lightning/plugins/training_type/single_device.py", line 68, in model_to_device
    self._model.to(self.root_device)
  File "/home/xwm/anaconda3/envs/SV/lib/python3.6/site-packages/pytorch_lightning/core/mixins/device_dtype_mixin.py", line 111, in to
    return super().to(*args, **kwargs)
  File "/home/xwm/anaconda3/envs/SV/lib/python3.6/site-packages/torch/nn/modules/module.py", line 899, in to
    return self._apply(convert)
  File "/home/xwm/anaconda3/envs/SV/lib/python3.6/site-packages/torch/nn/modules/module.py", line 570, in _apply
    module._apply(fn)
  File "/home/xwm/anaconda3/envs/SV/lib/python3.6/site-packages/torch/nn/modules/module.py", line 570, in _apply
    module._apply(fn)
  File "/home/xwm/anaconda3/envs/SV/lib/python3.6/site-packages/torch/nn/modules/module.py", line 570, in _apply
    module._apply(fn)
  [Previous line repeated 1 more time]
  File "/home/xwm/anaconda3/envs/SV/lib/python3.6/site-packages/torch/nn/modules/module.py", line 593, in _apply
    param_applied = fn(param)
  File "/home/xwm/anaconda3/envs/SV/lib/python3.6/site-packages/torch/nn/modules/module.py", line 897, in convert
    return t.to(device, dtype if t.is_floating_point() or t.is_complex() else None, non_blocking)
RuntimeError: CUDA error: out of memory
CUDA kernel errors might be asynchronously reported at some other API call,so the stacktrace below might be incorrect.
For debugging consider passing CUDA_LAUNCH_BLOCKING=1.

Failure # 10 (occurred at 2022-06-15_22-45-49)
Traceback (most recent call last):
  File "/home/xwm/anaconda3/envs/SV/lib/python3.6/site-packages/ray/tune/trial_runner.py", line 886, in _process_trial
    results = self.trial_executor.fetch_result(trial)
  File "/home/xwm/anaconda3/envs/SV/lib/python3.6/site-packages/ray/tune/ray_trial_executor.py", line 675, in fetch_result
    result = ray.get(trial_future[0], timeout=DEFAULT_GET_TIMEOUT)
  File "/home/xwm/anaconda3/envs/SV/lib/python3.6/site-packages/ray/_private/client_mode_hook.py", line 105, in wrapper
    return func(*args, **kwargs)
  File "/home/xwm/anaconda3/envs/SV/lib/python3.6/site-packages/ray/worker.py", line 1763, in get
    raise value.as_instanceof_cause()
ray.exceptions.RayTaskError(TuneError): [36mray::ImplicitFunc.train()[39m (pid=63261, ip=192.168.249.74, repr=train_tune)
  File "/home/xwm/anaconda3/envs/SV/lib/python3.6/site-packages/ray/tune/trainable.py", line 319, in train
    result = self.step()
  File "/home/xwm/anaconda3/envs/SV/lib/python3.6/site-packages/ray/tune/function_runner.py", line 381, in step
    self._report_thread_runner_error(block=True)
  File "/home/xwm/anaconda3/envs/SV/lib/python3.6/site-packages/ray/tune/function_runner.py", line 532, in _report_thread_runner_error
    ("Trial raised an exception. Traceback:\n{}".format(err_tb_str)
ray.tune.error.TuneError: Trial raised an exception. Traceback:
[36mray::ImplicitFunc.train()[39m (pid=63261, ip=192.168.249.74, repr=train_tune)
  File "/home/xwm/anaconda3/envs/SV/lib/python3.6/site-packages/ray/tune/function_runner.py", line 262, in run
    self._entrypoint()
  File "/home/xwm/anaconda3/envs/SV/lib/python3.6/site-packages/ray/tune/function_runner.py", line 331, in entrypoint
    self._status_reporter.get_checkpoint())
  File "/home/xwm/anaconda3/envs/SV/lib/python3.6/site-packages/ray/tune/function_runner.py", line 600, in _trainable_func
    output = fn()
  File "/home/xwm/anaconda3/envs/SV/lib/python3.6/site-packages/ray/tune/utils/trainable.py", line 371, in inner
    trainable(config, **fn_kwargs)
  File "train.py", line 572, in train_tune
    on="validation_end"),
  File "/home/xwm/anaconda3/envs/SV/lib/python3.6/site-packages/pytorch_lightning/trainer/trainer.py", line 741, in fit
    self._fit_impl, model, train_dataloaders, val_dataloaders, datamodule, ckpt_path
  File "/home/xwm/anaconda3/envs/SV/lib/python3.6/site-packages/pytorch_lightning/trainer/trainer.py", line 685, in _call_and_handle_interrupt
    return trainer_fn(*args, **kwargs)
  File "/home/xwm/anaconda3/envs/SV/lib/python3.6/site-packages/pytorch_lightning/trainer/trainer.py", line 777, in _fit_impl
    self._run(model, ckpt_path=ckpt_path)
  File "/home/xwm/anaconda3/envs/SV/lib/python3.6/site-packages/pytorch_lightning/trainer/trainer.py", line 1145, in _run
    self.accelerator.setup(self)
  File "/home/xwm/anaconda3/envs/SV/lib/python3.6/site-packages/pytorch_lightning/accelerators/gpu.py", line 46, in setup
    return super().setup(trainer)
  File "/home/xwm/anaconda3/envs/SV/lib/python3.6/site-packages/pytorch_lightning/accelerators/accelerator.py", line 91, in setup
    self.setup_training_type_plugin()
  File "/home/xwm/anaconda3/envs/SV/lib/python3.6/site-packages/pytorch_lightning/accelerators/accelerator.py", line 363, in setup_training_type_plugin
    self.training_type_plugin.setup()
  File "/home/xwm/anaconda3/envs/SV/lib/python3.6/site-packages/pytorch_lightning/plugins/training_type/single_device.py", line 71, in setup
    self.model_to_device()
  File "/home/xwm/anaconda3/envs/SV/lib/python3.6/site-packages/pytorch_lightning/plugins/training_type/single_device.py", line 68, in model_to_device
    self._model.to(self.root_device)
  File "/home/xwm/anaconda3/envs/SV/lib/python3.6/site-packages/pytorch_lightning/core/mixins/device_dtype_mixin.py", line 111, in to
    return super().to(*args, **kwargs)
  File "/home/xwm/anaconda3/envs/SV/lib/python3.6/site-packages/torch/nn/modules/module.py", line 899, in to
    return self._apply(convert)
  File "/home/xwm/anaconda3/envs/SV/lib/python3.6/site-packages/torch/nn/modules/module.py", line 570, in _apply
    module._apply(fn)
  File "/home/xwm/anaconda3/envs/SV/lib/python3.6/site-packages/torch/nn/modules/module.py", line 570, in _apply
    module._apply(fn)
  File "/home/xwm/anaconda3/envs/SV/lib/python3.6/site-packages/torch/nn/modules/module.py", line 570, in _apply
    module._apply(fn)
  [Previous line repeated 1 more time]
  File "/home/xwm/anaconda3/envs/SV/lib/python3.6/site-packages/torch/nn/modules/module.py", line 593, in _apply
    param_applied = fn(param)
  File "/home/xwm/anaconda3/envs/SV/lib/python3.6/site-packages/torch/nn/modules/module.py", line 897, in convert
    return t.to(device, dtype if t.is_floating_point() or t.is_complex() else None, non_blocking)
RuntimeError: CUDA error: out of memory
CUDA kernel errors might be asynchronously reported at some other API call,so the stacktrace below might be incorrect.
For debugging consider passing CUDA_LAUNCH_BLOCKING=1.

Failure # 11 (occurred at 2022-06-15_22-46-57)
Traceback (most recent call last):
  File "/home/xwm/anaconda3/envs/SV/lib/python3.6/site-packages/ray/tune/trial_runner.py", line 886, in _process_trial
    results = self.trial_executor.fetch_result(trial)
  File "/home/xwm/anaconda3/envs/SV/lib/python3.6/site-packages/ray/tune/ray_trial_executor.py", line 675, in fetch_result
    result = ray.get(trial_future[0], timeout=DEFAULT_GET_TIMEOUT)
  File "/home/xwm/anaconda3/envs/SV/lib/python3.6/site-packages/ray/_private/client_mode_hook.py", line 105, in wrapper
    return func(*args, **kwargs)
  File "/home/xwm/anaconda3/envs/SV/lib/python3.6/site-packages/ray/worker.py", line 1763, in get
    raise value.as_instanceof_cause()
ray.exceptions.RayTaskError(TuneError): [36mray::ImplicitFunc.train()[39m (pid=67711, ip=192.168.249.74, repr=train_tune)
  File "/home/xwm/anaconda3/envs/SV/lib/python3.6/site-packages/ray/tune/trainable.py", line 319, in train
    result = self.step()
  File "/home/xwm/anaconda3/envs/SV/lib/python3.6/site-packages/ray/tune/function_runner.py", line 381, in step
    self._report_thread_runner_error(block=True)
  File "/home/xwm/anaconda3/envs/SV/lib/python3.6/site-packages/ray/tune/function_runner.py", line 532, in _report_thread_runner_error
    ("Trial raised an exception. Traceback:\n{}".format(err_tb_str)
ray.tune.error.TuneError: Trial raised an exception. Traceback:
[36mray::ImplicitFunc.train()[39m (pid=67711, ip=192.168.249.74, repr=train_tune)
  File "/home/xwm/anaconda3/envs/SV/lib/python3.6/site-packages/ray/tune/function_runner.py", line 262, in run
    self._entrypoint()
  File "/home/xwm/anaconda3/envs/SV/lib/python3.6/site-packages/ray/tune/function_runner.py", line 331, in entrypoint
    self._status_reporter.get_checkpoint())
  File "/home/xwm/anaconda3/envs/SV/lib/python3.6/site-packages/ray/tune/function_runner.py", line 600, in _trainable_func
    output = fn()
  File "/home/xwm/anaconda3/envs/SV/lib/python3.6/site-packages/ray/tune/utils/trainable.py", line 371, in inner
    trainable(config, **fn_kwargs)
  File "train.py", line 572, in train_tune
    on="validation_end"),
  File "/home/xwm/anaconda3/envs/SV/lib/python3.6/site-packages/pytorch_lightning/trainer/trainer.py", line 741, in fit
    self._fit_impl, model, train_dataloaders, val_dataloaders, datamodule, ckpt_path
  File "/home/xwm/anaconda3/envs/SV/lib/python3.6/site-packages/pytorch_lightning/trainer/trainer.py", line 685, in _call_and_handle_interrupt
    return trainer_fn(*args, **kwargs)
  File "/home/xwm/anaconda3/envs/SV/lib/python3.6/site-packages/pytorch_lightning/trainer/trainer.py", line 777, in _fit_impl
    self._run(model, ckpt_path=ckpt_path)
  File "/home/xwm/anaconda3/envs/SV/lib/python3.6/site-packages/pytorch_lightning/trainer/trainer.py", line 1145, in _run
    self.accelerator.setup(self)
  File "/home/xwm/anaconda3/envs/SV/lib/python3.6/site-packages/pytorch_lightning/accelerators/gpu.py", line 46, in setup
    return super().setup(trainer)
  File "/home/xwm/anaconda3/envs/SV/lib/python3.6/site-packages/pytorch_lightning/accelerators/accelerator.py", line 91, in setup
    self.setup_training_type_plugin()
  File "/home/xwm/anaconda3/envs/SV/lib/python3.6/site-packages/pytorch_lightning/accelerators/accelerator.py", line 363, in setup_training_type_plugin
    self.training_type_plugin.setup()
  File "/home/xwm/anaconda3/envs/SV/lib/python3.6/site-packages/pytorch_lightning/plugins/training_type/single_device.py", line 71, in setup
    self.model_to_device()
  File "/home/xwm/anaconda3/envs/SV/lib/python3.6/site-packages/pytorch_lightning/plugins/training_type/single_device.py", line 68, in model_to_device
    self._model.to(self.root_device)
  File "/home/xwm/anaconda3/envs/SV/lib/python3.6/site-packages/pytorch_lightning/core/mixins/device_dtype_mixin.py", line 111, in to
    return super().to(*args, **kwargs)
  File "/home/xwm/anaconda3/envs/SV/lib/python3.6/site-packages/torch/nn/modules/module.py", line 899, in to
    return self._apply(convert)
  File "/home/xwm/anaconda3/envs/SV/lib/python3.6/site-packages/torch/nn/modules/module.py", line 570, in _apply
    module._apply(fn)
  File "/home/xwm/anaconda3/envs/SV/lib/python3.6/site-packages/torch/nn/modules/module.py", line 570, in _apply
    module._apply(fn)
  File "/home/xwm/anaconda3/envs/SV/lib/python3.6/site-packages/torch/nn/modules/module.py", line 570, in _apply
    module._apply(fn)
  [Previous line repeated 1 more time]
  File "/home/xwm/anaconda3/envs/SV/lib/python3.6/site-packages/torch/nn/modules/module.py", line 593, in _apply
    param_applied = fn(param)
  File "/home/xwm/anaconda3/envs/SV/lib/python3.6/site-packages/torch/nn/modules/module.py", line 897, in convert
    return t.to(device, dtype if t.is_floating_point() or t.is_complex() else None, non_blocking)
RuntimeError: CUDA error: out of memory
CUDA kernel errors might be asynchronously reported at some other API call,so the stacktrace below might be incorrect.
For debugging consider passing CUDA_LAUNCH_BLOCKING=1.

Failure # 12 (occurred at 2022-06-15_22-48-12)
Traceback (most recent call last):
  File "/home/xwm/anaconda3/envs/SV/lib/python3.6/site-packages/ray/tune/trial_runner.py", line 886, in _process_trial
    results = self.trial_executor.fetch_result(trial)
  File "/home/xwm/anaconda3/envs/SV/lib/python3.6/site-packages/ray/tune/ray_trial_executor.py", line 675, in fetch_result
    result = ray.get(trial_future[0], timeout=DEFAULT_GET_TIMEOUT)
  File "/home/xwm/anaconda3/envs/SV/lib/python3.6/site-packages/ray/_private/client_mode_hook.py", line 105, in wrapper
    return func(*args, **kwargs)
  File "/home/xwm/anaconda3/envs/SV/lib/python3.6/site-packages/ray/worker.py", line 1763, in get
    raise value.as_instanceof_cause()
ray.exceptions.RayTaskError(TuneError): [36mray::ImplicitFunc.train()[39m (pid=70542, ip=192.168.249.74, repr=train_tune)
  File "/home/xwm/anaconda3/envs/SV/lib/python3.6/site-packages/ray/tune/trainable.py", line 319, in train
    result = self.step()
  File "/home/xwm/anaconda3/envs/SV/lib/python3.6/site-packages/ray/tune/function_runner.py", line 381, in step
    self._report_thread_runner_error(block=True)
  File "/home/xwm/anaconda3/envs/SV/lib/python3.6/site-packages/ray/tune/function_runner.py", line 532, in _report_thread_runner_error
    ("Trial raised an exception. Traceback:\n{}".format(err_tb_str)
ray.tune.error.TuneError: Trial raised an exception. Traceback:
[36mray::ImplicitFunc.train()[39m (pid=70542, ip=192.168.249.74, repr=train_tune)
  File "/home/xwm/anaconda3/envs/SV/lib/python3.6/site-packages/ray/tune/function_runner.py", line 262, in run
    self._entrypoint()
  File "/home/xwm/anaconda3/envs/SV/lib/python3.6/site-packages/ray/tune/function_runner.py", line 331, in entrypoint
    self._status_reporter.get_checkpoint())
  File "/home/xwm/anaconda3/envs/SV/lib/python3.6/site-packages/ray/tune/function_runner.py", line 600, in _trainable_func
    output = fn()
  File "/home/xwm/anaconda3/envs/SV/lib/python3.6/site-packages/ray/tune/utils/trainable.py", line 371, in inner
    trainable(config, **fn_kwargs)
  File "train.py", line 572, in train_tune
    on="validation_end"),
  File "/home/xwm/anaconda3/envs/SV/lib/python3.6/site-packages/pytorch_lightning/trainer/trainer.py", line 741, in fit
    self._fit_impl, model, train_dataloaders, val_dataloaders, datamodule, ckpt_path
  File "/home/xwm/anaconda3/envs/SV/lib/python3.6/site-packages/pytorch_lightning/trainer/trainer.py", line 685, in _call_and_handle_interrupt
    return trainer_fn(*args, **kwargs)
  File "/home/xwm/anaconda3/envs/SV/lib/python3.6/site-packages/pytorch_lightning/trainer/trainer.py", line 777, in _fit_impl
    self._run(model, ckpt_path=ckpt_path)
  File "/home/xwm/anaconda3/envs/SV/lib/python3.6/site-packages/pytorch_lightning/trainer/trainer.py", line 1145, in _run
    self.accelerator.setup(self)
  File "/home/xwm/anaconda3/envs/SV/lib/python3.6/site-packages/pytorch_lightning/accelerators/gpu.py", line 46, in setup
    return super().setup(trainer)
  File "/home/xwm/anaconda3/envs/SV/lib/python3.6/site-packages/pytorch_lightning/accelerators/accelerator.py", line 91, in setup
    self.setup_training_type_plugin()
  File "/home/xwm/anaconda3/envs/SV/lib/python3.6/site-packages/pytorch_lightning/accelerators/accelerator.py", line 363, in setup_training_type_plugin
    self.training_type_plugin.setup()
  File "/home/xwm/anaconda3/envs/SV/lib/python3.6/site-packages/pytorch_lightning/plugins/training_type/single_device.py", line 71, in setup
    self.model_to_device()
  File "/home/xwm/anaconda3/envs/SV/lib/python3.6/site-packages/pytorch_lightning/plugins/training_type/single_device.py", line 68, in model_to_device
    self._model.to(self.root_device)
  File "/home/xwm/anaconda3/envs/SV/lib/python3.6/site-packages/pytorch_lightning/core/mixins/device_dtype_mixin.py", line 111, in to
    return super().to(*args, **kwargs)
  File "/home/xwm/anaconda3/envs/SV/lib/python3.6/site-packages/torch/nn/modules/module.py", line 899, in to
    return self._apply(convert)
  File "/home/xwm/anaconda3/envs/SV/lib/python3.6/site-packages/torch/nn/modules/module.py", line 570, in _apply
    module._apply(fn)
  File "/home/xwm/anaconda3/envs/SV/lib/python3.6/site-packages/torch/nn/modules/module.py", line 570, in _apply
    module._apply(fn)
  File "/home/xwm/anaconda3/envs/SV/lib/python3.6/site-packages/torch/nn/modules/module.py", line 570, in _apply
    module._apply(fn)
  [Previous line repeated 1 more time]
  File "/home/xwm/anaconda3/envs/SV/lib/python3.6/site-packages/torch/nn/modules/module.py", line 593, in _apply
    param_applied = fn(param)
  File "/home/xwm/anaconda3/envs/SV/lib/python3.6/site-packages/torch/nn/modules/module.py", line 897, in convert
    return t.to(device, dtype if t.is_floating_point() or t.is_complex() else None, non_blocking)
RuntimeError: CUDA error: out of memory
CUDA kernel errors might be asynchronously reported at some other API call,so the stacktrace below might be incorrect.
For debugging consider passing CUDA_LAUNCH_BLOCKING=1.

Failure # 13 (occurred at 2022-06-15_22-49-25)
Traceback (most recent call last):
  File "/home/xwm/anaconda3/envs/SV/lib/python3.6/site-packages/ray/tune/trial_runner.py", line 886, in _process_trial
    results = self.trial_executor.fetch_result(trial)
  File "/home/xwm/anaconda3/envs/SV/lib/python3.6/site-packages/ray/tune/ray_trial_executor.py", line 675, in fetch_result
    result = ray.get(trial_future[0], timeout=DEFAULT_GET_TIMEOUT)
  File "/home/xwm/anaconda3/envs/SV/lib/python3.6/site-packages/ray/_private/client_mode_hook.py", line 105, in wrapper
    return func(*args, **kwargs)
  File "/home/xwm/anaconda3/envs/SV/lib/python3.6/site-packages/ray/worker.py", line 1763, in get
    raise value.as_instanceof_cause()
ray.exceptions.RayTaskError(TuneError): [36mray::ImplicitFunc.train()[39m (pid=74841, ip=192.168.249.74, repr=train_tune)
  File "/home/xwm/anaconda3/envs/SV/lib/python3.6/site-packages/ray/tune/trainable.py", line 319, in train
    result = self.step()
  File "/home/xwm/anaconda3/envs/SV/lib/python3.6/site-packages/ray/tune/function_runner.py", line 381, in step
    self._report_thread_runner_error(block=True)
  File "/home/xwm/anaconda3/envs/SV/lib/python3.6/site-packages/ray/tune/function_runner.py", line 532, in _report_thread_runner_error
    ("Trial raised an exception. Traceback:\n{}".format(err_tb_str)
ray.tune.error.TuneError: Trial raised an exception. Traceback:
[36mray::ImplicitFunc.train()[39m (pid=74841, ip=192.168.249.74, repr=train_tune)
  File "/home/xwm/anaconda3/envs/SV/lib/python3.6/site-packages/ray/tune/function_runner.py", line 262, in run
    self._entrypoint()
  File "/home/xwm/anaconda3/envs/SV/lib/python3.6/site-packages/ray/tune/function_runner.py", line 331, in entrypoint
    self._status_reporter.get_checkpoint())
  File "/home/xwm/anaconda3/envs/SV/lib/python3.6/site-packages/ray/tune/function_runner.py", line 600, in _trainable_func
    output = fn()
  File "/home/xwm/anaconda3/envs/SV/lib/python3.6/site-packages/ray/tune/utils/trainable.py", line 371, in inner
    trainable(config, **fn_kwargs)
  File "train.py", line 572, in train_tune
    on="validation_end"),
  File "/home/xwm/anaconda3/envs/SV/lib/python3.6/site-packages/pytorch_lightning/trainer/trainer.py", line 741, in fit
    self._fit_impl, model, train_dataloaders, val_dataloaders, datamodule, ckpt_path
  File "/home/xwm/anaconda3/envs/SV/lib/python3.6/site-packages/pytorch_lightning/trainer/trainer.py", line 685, in _call_and_handle_interrupt
    return trainer_fn(*args, **kwargs)
  File "/home/xwm/anaconda3/envs/SV/lib/python3.6/site-packages/pytorch_lightning/trainer/trainer.py", line 777, in _fit_impl
    self._run(model, ckpt_path=ckpt_path)
  File "/home/xwm/anaconda3/envs/SV/lib/python3.6/site-packages/pytorch_lightning/trainer/trainer.py", line 1145, in _run
    self.accelerator.setup(self)
  File "/home/xwm/anaconda3/envs/SV/lib/python3.6/site-packages/pytorch_lightning/accelerators/gpu.py", line 46, in setup
    return super().setup(trainer)
  File "/home/xwm/anaconda3/envs/SV/lib/python3.6/site-packages/pytorch_lightning/accelerators/accelerator.py", line 91, in setup
    self.setup_training_type_plugin()
  File "/home/xwm/anaconda3/envs/SV/lib/python3.6/site-packages/pytorch_lightning/accelerators/accelerator.py", line 363, in setup_training_type_plugin
    self.training_type_plugin.setup()
  File "/home/xwm/anaconda3/envs/SV/lib/python3.6/site-packages/pytorch_lightning/plugins/training_type/single_device.py", line 71, in setup
    self.model_to_device()
  File "/home/xwm/anaconda3/envs/SV/lib/python3.6/site-packages/pytorch_lightning/plugins/training_type/single_device.py", line 68, in model_to_device
    self._model.to(self.root_device)
  File "/home/xwm/anaconda3/envs/SV/lib/python3.6/site-packages/pytorch_lightning/core/mixins/device_dtype_mixin.py", line 111, in to
    return super().to(*args, **kwargs)
  File "/home/xwm/anaconda3/envs/SV/lib/python3.6/site-packages/torch/nn/modules/module.py", line 899, in to
    return self._apply(convert)
  File "/home/xwm/anaconda3/envs/SV/lib/python3.6/site-packages/torch/nn/modules/module.py", line 570, in _apply
    module._apply(fn)
  File "/home/xwm/anaconda3/envs/SV/lib/python3.6/site-packages/torch/nn/modules/module.py", line 570, in _apply
    module._apply(fn)
  File "/home/xwm/anaconda3/envs/SV/lib/python3.6/site-packages/torch/nn/modules/module.py", line 570, in _apply
    module._apply(fn)
  [Previous line repeated 1 more time]
  File "/home/xwm/anaconda3/envs/SV/lib/python3.6/site-packages/torch/nn/modules/module.py", line 593, in _apply
    param_applied = fn(param)
  File "/home/xwm/anaconda3/envs/SV/lib/python3.6/site-packages/torch/nn/modules/module.py", line 897, in convert
    return t.to(device, dtype if t.is_floating_point() or t.is_complex() else None, non_blocking)
RuntimeError: CUDA error: out of memory
CUDA kernel errors might be asynchronously reported at some other API call,so the stacktrace below might be incorrect.
For debugging consider passing CUDA_LAUNCH_BLOCKING=1.

Failure # 14 (occurred at 2022-06-15_22-50-38)
Traceback (most recent call last):
  File "/home/xwm/anaconda3/envs/SV/lib/python3.6/site-packages/ray/tune/trial_runner.py", line 886, in _process_trial
    results = self.trial_executor.fetch_result(trial)
  File "/home/xwm/anaconda3/envs/SV/lib/python3.6/site-packages/ray/tune/ray_trial_executor.py", line 675, in fetch_result
    result = ray.get(trial_future[0], timeout=DEFAULT_GET_TIMEOUT)
  File "/home/xwm/anaconda3/envs/SV/lib/python3.6/site-packages/ray/_private/client_mode_hook.py", line 105, in wrapper
    return func(*args, **kwargs)
  File "/home/xwm/anaconda3/envs/SV/lib/python3.6/site-packages/ray/worker.py", line 1763, in get
    raise value.as_instanceof_cause()
ray.exceptions.RayTaskError(TuneError): [36mray::ImplicitFunc.train()[39m (pid=79483, ip=192.168.249.74, repr=train_tune)
  File "/home/xwm/anaconda3/envs/SV/lib/python3.6/site-packages/ray/tune/trainable.py", line 319, in train
    result = self.step()
  File "/home/xwm/anaconda3/envs/SV/lib/python3.6/site-packages/ray/tune/function_runner.py", line 381, in step
    self._report_thread_runner_error(block=True)
  File "/home/xwm/anaconda3/envs/SV/lib/python3.6/site-packages/ray/tune/function_runner.py", line 532, in _report_thread_runner_error
    ("Trial raised an exception. Traceback:\n{}".format(err_tb_str)
ray.tune.error.TuneError: Trial raised an exception. Traceback:
[36mray::ImplicitFunc.train()[39m (pid=79483, ip=192.168.249.74, repr=train_tune)
  File "/home/xwm/anaconda3/envs/SV/lib/python3.6/site-packages/ray/tune/function_runner.py", line 262, in run
    self._entrypoint()
  File "/home/xwm/anaconda3/envs/SV/lib/python3.6/site-packages/ray/tune/function_runner.py", line 331, in entrypoint
    self._status_reporter.get_checkpoint())
  File "/home/xwm/anaconda3/envs/SV/lib/python3.6/site-packages/ray/tune/function_runner.py", line 600, in _trainable_func
    output = fn()
  File "/home/xwm/anaconda3/envs/SV/lib/python3.6/site-packages/ray/tune/utils/trainable.py", line 371, in inner
    trainable(config, **fn_kwargs)
  File "train.py", line 572, in train_tune
    on="validation_end"),
  File "/home/xwm/anaconda3/envs/SV/lib/python3.6/site-packages/pytorch_lightning/trainer/trainer.py", line 741, in fit
    self._fit_impl, model, train_dataloaders, val_dataloaders, datamodule, ckpt_path
  File "/home/xwm/anaconda3/envs/SV/lib/python3.6/site-packages/pytorch_lightning/trainer/trainer.py", line 685, in _call_and_handle_interrupt
    return trainer_fn(*args, **kwargs)
  File "/home/xwm/anaconda3/envs/SV/lib/python3.6/site-packages/pytorch_lightning/trainer/trainer.py", line 777, in _fit_impl
    self._run(model, ckpt_path=ckpt_path)
  File "/home/xwm/anaconda3/envs/SV/lib/python3.6/site-packages/pytorch_lightning/trainer/trainer.py", line 1145, in _run
    self.accelerator.setup(self)
  File "/home/xwm/anaconda3/envs/SV/lib/python3.6/site-packages/pytorch_lightning/accelerators/gpu.py", line 46, in setup
    return super().setup(trainer)
  File "/home/xwm/anaconda3/envs/SV/lib/python3.6/site-packages/pytorch_lightning/accelerators/accelerator.py", line 91, in setup
    self.setup_training_type_plugin()
  File "/home/xwm/anaconda3/envs/SV/lib/python3.6/site-packages/pytorch_lightning/accelerators/accelerator.py", line 363, in setup_training_type_plugin
    self.training_type_plugin.setup()
  File "/home/xwm/anaconda3/envs/SV/lib/python3.6/site-packages/pytorch_lightning/plugins/training_type/single_device.py", line 71, in setup
    self.model_to_device()
  File "/home/xwm/anaconda3/envs/SV/lib/python3.6/site-packages/pytorch_lightning/plugins/training_type/single_device.py", line 68, in model_to_device
    self._model.to(self.root_device)
  File "/home/xwm/anaconda3/envs/SV/lib/python3.6/site-packages/pytorch_lightning/core/mixins/device_dtype_mixin.py", line 111, in to
    return super().to(*args, **kwargs)
  File "/home/xwm/anaconda3/envs/SV/lib/python3.6/site-packages/torch/nn/modules/module.py", line 899, in to
    return self._apply(convert)
  File "/home/xwm/anaconda3/envs/SV/lib/python3.6/site-packages/torch/nn/modules/module.py", line 570, in _apply
    module._apply(fn)
  File "/home/xwm/anaconda3/envs/SV/lib/python3.6/site-packages/torch/nn/modules/module.py", line 570, in _apply
    module._apply(fn)
  File "/home/xwm/anaconda3/envs/SV/lib/python3.6/site-packages/torch/nn/modules/module.py", line 570, in _apply
    module._apply(fn)
  [Previous line repeated 1 more time]
  File "/home/xwm/anaconda3/envs/SV/lib/python3.6/site-packages/torch/nn/modules/module.py", line 593, in _apply
    param_applied = fn(param)
  File "/home/xwm/anaconda3/envs/SV/lib/python3.6/site-packages/torch/nn/modules/module.py", line 897, in convert
    return t.to(device, dtype if t.is_floating_point() or t.is_complex() else None, non_blocking)
RuntimeError: CUDA error: out of memory
CUDA kernel errors might be asynchronously reported at some other API call,so the stacktrace below might be incorrect.
For debugging consider passing CUDA_LAUNCH_BLOCKING=1.

Failure # 15 (occurred at 2022-06-15_22-51-49)
Traceback (most recent call last):
  File "/home/xwm/anaconda3/envs/SV/lib/python3.6/site-packages/ray/tune/trial_runner.py", line 886, in _process_trial
    results = self.trial_executor.fetch_result(trial)
  File "/home/xwm/anaconda3/envs/SV/lib/python3.6/site-packages/ray/tune/ray_trial_executor.py", line 675, in fetch_result
    result = ray.get(trial_future[0], timeout=DEFAULT_GET_TIMEOUT)
  File "/home/xwm/anaconda3/envs/SV/lib/python3.6/site-packages/ray/_private/client_mode_hook.py", line 105, in wrapper
    return func(*args, **kwargs)
  File "/home/xwm/anaconda3/envs/SV/lib/python3.6/site-packages/ray/worker.py", line 1763, in get
    raise value.as_instanceof_cause()
ray.exceptions.RayTaskError(TuneError): [36mray::ImplicitFunc.train()[39m (pid=83879, ip=192.168.249.74, repr=train_tune)
  File "/home/xwm/anaconda3/envs/SV/lib/python3.6/site-packages/ray/tune/trainable.py", line 319, in train
    result = self.step()
  File "/home/xwm/anaconda3/envs/SV/lib/python3.6/site-packages/ray/tune/function_runner.py", line 381, in step
    self._report_thread_runner_error(block=True)
  File "/home/xwm/anaconda3/envs/SV/lib/python3.6/site-packages/ray/tune/function_runner.py", line 532, in _report_thread_runner_error
    ("Trial raised an exception. Traceback:\n{}".format(err_tb_str)
ray.tune.error.TuneError: Trial raised an exception. Traceback:
[36mray::ImplicitFunc.train()[39m (pid=83879, ip=192.168.249.74, repr=train_tune)
  File "/home/xwm/anaconda3/envs/SV/lib/python3.6/site-packages/ray/tune/function_runner.py", line 262, in run
    self._entrypoint()
  File "/home/xwm/anaconda3/envs/SV/lib/python3.6/site-packages/ray/tune/function_runner.py", line 331, in entrypoint
    self._status_reporter.get_checkpoint())
  File "/home/xwm/anaconda3/envs/SV/lib/python3.6/site-packages/ray/tune/function_runner.py", line 600, in _trainable_func
    output = fn()
  File "/home/xwm/anaconda3/envs/SV/lib/python3.6/site-packages/ray/tune/utils/trainable.py", line 371, in inner
    trainable(config, **fn_kwargs)
  File "train.py", line 572, in train_tune
    on="validation_end"),
  File "/home/xwm/anaconda3/envs/SV/lib/python3.6/site-packages/pytorch_lightning/trainer/trainer.py", line 741, in fit
    self._fit_impl, model, train_dataloaders, val_dataloaders, datamodule, ckpt_path
  File "/home/xwm/anaconda3/envs/SV/lib/python3.6/site-packages/pytorch_lightning/trainer/trainer.py", line 685, in _call_and_handle_interrupt
    return trainer_fn(*args, **kwargs)
  File "/home/xwm/anaconda3/envs/SV/lib/python3.6/site-packages/pytorch_lightning/trainer/trainer.py", line 777, in _fit_impl
    self._run(model, ckpt_path=ckpt_path)
  File "/home/xwm/anaconda3/envs/SV/lib/python3.6/site-packages/pytorch_lightning/trainer/trainer.py", line 1145, in _run
    self.accelerator.setup(self)
  File "/home/xwm/anaconda3/envs/SV/lib/python3.6/site-packages/pytorch_lightning/accelerators/gpu.py", line 46, in setup
    return super().setup(trainer)
  File "/home/xwm/anaconda3/envs/SV/lib/python3.6/site-packages/pytorch_lightning/accelerators/accelerator.py", line 91, in setup
    self.setup_training_type_plugin()
  File "/home/xwm/anaconda3/envs/SV/lib/python3.6/site-packages/pytorch_lightning/accelerators/accelerator.py", line 363, in setup_training_type_plugin
    self.training_type_plugin.setup()
  File "/home/xwm/anaconda3/envs/SV/lib/python3.6/site-packages/pytorch_lightning/plugins/training_type/single_device.py", line 71, in setup
    self.model_to_device()
  File "/home/xwm/anaconda3/envs/SV/lib/python3.6/site-packages/pytorch_lightning/plugins/training_type/single_device.py", line 68, in model_to_device
    self._model.to(self.root_device)
  File "/home/xwm/anaconda3/envs/SV/lib/python3.6/site-packages/pytorch_lightning/core/mixins/device_dtype_mixin.py", line 111, in to
    return super().to(*args, **kwargs)
  File "/home/xwm/anaconda3/envs/SV/lib/python3.6/site-packages/torch/nn/modules/module.py", line 899, in to
    return self._apply(convert)
  File "/home/xwm/anaconda3/envs/SV/lib/python3.6/site-packages/torch/nn/modules/module.py", line 570, in _apply
    module._apply(fn)
  File "/home/xwm/anaconda3/envs/SV/lib/python3.6/site-packages/torch/nn/modules/module.py", line 570, in _apply
    module._apply(fn)
  File "/home/xwm/anaconda3/envs/SV/lib/python3.6/site-packages/torch/nn/modules/module.py", line 570, in _apply
    module._apply(fn)
  [Previous line repeated 1 more time]
  File "/home/xwm/anaconda3/envs/SV/lib/python3.6/site-packages/torch/nn/modules/module.py", line 593, in _apply
    param_applied = fn(param)
  File "/home/xwm/anaconda3/envs/SV/lib/python3.6/site-packages/torch/nn/modules/module.py", line 897, in convert
    return t.to(device, dtype if t.is_floating_point() or t.is_complex() else None, non_blocking)
RuntimeError: CUDA error: out of memory
CUDA kernel errors might be asynchronously reported at some other API call,so the stacktrace below might be incorrect.
For debugging consider passing CUDA_LAUNCH_BLOCKING=1.

Failure # 16 (occurred at 2022-06-15_22-53-02)
Traceback (most recent call last):
  File "/home/xwm/anaconda3/envs/SV/lib/python3.6/site-packages/ray/tune/trial_runner.py", line 886, in _process_trial
    results = self.trial_executor.fetch_result(trial)
  File "/home/xwm/anaconda3/envs/SV/lib/python3.6/site-packages/ray/tune/ray_trial_executor.py", line 675, in fetch_result
    result = ray.get(trial_future[0], timeout=DEFAULT_GET_TIMEOUT)
  File "/home/xwm/anaconda3/envs/SV/lib/python3.6/site-packages/ray/_private/client_mode_hook.py", line 105, in wrapper
    return func(*args, **kwargs)
  File "/home/xwm/anaconda3/envs/SV/lib/python3.6/site-packages/ray/worker.py", line 1763, in get
    raise value.as_instanceof_cause()
ray.exceptions.RayTaskError(TuneError): [36mray::ImplicitFunc.train()[39m (pid=88288, ip=192.168.249.74, repr=train_tune)
  File "/home/xwm/anaconda3/envs/SV/lib/python3.6/site-packages/ray/tune/trainable.py", line 319, in train
    result = self.step()
  File "/home/xwm/anaconda3/envs/SV/lib/python3.6/site-packages/ray/tune/function_runner.py", line 381, in step
    self._report_thread_runner_error(block=True)
  File "/home/xwm/anaconda3/envs/SV/lib/python3.6/site-packages/ray/tune/function_runner.py", line 532, in _report_thread_runner_error
    ("Trial raised an exception. Traceback:\n{}".format(err_tb_str)
ray.tune.error.TuneError: Trial raised an exception. Traceback:
[36mray::ImplicitFunc.train()[39m (pid=88288, ip=192.168.249.74, repr=train_tune)
  File "/home/xwm/anaconda3/envs/SV/lib/python3.6/site-packages/ray/tune/function_runner.py", line 262, in run
    self._entrypoint()
  File "/home/xwm/anaconda3/envs/SV/lib/python3.6/site-packages/ray/tune/function_runner.py", line 331, in entrypoint
    self._status_reporter.get_checkpoint())
  File "/home/xwm/anaconda3/envs/SV/lib/python3.6/site-packages/ray/tune/function_runner.py", line 600, in _trainable_func
    output = fn()
  File "/home/xwm/anaconda3/envs/SV/lib/python3.6/site-packages/ray/tune/utils/trainable.py", line 371, in inner
    trainable(config, **fn_kwargs)
  File "train.py", line 572, in train_tune
    on="validation_end"),
  File "/home/xwm/anaconda3/envs/SV/lib/python3.6/site-packages/pytorch_lightning/trainer/trainer.py", line 741, in fit
    self._fit_impl, model, train_dataloaders, val_dataloaders, datamodule, ckpt_path
  File "/home/xwm/anaconda3/envs/SV/lib/python3.6/site-packages/pytorch_lightning/trainer/trainer.py", line 685, in _call_and_handle_interrupt
    return trainer_fn(*args, **kwargs)
  File "/home/xwm/anaconda3/envs/SV/lib/python3.6/site-packages/pytorch_lightning/trainer/trainer.py", line 777, in _fit_impl
    self._run(model, ckpt_path=ckpt_path)
  File "/home/xwm/anaconda3/envs/SV/lib/python3.6/site-packages/pytorch_lightning/trainer/trainer.py", line 1145, in _run
    self.accelerator.setup(self)
  File "/home/xwm/anaconda3/envs/SV/lib/python3.6/site-packages/pytorch_lightning/accelerators/gpu.py", line 46, in setup
    return super().setup(trainer)
  File "/home/xwm/anaconda3/envs/SV/lib/python3.6/site-packages/pytorch_lightning/accelerators/accelerator.py", line 91, in setup
    self.setup_training_type_plugin()
  File "/home/xwm/anaconda3/envs/SV/lib/python3.6/site-packages/pytorch_lightning/accelerators/accelerator.py", line 363, in setup_training_type_plugin
    self.training_type_plugin.setup()
  File "/home/xwm/anaconda3/envs/SV/lib/python3.6/site-packages/pytorch_lightning/plugins/training_type/single_device.py", line 71, in setup
    self.model_to_device()
  File "/home/xwm/anaconda3/envs/SV/lib/python3.6/site-packages/pytorch_lightning/plugins/training_type/single_device.py", line 68, in model_to_device
    self._model.to(self.root_device)
  File "/home/xwm/anaconda3/envs/SV/lib/python3.6/site-packages/pytorch_lightning/core/mixins/device_dtype_mixin.py", line 111, in to
    return super().to(*args, **kwargs)
  File "/home/xwm/anaconda3/envs/SV/lib/python3.6/site-packages/torch/nn/modules/module.py", line 899, in to
    return self._apply(convert)
  File "/home/xwm/anaconda3/envs/SV/lib/python3.6/site-packages/torch/nn/modules/module.py", line 570, in _apply
    module._apply(fn)
  File "/home/xwm/anaconda3/envs/SV/lib/python3.6/site-packages/torch/nn/modules/module.py", line 570, in _apply
    module._apply(fn)
  File "/home/xwm/anaconda3/envs/SV/lib/python3.6/site-packages/torch/nn/modules/module.py", line 570, in _apply
    module._apply(fn)
  [Previous line repeated 1 more time]
  File "/home/xwm/anaconda3/envs/SV/lib/python3.6/site-packages/torch/nn/modules/module.py", line 593, in _apply
    param_applied = fn(param)
  File "/home/xwm/anaconda3/envs/SV/lib/python3.6/site-packages/torch/nn/modules/module.py", line 897, in convert
    return t.to(device, dtype if t.is_floating_point() or t.is_complex() else None, non_blocking)
RuntimeError: CUDA error: out of memory
CUDA kernel errors might be asynchronously reported at some other API call,so the stacktrace below might be incorrect.
For debugging consider passing CUDA_LAUNCH_BLOCKING=1.

Failure # 17 (occurred at 2022-06-15_22-54-26)
Traceback (most recent call last):
  File "/home/xwm/anaconda3/envs/SV/lib/python3.6/site-packages/ray/tune/trial_runner.py", line 886, in _process_trial
    results = self.trial_executor.fetch_result(trial)
  File "/home/xwm/anaconda3/envs/SV/lib/python3.6/site-packages/ray/tune/ray_trial_executor.py", line 675, in fetch_result
    result = ray.get(trial_future[0], timeout=DEFAULT_GET_TIMEOUT)
  File "/home/xwm/anaconda3/envs/SV/lib/python3.6/site-packages/ray/_private/client_mode_hook.py", line 105, in wrapper
    return func(*args, **kwargs)
  File "/home/xwm/anaconda3/envs/SV/lib/python3.6/site-packages/ray/worker.py", line 1763, in get
    raise value.as_instanceof_cause()
ray.exceptions.RayTaskError(TuneError): [36mray::ImplicitFunc.train()[39m (pid=92681, ip=192.168.249.74, repr=train_tune)
  File "/home/xwm/anaconda3/envs/SV/lib/python3.6/site-packages/ray/tune/trainable.py", line 319, in train
    result = self.step()
  File "/home/xwm/anaconda3/envs/SV/lib/python3.6/site-packages/ray/tune/function_runner.py", line 381, in step
    self._report_thread_runner_error(block=True)
  File "/home/xwm/anaconda3/envs/SV/lib/python3.6/site-packages/ray/tune/function_runner.py", line 532, in _report_thread_runner_error
    ("Trial raised an exception. Traceback:\n{}".format(err_tb_str)
ray.tune.error.TuneError: Trial raised an exception. Traceback:
[36mray::ImplicitFunc.train()[39m (pid=92681, ip=192.168.249.74, repr=train_tune)
  File "/home/xwm/anaconda3/envs/SV/lib/python3.6/site-packages/ray/tune/function_runner.py", line 262, in run
    self._entrypoint()
  File "/home/xwm/anaconda3/envs/SV/lib/python3.6/site-packages/ray/tune/function_runner.py", line 331, in entrypoint
    self._status_reporter.get_checkpoint())
  File "/home/xwm/anaconda3/envs/SV/lib/python3.6/site-packages/ray/tune/function_runner.py", line 600, in _trainable_func
    output = fn()
  File "/home/xwm/anaconda3/envs/SV/lib/python3.6/site-packages/ray/tune/utils/trainable.py", line 371, in inner
    trainable(config, **fn_kwargs)
  File "train.py", line 572, in train_tune
    on="validation_end"),
  File "/home/xwm/anaconda3/envs/SV/lib/python3.6/site-packages/pytorch_lightning/trainer/trainer.py", line 741, in fit
    self._fit_impl, model, train_dataloaders, val_dataloaders, datamodule, ckpt_path
  File "/home/xwm/anaconda3/envs/SV/lib/python3.6/site-packages/pytorch_lightning/trainer/trainer.py", line 685, in _call_and_handle_interrupt
    return trainer_fn(*args, **kwargs)
  File "/home/xwm/anaconda3/envs/SV/lib/python3.6/site-packages/pytorch_lightning/trainer/trainer.py", line 777, in _fit_impl
    self._run(model, ckpt_path=ckpt_path)
  File "/home/xwm/anaconda3/envs/SV/lib/python3.6/site-packages/pytorch_lightning/trainer/trainer.py", line 1145, in _run
    self.accelerator.setup(self)
  File "/home/xwm/anaconda3/envs/SV/lib/python3.6/site-packages/pytorch_lightning/accelerators/gpu.py", line 46, in setup
    return super().setup(trainer)
  File "/home/xwm/anaconda3/envs/SV/lib/python3.6/site-packages/pytorch_lightning/accelerators/accelerator.py", line 91, in setup
    self.setup_training_type_plugin()
  File "/home/xwm/anaconda3/envs/SV/lib/python3.6/site-packages/pytorch_lightning/accelerators/accelerator.py", line 363, in setup_training_type_plugin
    self.training_type_plugin.setup()
  File "/home/xwm/anaconda3/envs/SV/lib/python3.6/site-packages/pytorch_lightning/plugins/training_type/single_device.py", line 71, in setup
    self.model_to_device()
  File "/home/xwm/anaconda3/envs/SV/lib/python3.6/site-packages/pytorch_lightning/plugins/training_type/single_device.py", line 68, in model_to_device
    self._model.to(self.root_device)
  File "/home/xwm/anaconda3/envs/SV/lib/python3.6/site-packages/pytorch_lightning/core/mixins/device_dtype_mixin.py", line 111, in to
    return super().to(*args, **kwargs)
  File "/home/xwm/anaconda3/envs/SV/lib/python3.6/site-packages/torch/nn/modules/module.py", line 899, in to
    return self._apply(convert)
  File "/home/xwm/anaconda3/envs/SV/lib/python3.6/site-packages/torch/nn/modules/module.py", line 570, in _apply
    module._apply(fn)
  File "/home/xwm/anaconda3/envs/SV/lib/python3.6/site-packages/torch/nn/modules/module.py", line 570, in _apply
    module._apply(fn)
  File "/home/xwm/anaconda3/envs/SV/lib/python3.6/site-packages/torch/nn/modules/module.py", line 570, in _apply
    module._apply(fn)
  [Previous line repeated 1 more time]
  File "/home/xwm/anaconda3/envs/SV/lib/python3.6/site-packages/torch/nn/modules/module.py", line 593, in _apply
    param_applied = fn(param)
  File "/home/xwm/anaconda3/envs/SV/lib/python3.6/site-packages/torch/nn/modules/module.py", line 897, in convert
    return t.to(device, dtype if t.is_floating_point() or t.is_complex() else None, non_blocking)
RuntimeError: CUDA error: out of memory
CUDA kernel errors might be asynchronously reported at some other API call,so the stacktrace below might be incorrect.
For debugging consider passing CUDA_LAUNCH_BLOCKING=1.

Failure # 18 (occurred at 2022-06-15_22-55-29)
Traceback (most recent call last):
  File "/home/xwm/anaconda3/envs/SV/lib/python3.6/site-packages/ray/tune/trial_runner.py", line 886, in _process_trial
    results = self.trial_executor.fetch_result(trial)
  File "/home/xwm/anaconda3/envs/SV/lib/python3.6/site-packages/ray/tune/ray_trial_executor.py", line 675, in fetch_result
    result = ray.get(trial_future[0], timeout=DEFAULT_GET_TIMEOUT)
  File "/home/xwm/anaconda3/envs/SV/lib/python3.6/site-packages/ray/_private/client_mode_hook.py", line 105, in wrapper
    return func(*args, **kwargs)
  File "/home/xwm/anaconda3/envs/SV/lib/python3.6/site-packages/ray/worker.py", line 1763, in get
    raise value.as_instanceof_cause()
ray.exceptions.RayTaskError(TuneError): [36mray::ImplicitFunc.train()[39m (pid=97681, ip=192.168.249.74, repr=train_tune)
  File "/home/xwm/anaconda3/envs/SV/lib/python3.6/site-packages/ray/tune/trainable.py", line 319, in train
    result = self.step()
  File "/home/xwm/anaconda3/envs/SV/lib/python3.6/site-packages/ray/tune/function_runner.py", line 381, in step
    self._report_thread_runner_error(block=True)
  File "/home/xwm/anaconda3/envs/SV/lib/python3.6/site-packages/ray/tune/function_runner.py", line 532, in _report_thread_runner_error
    ("Trial raised an exception. Traceback:\n{}".format(err_tb_str)
ray.tune.error.TuneError: Trial raised an exception. Traceback:
[36mray::ImplicitFunc.train()[39m (pid=97681, ip=192.168.249.74, repr=train_tune)
  File "/home/xwm/anaconda3/envs/SV/lib/python3.6/site-packages/ray/tune/function_runner.py", line 262, in run
    self._entrypoint()
  File "/home/xwm/anaconda3/envs/SV/lib/python3.6/site-packages/ray/tune/function_runner.py", line 331, in entrypoint
    self._status_reporter.get_checkpoint())
  File "/home/xwm/anaconda3/envs/SV/lib/python3.6/site-packages/ray/tune/function_runner.py", line 600, in _trainable_func
    output = fn()
  File "/home/xwm/anaconda3/envs/SV/lib/python3.6/site-packages/ray/tune/utils/trainable.py", line 371, in inner
    trainable(config, **fn_kwargs)
  File "train.py", line 572, in train_tune
    on="validation_end"),
  File "/home/xwm/anaconda3/envs/SV/lib/python3.6/site-packages/pytorch_lightning/trainer/trainer.py", line 741, in fit
    self._fit_impl, model, train_dataloaders, val_dataloaders, datamodule, ckpt_path
  File "/home/xwm/anaconda3/envs/SV/lib/python3.6/site-packages/pytorch_lightning/trainer/trainer.py", line 685, in _call_and_handle_interrupt
    return trainer_fn(*args, **kwargs)
  File "/home/xwm/anaconda3/envs/SV/lib/python3.6/site-packages/pytorch_lightning/trainer/trainer.py", line 777, in _fit_impl
    self._run(model, ckpt_path=ckpt_path)
  File "/home/xwm/anaconda3/envs/SV/lib/python3.6/site-packages/pytorch_lightning/trainer/trainer.py", line 1145, in _run
    self.accelerator.setup(self)
  File "/home/xwm/anaconda3/envs/SV/lib/python3.6/site-packages/pytorch_lightning/accelerators/gpu.py", line 46, in setup
    return super().setup(trainer)
  File "/home/xwm/anaconda3/envs/SV/lib/python3.6/site-packages/pytorch_lightning/accelerators/accelerator.py", line 91, in setup
    self.setup_training_type_plugin()
  File "/home/xwm/anaconda3/envs/SV/lib/python3.6/site-packages/pytorch_lightning/accelerators/accelerator.py", line 363, in setup_training_type_plugin
    self.training_type_plugin.setup()
  File "/home/xwm/anaconda3/envs/SV/lib/python3.6/site-packages/pytorch_lightning/plugins/training_type/single_device.py", line 71, in setup
    self.model_to_device()
  File "/home/xwm/anaconda3/envs/SV/lib/python3.6/site-packages/pytorch_lightning/plugins/training_type/single_device.py", line 68, in model_to_device
    self._model.to(self.root_device)
  File "/home/xwm/anaconda3/envs/SV/lib/python3.6/site-packages/pytorch_lightning/core/mixins/device_dtype_mixin.py", line 111, in to
    return super().to(*args, **kwargs)
  File "/home/xwm/anaconda3/envs/SV/lib/python3.6/site-packages/torch/nn/modules/module.py", line 899, in to
    return self._apply(convert)
  File "/home/xwm/anaconda3/envs/SV/lib/python3.6/site-packages/torch/nn/modules/module.py", line 570, in _apply
    module._apply(fn)
  File "/home/xwm/anaconda3/envs/SV/lib/python3.6/site-packages/torch/nn/modules/module.py", line 570, in _apply
    module._apply(fn)
  File "/home/xwm/anaconda3/envs/SV/lib/python3.6/site-packages/torch/nn/modules/module.py", line 570, in _apply
    module._apply(fn)
  [Previous line repeated 1 more time]
  File "/home/xwm/anaconda3/envs/SV/lib/python3.6/site-packages/torch/nn/modules/module.py", line 593, in _apply
    param_applied = fn(param)
  File "/home/xwm/anaconda3/envs/SV/lib/python3.6/site-packages/torch/nn/modules/module.py", line 897, in convert
    return t.to(device, dtype if t.is_floating_point() or t.is_complex() else None, non_blocking)
RuntimeError: CUDA error: out of memory
CUDA kernel errors might be asynchronously reported at some other API call,so the stacktrace below might be incorrect.
For debugging consider passing CUDA_LAUNCH_BLOCKING=1.

Failure # 19 (occurred at 2022-06-15_22-56-37)
Traceback (most recent call last):
  File "/home/xwm/anaconda3/envs/SV/lib/python3.6/site-packages/ray/tune/trial_runner.py", line 886, in _process_trial
    results = self.trial_executor.fetch_result(trial)
  File "/home/xwm/anaconda3/envs/SV/lib/python3.6/site-packages/ray/tune/ray_trial_executor.py", line 675, in fetch_result
    result = ray.get(trial_future[0], timeout=DEFAULT_GET_TIMEOUT)
  File "/home/xwm/anaconda3/envs/SV/lib/python3.6/site-packages/ray/_private/client_mode_hook.py", line 105, in wrapper
    return func(*args, **kwargs)
  File "/home/xwm/anaconda3/envs/SV/lib/python3.6/site-packages/ray/worker.py", line 1763, in get
    raise value.as_instanceof_cause()
ray.exceptions.RayTaskError(TuneError): [36mray::ImplicitFunc.train()[39m (pid=102076, ip=192.168.249.74, repr=train_tune)
  File "/home/xwm/anaconda3/envs/SV/lib/python3.6/site-packages/ray/tune/trainable.py", line 319, in train
    result = self.step()
  File "/home/xwm/anaconda3/envs/SV/lib/python3.6/site-packages/ray/tune/function_runner.py", line 381, in step
    self._report_thread_runner_error(block=True)
  File "/home/xwm/anaconda3/envs/SV/lib/python3.6/site-packages/ray/tune/function_runner.py", line 532, in _report_thread_runner_error
    ("Trial raised an exception. Traceback:\n{}".format(err_tb_str)
ray.tune.error.TuneError: Trial raised an exception. Traceback:
[36mray::ImplicitFunc.train()[39m (pid=102076, ip=192.168.249.74, repr=train_tune)
  File "/home/xwm/anaconda3/envs/SV/lib/python3.6/site-packages/ray/tune/function_runner.py", line 262, in run
    self._entrypoint()
  File "/home/xwm/anaconda3/envs/SV/lib/python3.6/site-packages/ray/tune/function_runner.py", line 331, in entrypoint
    self._status_reporter.get_checkpoint())
  File "/home/xwm/anaconda3/envs/SV/lib/python3.6/site-packages/ray/tune/function_runner.py", line 600, in _trainable_func
    output = fn()
  File "/home/xwm/anaconda3/envs/SV/lib/python3.6/site-packages/ray/tune/utils/trainable.py", line 371, in inner
    trainable(config, **fn_kwargs)
  File "train.py", line 572, in train_tune
    on="validation_end"),
  File "/home/xwm/anaconda3/envs/SV/lib/python3.6/site-packages/pytorch_lightning/trainer/trainer.py", line 741, in fit
    self._fit_impl, model, train_dataloaders, val_dataloaders, datamodule, ckpt_path
  File "/home/xwm/anaconda3/envs/SV/lib/python3.6/site-packages/pytorch_lightning/trainer/trainer.py", line 685, in _call_and_handle_interrupt
    return trainer_fn(*args, **kwargs)
  File "/home/xwm/anaconda3/envs/SV/lib/python3.6/site-packages/pytorch_lightning/trainer/trainer.py", line 777, in _fit_impl
    self._run(model, ckpt_path=ckpt_path)
  File "/home/xwm/anaconda3/envs/SV/lib/python3.6/site-packages/pytorch_lightning/trainer/trainer.py", line 1145, in _run
    self.accelerator.setup(self)
  File "/home/xwm/anaconda3/envs/SV/lib/python3.6/site-packages/pytorch_lightning/accelerators/gpu.py", line 46, in setup
    return super().setup(trainer)
  File "/home/xwm/anaconda3/envs/SV/lib/python3.6/site-packages/pytorch_lightning/accelerators/accelerator.py", line 91, in setup
    self.setup_training_type_plugin()
  File "/home/xwm/anaconda3/envs/SV/lib/python3.6/site-packages/pytorch_lightning/accelerators/accelerator.py", line 363, in setup_training_type_plugin
    self.training_type_plugin.setup()
  File "/home/xwm/anaconda3/envs/SV/lib/python3.6/site-packages/pytorch_lightning/plugins/training_type/single_device.py", line 71, in setup
    self.model_to_device()
  File "/home/xwm/anaconda3/envs/SV/lib/python3.6/site-packages/pytorch_lightning/plugins/training_type/single_device.py", line 68, in model_to_device
    self._model.to(self.root_device)
  File "/home/xwm/anaconda3/envs/SV/lib/python3.6/site-packages/pytorch_lightning/core/mixins/device_dtype_mixin.py", line 111, in to
    return super().to(*args, **kwargs)
  File "/home/xwm/anaconda3/envs/SV/lib/python3.6/site-packages/torch/nn/modules/module.py", line 899, in to
    return self._apply(convert)
  File "/home/xwm/anaconda3/envs/SV/lib/python3.6/site-packages/torch/nn/modules/module.py", line 570, in _apply
    module._apply(fn)
  File "/home/xwm/anaconda3/envs/SV/lib/python3.6/site-packages/torch/nn/modules/module.py", line 570, in _apply
    module._apply(fn)
  File "/home/xwm/anaconda3/envs/SV/lib/python3.6/site-packages/torch/nn/modules/module.py", line 570, in _apply
    module._apply(fn)
  [Previous line repeated 1 more time]
  File "/home/xwm/anaconda3/envs/SV/lib/python3.6/site-packages/torch/nn/modules/module.py", line 593, in _apply
    param_applied = fn(param)
  File "/home/xwm/anaconda3/envs/SV/lib/python3.6/site-packages/torch/nn/modules/module.py", line 897, in convert
    return t.to(device, dtype if t.is_floating_point() or t.is_complex() else None, non_blocking)
RuntimeError: CUDA error: out of memory
CUDA kernel errors might be asynchronously reported at some other API call,so the stacktrace below might be incorrect.
For debugging consider passing CUDA_LAUNCH_BLOCKING=1.

Failure # 20 (occurred at 2022-06-15_22-58-04)
Traceback (most recent call last):
  File "/home/xwm/anaconda3/envs/SV/lib/python3.6/site-packages/ray/tune/trial_runner.py", line 886, in _process_trial
    results = self.trial_executor.fetch_result(trial)
  File "/home/xwm/anaconda3/envs/SV/lib/python3.6/site-packages/ray/tune/ray_trial_executor.py", line 675, in fetch_result
    result = ray.get(trial_future[0], timeout=DEFAULT_GET_TIMEOUT)
  File "/home/xwm/anaconda3/envs/SV/lib/python3.6/site-packages/ray/_private/client_mode_hook.py", line 105, in wrapper
    return func(*args, **kwargs)
  File "/home/xwm/anaconda3/envs/SV/lib/python3.6/site-packages/ray/worker.py", line 1763, in get
    raise value.as_instanceof_cause()
ray.exceptions.RayTaskError(TuneError): [36mray::ImplicitFunc.train()[39m (pid=106911, ip=192.168.249.74, repr=train_tune)
  File "/home/xwm/anaconda3/envs/SV/lib/python3.6/site-packages/ray/tune/trainable.py", line 319, in train
    result = self.step()
  File "/home/xwm/anaconda3/envs/SV/lib/python3.6/site-packages/ray/tune/function_runner.py", line 381, in step
    self._report_thread_runner_error(block=True)
  File "/home/xwm/anaconda3/envs/SV/lib/python3.6/site-packages/ray/tune/function_runner.py", line 532, in _report_thread_runner_error
    ("Trial raised an exception. Traceback:\n{}".format(err_tb_str)
ray.tune.error.TuneError: Trial raised an exception. Traceback:
[36mray::ImplicitFunc.train()[39m (pid=106911, ip=192.168.249.74, repr=train_tune)
  File "/home/xwm/anaconda3/envs/SV/lib/python3.6/site-packages/ray/tune/function_runner.py", line 262, in run
    self._entrypoint()
  File "/home/xwm/anaconda3/envs/SV/lib/python3.6/site-packages/ray/tune/function_runner.py", line 331, in entrypoint
    self._status_reporter.get_checkpoint())
  File "/home/xwm/anaconda3/envs/SV/lib/python3.6/site-packages/ray/tune/function_runner.py", line 600, in _trainable_func
    output = fn()
  File "/home/xwm/anaconda3/envs/SV/lib/python3.6/site-packages/ray/tune/utils/trainable.py", line 371, in inner
    trainable(config, **fn_kwargs)
  File "train.py", line 572, in train_tune
    on="validation_end"),
  File "/home/xwm/anaconda3/envs/SV/lib/python3.6/site-packages/pytorch_lightning/trainer/trainer.py", line 741, in fit
    self._fit_impl, model, train_dataloaders, val_dataloaders, datamodule, ckpt_path
  File "/home/xwm/anaconda3/envs/SV/lib/python3.6/site-packages/pytorch_lightning/trainer/trainer.py", line 685, in _call_and_handle_interrupt
    return trainer_fn(*args, **kwargs)
  File "/home/xwm/anaconda3/envs/SV/lib/python3.6/site-packages/pytorch_lightning/trainer/trainer.py", line 777, in _fit_impl
    self._run(model, ckpt_path=ckpt_path)
  File "/home/xwm/anaconda3/envs/SV/lib/python3.6/site-packages/pytorch_lightning/trainer/trainer.py", line 1145, in _run
    self.accelerator.setup(self)
  File "/home/xwm/anaconda3/envs/SV/lib/python3.6/site-packages/pytorch_lightning/accelerators/gpu.py", line 46, in setup
    return super().setup(trainer)
  File "/home/xwm/anaconda3/envs/SV/lib/python3.6/site-packages/pytorch_lightning/accelerators/accelerator.py", line 91, in setup
    self.setup_training_type_plugin()
  File "/home/xwm/anaconda3/envs/SV/lib/python3.6/site-packages/pytorch_lightning/accelerators/accelerator.py", line 363, in setup_training_type_plugin
    self.training_type_plugin.setup()
  File "/home/xwm/anaconda3/envs/SV/lib/python3.6/site-packages/pytorch_lightning/plugins/training_type/single_device.py", line 71, in setup
    self.model_to_device()
  File "/home/xwm/anaconda3/envs/SV/lib/python3.6/site-packages/pytorch_lightning/plugins/training_type/single_device.py", line 68, in model_to_device
    self._model.to(self.root_device)
  File "/home/xwm/anaconda3/envs/SV/lib/python3.6/site-packages/pytorch_lightning/core/mixins/device_dtype_mixin.py", line 111, in to
    return super().to(*args, **kwargs)
  File "/home/xwm/anaconda3/envs/SV/lib/python3.6/site-packages/torch/nn/modules/module.py", line 899, in to
    return self._apply(convert)
  File "/home/xwm/anaconda3/envs/SV/lib/python3.6/site-packages/torch/nn/modules/module.py", line 570, in _apply
    module._apply(fn)
  File "/home/xwm/anaconda3/envs/SV/lib/python3.6/site-packages/torch/nn/modules/module.py", line 570, in _apply
    module._apply(fn)
  File "/home/xwm/anaconda3/envs/SV/lib/python3.6/site-packages/torch/nn/modules/module.py", line 570, in _apply
    module._apply(fn)
  [Previous line repeated 1 more time]
  File "/home/xwm/anaconda3/envs/SV/lib/python3.6/site-packages/torch/nn/modules/module.py", line 593, in _apply
    param_applied = fn(param)
  File "/home/xwm/anaconda3/envs/SV/lib/python3.6/site-packages/torch/nn/modules/module.py", line 897, in convert
    return t.to(device, dtype if t.is_floating_point() or t.is_complex() else None, non_blocking)
RuntimeError: CUDA error: out of memory
CUDA kernel errors might be asynchronously reported at some other API call,so the stacktrace below might be incorrect.
For debugging consider passing CUDA_LAUNCH_BLOCKING=1.

Failure # 21 (occurred at 2022-06-15_22-59-15)
Traceback (most recent call last):
  File "/home/xwm/anaconda3/envs/SV/lib/python3.6/site-packages/ray/tune/trial_runner.py", line 886, in _process_trial
    results = self.trial_executor.fetch_result(trial)
  File "/home/xwm/anaconda3/envs/SV/lib/python3.6/site-packages/ray/tune/ray_trial_executor.py", line 675, in fetch_result
    result = ray.get(trial_future[0], timeout=DEFAULT_GET_TIMEOUT)
  File "/home/xwm/anaconda3/envs/SV/lib/python3.6/site-packages/ray/_private/client_mode_hook.py", line 105, in wrapper
    return func(*args, **kwargs)
  File "/home/xwm/anaconda3/envs/SV/lib/python3.6/site-packages/ray/worker.py", line 1763, in get
    raise value.as_instanceof_cause()
ray.exceptions.RayTaskError(TuneError): [36mray::ImplicitFunc.train()[39m (pid=112148, ip=192.168.249.74, repr=train_tune)
  File "/home/xwm/anaconda3/envs/SV/lib/python3.6/site-packages/ray/tune/trainable.py", line 319, in train
    result = self.step()
  File "/home/xwm/anaconda3/envs/SV/lib/python3.6/site-packages/ray/tune/function_runner.py", line 381, in step
    self._report_thread_runner_error(block=True)
  File "/home/xwm/anaconda3/envs/SV/lib/python3.6/site-packages/ray/tune/function_runner.py", line 532, in _report_thread_runner_error
    ("Trial raised an exception. Traceback:\n{}".format(err_tb_str)
ray.tune.error.TuneError: Trial raised an exception. Traceback:
[36mray::ImplicitFunc.train()[39m (pid=112148, ip=192.168.249.74, repr=train_tune)
  File "/home/xwm/anaconda3/envs/SV/lib/python3.6/site-packages/ray/tune/function_runner.py", line 262, in run
    self._entrypoint()
  File "/home/xwm/anaconda3/envs/SV/lib/python3.6/site-packages/ray/tune/function_runner.py", line 331, in entrypoint
    self._status_reporter.get_checkpoint())
  File "/home/xwm/anaconda3/envs/SV/lib/python3.6/site-packages/ray/tune/function_runner.py", line 600, in _trainable_func
    output = fn()
  File "/home/xwm/anaconda3/envs/SV/lib/python3.6/site-packages/ray/tune/utils/trainable.py", line 371, in inner
    trainable(config, **fn_kwargs)
  File "train.py", line 572, in train_tune
    on="validation_end"),
  File "/home/xwm/anaconda3/envs/SV/lib/python3.6/site-packages/pytorch_lightning/trainer/trainer.py", line 741, in fit
    self._fit_impl, model, train_dataloaders, val_dataloaders, datamodule, ckpt_path
  File "/home/xwm/anaconda3/envs/SV/lib/python3.6/site-packages/pytorch_lightning/trainer/trainer.py", line 685, in _call_and_handle_interrupt
    return trainer_fn(*args, **kwargs)
  File "/home/xwm/anaconda3/envs/SV/lib/python3.6/site-packages/pytorch_lightning/trainer/trainer.py", line 777, in _fit_impl
    self._run(model, ckpt_path=ckpt_path)
  File "/home/xwm/anaconda3/envs/SV/lib/python3.6/site-packages/pytorch_lightning/trainer/trainer.py", line 1145, in _run
    self.accelerator.setup(self)
  File "/home/xwm/anaconda3/envs/SV/lib/python3.6/site-packages/pytorch_lightning/accelerators/gpu.py", line 46, in setup
    return super().setup(trainer)
  File "/home/xwm/anaconda3/envs/SV/lib/python3.6/site-packages/pytorch_lightning/accelerators/accelerator.py", line 91, in setup
    self.setup_training_type_plugin()
  File "/home/xwm/anaconda3/envs/SV/lib/python3.6/site-packages/pytorch_lightning/accelerators/accelerator.py", line 363, in setup_training_type_plugin
    self.training_type_plugin.setup()
  File "/home/xwm/anaconda3/envs/SV/lib/python3.6/site-packages/pytorch_lightning/plugins/training_type/single_device.py", line 71, in setup
    self.model_to_device()
  File "/home/xwm/anaconda3/envs/SV/lib/python3.6/site-packages/pytorch_lightning/plugins/training_type/single_device.py", line 68, in model_to_device
    self._model.to(self.root_device)
  File "/home/xwm/anaconda3/envs/SV/lib/python3.6/site-packages/pytorch_lightning/core/mixins/device_dtype_mixin.py", line 111, in to
    return super().to(*args, **kwargs)
  File "/home/xwm/anaconda3/envs/SV/lib/python3.6/site-packages/torch/nn/modules/module.py", line 899, in to
    return self._apply(convert)
  File "/home/xwm/anaconda3/envs/SV/lib/python3.6/site-packages/torch/nn/modules/module.py", line 570, in _apply
    module._apply(fn)
  File "/home/xwm/anaconda3/envs/SV/lib/python3.6/site-packages/torch/nn/modules/module.py", line 570, in _apply
    module._apply(fn)
  File "/home/xwm/anaconda3/envs/SV/lib/python3.6/site-packages/torch/nn/modules/module.py", line 570, in _apply
    module._apply(fn)
  [Previous line repeated 1 more time]
  File "/home/xwm/anaconda3/envs/SV/lib/python3.6/site-packages/torch/nn/modules/module.py", line 593, in _apply
    param_applied = fn(param)
  File "/home/xwm/anaconda3/envs/SV/lib/python3.6/site-packages/torch/nn/modules/module.py", line 897, in convert
    return t.to(device, dtype if t.is_floating_point() or t.is_complex() else None, non_blocking)
RuntimeError: CUDA error: out of memory
CUDA kernel errors might be asynchronously reported at some other API call,so the stacktrace below might be incorrect.
For debugging consider passing CUDA_LAUNCH_BLOCKING=1.

Failure # 22 (occurred at 2022-06-15_23-00-38)
Traceback (most recent call last):
  File "/home/xwm/anaconda3/envs/SV/lib/python3.6/site-packages/ray/tune/trial_runner.py", line 886, in _process_trial
    results = self.trial_executor.fetch_result(trial)
  File "/home/xwm/anaconda3/envs/SV/lib/python3.6/site-packages/ray/tune/ray_trial_executor.py", line 675, in fetch_result
    result = ray.get(trial_future[0], timeout=DEFAULT_GET_TIMEOUT)
  File "/home/xwm/anaconda3/envs/SV/lib/python3.6/site-packages/ray/_private/client_mode_hook.py", line 105, in wrapper
    return func(*args, **kwargs)
  File "/home/xwm/anaconda3/envs/SV/lib/python3.6/site-packages/ray/worker.py", line 1763, in get
    raise value.as_instanceof_cause()
ray.exceptions.RayTaskError(TuneError): [36mray::ImplicitFunc.train()[39m (pid=116479, ip=192.168.249.74, repr=train_tune)
  File "/home/xwm/anaconda3/envs/SV/lib/python3.6/site-packages/ray/tune/trainable.py", line 319, in train
    result = self.step()
  File "/home/xwm/anaconda3/envs/SV/lib/python3.6/site-packages/ray/tune/function_runner.py", line 381, in step
    self._report_thread_runner_error(block=True)
  File "/home/xwm/anaconda3/envs/SV/lib/python3.6/site-packages/ray/tune/function_runner.py", line 532, in _report_thread_runner_error
    ("Trial raised an exception. Traceback:\n{}".format(err_tb_str)
ray.tune.error.TuneError: Trial raised an exception. Traceback:
[36mray::ImplicitFunc.train()[39m (pid=116479, ip=192.168.249.74, repr=train_tune)
  File "/home/xwm/anaconda3/envs/SV/lib/python3.6/site-packages/ray/tune/function_runner.py", line 262, in run
    self._entrypoint()
  File "/home/xwm/anaconda3/envs/SV/lib/python3.6/site-packages/ray/tune/function_runner.py", line 331, in entrypoint
    self._status_reporter.get_checkpoint())
  File "/home/xwm/anaconda3/envs/SV/lib/python3.6/site-packages/ray/tune/function_runner.py", line 600, in _trainable_func
    output = fn()
  File "/home/xwm/anaconda3/envs/SV/lib/python3.6/site-packages/ray/tune/utils/trainable.py", line 371, in inner
    trainable(config, **fn_kwargs)
  File "train.py", line 572, in train_tune
    on="validation_end"),
  File "/home/xwm/anaconda3/envs/SV/lib/python3.6/site-packages/pytorch_lightning/trainer/trainer.py", line 741, in fit
    self._fit_impl, model, train_dataloaders, val_dataloaders, datamodule, ckpt_path
  File "/home/xwm/anaconda3/envs/SV/lib/python3.6/site-packages/pytorch_lightning/trainer/trainer.py", line 685, in _call_and_handle_interrupt
    return trainer_fn(*args, **kwargs)
  File "/home/xwm/anaconda3/envs/SV/lib/python3.6/site-packages/pytorch_lightning/trainer/trainer.py", line 777, in _fit_impl
    self._run(model, ckpt_path=ckpt_path)
  File "/home/xwm/anaconda3/envs/SV/lib/python3.6/site-packages/pytorch_lightning/trainer/trainer.py", line 1145, in _run
    self.accelerator.setup(self)
  File "/home/xwm/anaconda3/envs/SV/lib/python3.6/site-packages/pytorch_lightning/accelerators/gpu.py", line 46, in setup
    return super().setup(trainer)
  File "/home/xwm/anaconda3/envs/SV/lib/python3.6/site-packages/pytorch_lightning/accelerators/accelerator.py", line 91, in setup
    self.setup_training_type_plugin()
  File "/home/xwm/anaconda3/envs/SV/lib/python3.6/site-packages/pytorch_lightning/accelerators/accelerator.py", line 363, in setup_training_type_plugin
    self.training_type_plugin.setup()
  File "/home/xwm/anaconda3/envs/SV/lib/python3.6/site-packages/pytorch_lightning/plugins/training_type/single_device.py", line 71, in setup
    self.model_to_device()
  File "/home/xwm/anaconda3/envs/SV/lib/python3.6/site-packages/pytorch_lightning/plugins/training_type/single_device.py", line 68, in model_to_device
    self._model.to(self.root_device)
  File "/home/xwm/anaconda3/envs/SV/lib/python3.6/site-packages/pytorch_lightning/core/mixins/device_dtype_mixin.py", line 111, in to
    return super().to(*args, **kwargs)
  File "/home/xwm/anaconda3/envs/SV/lib/python3.6/site-packages/torch/nn/modules/module.py", line 899, in to
    return self._apply(convert)
  File "/home/xwm/anaconda3/envs/SV/lib/python3.6/site-packages/torch/nn/modules/module.py", line 570, in _apply
    module._apply(fn)
  File "/home/xwm/anaconda3/envs/SV/lib/python3.6/site-packages/torch/nn/modules/module.py", line 570, in _apply
    module._apply(fn)
  File "/home/xwm/anaconda3/envs/SV/lib/python3.6/site-packages/torch/nn/modules/module.py", line 570, in _apply
    module._apply(fn)
  [Previous line repeated 1 more time]
  File "/home/xwm/anaconda3/envs/SV/lib/python3.6/site-packages/torch/nn/modules/module.py", line 593, in _apply
    param_applied = fn(param)
  File "/home/xwm/anaconda3/envs/SV/lib/python3.6/site-packages/torch/nn/modules/module.py", line 897, in convert
    return t.to(device, dtype if t.is_floating_point() or t.is_complex() else None, non_blocking)
RuntimeError: CUDA error: out of memory
CUDA kernel errors might be asynchronously reported at some other API call,so the stacktrace below might be incorrect.
For debugging consider passing CUDA_LAUNCH_BLOCKING=1.

Failure # 23 (occurred at 2022-06-15_23-01-55)
Traceback (most recent call last):
  File "/home/xwm/anaconda3/envs/SV/lib/python3.6/site-packages/ray/tune/trial_runner.py", line 886, in _process_trial
    results = self.trial_executor.fetch_result(trial)
  File "/home/xwm/anaconda3/envs/SV/lib/python3.6/site-packages/ray/tune/ray_trial_executor.py", line 675, in fetch_result
    result = ray.get(trial_future[0], timeout=DEFAULT_GET_TIMEOUT)
  File "/home/xwm/anaconda3/envs/SV/lib/python3.6/site-packages/ray/_private/client_mode_hook.py", line 105, in wrapper
    return func(*args, **kwargs)
  File "/home/xwm/anaconda3/envs/SV/lib/python3.6/site-packages/ray/worker.py", line 1763, in get
    raise value.as_instanceof_cause()
ray.exceptions.RayTaskError(TuneError): [36mray::ImplicitFunc.train()[39m (pid=119557, ip=192.168.249.74, repr=train_tune)
  File "/home/xwm/anaconda3/envs/SV/lib/python3.6/site-packages/ray/tune/trainable.py", line 319, in train
    result = self.step()
  File "/home/xwm/anaconda3/envs/SV/lib/python3.6/site-packages/ray/tune/function_runner.py", line 381, in step
    self._report_thread_runner_error(block=True)
  File "/home/xwm/anaconda3/envs/SV/lib/python3.6/site-packages/ray/tune/function_runner.py", line 532, in _report_thread_runner_error
    ("Trial raised an exception. Traceback:\n{}".format(err_tb_str)
ray.tune.error.TuneError: Trial raised an exception. Traceback:
[36mray::ImplicitFunc.train()[39m (pid=119557, ip=192.168.249.74, repr=train_tune)
  File "/home/xwm/anaconda3/envs/SV/lib/python3.6/site-packages/ray/tune/function_runner.py", line 262, in run
    self._entrypoint()
  File "/home/xwm/anaconda3/envs/SV/lib/python3.6/site-packages/ray/tune/function_runner.py", line 331, in entrypoint
    self._status_reporter.get_checkpoint())
  File "/home/xwm/anaconda3/envs/SV/lib/python3.6/site-packages/ray/tune/function_runner.py", line 600, in _trainable_func
    output = fn()
  File "/home/xwm/anaconda3/envs/SV/lib/python3.6/site-packages/ray/tune/utils/trainable.py", line 371, in inner
    trainable(config, **fn_kwargs)
  File "train.py", line 572, in train_tune
    on="validation_end"),
  File "/home/xwm/anaconda3/envs/SV/lib/python3.6/site-packages/pytorch_lightning/trainer/trainer.py", line 741, in fit
    self._fit_impl, model, train_dataloaders, val_dataloaders, datamodule, ckpt_path
  File "/home/xwm/anaconda3/envs/SV/lib/python3.6/site-packages/pytorch_lightning/trainer/trainer.py", line 685, in _call_and_handle_interrupt
    return trainer_fn(*args, **kwargs)
  File "/home/xwm/anaconda3/envs/SV/lib/python3.6/site-packages/pytorch_lightning/trainer/trainer.py", line 777, in _fit_impl
    self._run(model, ckpt_path=ckpt_path)
  File "/home/xwm/anaconda3/envs/SV/lib/python3.6/site-packages/pytorch_lightning/trainer/trainer.py", line 1145, in _run
    self.accelerator.setup(self)
  File "/home/xwm/anaconda3/envs/SV/lib/python3.6/site-packages/pytorch_lightning/accelerators/gpu.py", line 46, in setup
    return super().setup(trainer)
  File "/home/xwm/anaconda3/envs/SV/lib/python3.6/site-packages/pytorch_lightning/accelerators/accelerator.py", line 91, in setup
    self.setup_training_type_plugin()
  File "/home/xwm/anaconda3/envs/SV/lib/python3.6/site-packages/pytorch_lightning/accelerators/accelerator.py", line 363, in setup_training_type_plugin
    self.training_type_plugin.setup()
  File "/home/xwm/anaconda3/envs/SV/lib/python3.6/site-packages/pytorch_lightning/plugins/training_type/single_device.py", line 71, in setup
    self.model_to_device()
  File "/home/xwm/anaconda3/envs/SV/lib/python3.6/site-packages/pytorch_lightning/plugins/training_type/single_device.py", line 68, in model_to_device
    self._model.to(self.root_device)
  File "/home/xwm/anaconda3/envs/SV/lib/python3.6/site-packages/pytorch_lightning/core/mixins/device_dtype_mixin.py", line 111, in to
    return super().to(*args, **kwargs)
  File "/home/xwm/anaconda3/envs/SV/lib/python3.6/site-packages/torch/nn/modules/module.py", line 899, in to
    return self._apply(convert)
  File "/home/xwm/anaconda3/envs/SV/lib/python3.6/site-packages/torch/nn/modules/module.py", line 570, in _apply
    module._apply(fn)
  File "/home/xwm/anaconda3/envs/SV/lib/python3.6/site-packages/torch/nn/modules/module.py", line 570, in _apply
    module._apply(fn)
  File "/home/xwm/anaconda3/envs/SV/lib/python3.6/site-packages/torch/nn/modules/module.py", line 570, in _apply
    module._apply(fn)
  [Previous line repeated 1 more time]
  File "/home/xwm/anaconda3/envs/SV/lib/python3.6/site-packages/torch/nn/modules/module.py", line 593, in _apply
    param_applied = fn(param)
  File "/home/xwm/anaconda3/envs/SV/lib/python3.6/site-packages/torch/nn/modules/module.py", line 897, in convert
    return t.to(device, dtype if t.is_floating_point() or t.is_complex() else None, non_blocking)
RuntimeError: CUDA error: out of memory
CUDA kernel errors might be asynchronously reported at some other API call,so the stacktrace below might be incorrect.
For debugging consider passing CUDA_LAUNCH_BLOCKING=1.

Failure # 24 (occurred at 2022-06-15_23-03-04)
Traceback (most recent call last):
  File "/home/xwm/anaconda3/envs/SV/lib/python3.6/site-packages/ray/tune/trial_runner.py", line 886, in _process_trial
    results = self.trial_executor.fetch_result(trial)
  File "/home/xwm/anaconda3/envs/SV/lib/python3.6/site-packages/ray/tune/ray_trial_executor.py", line 675, in fetch_result
    result = ray.get(trial_future[0], timeout=DEFAULT_GET_TIMEOUT)
  File "/home/xwm/anaconda3/envs/SV/lib/python3.6/site-packages/ray/_private/client_mode_hook.py", line 105, in wrapper
    return func(*args, **kwargs)
  File "/home/xwm/anaconda3/envs/SV/lib/python3.6/site-packages/ray/worker.py", line 1763, in get
    raise value.as_instanceof_cause()
ray.exceptions.RayTaskError(TuneError): [36mray::ImplicitFunc.train()[39m (pid=127000, ip=192.168.249.74, repr=train_tune)
  File "/home/xwm/anaconda3/envs/SV/lib/python3.6/site-packages/ray/tune/trainable.py", line 319, in train
    result = self.step()
  File "/home/xwm/anaconda3/envs/SV/lib/python3.6/site-packages/ray/tune/function_runner.py", line 381, in step
    self._report_thread_runner_error(block=True)
  File "/home/xwm/anaconda3/envs/SV/lib/python3.6/site-packages/ray/tune/function_runner.py", line 532, in _report_thread_runner_error
    ("Trial raised an exception. Traceback:\n{}".format(err_tb_str)
ray.tune.error.TuneError: Trial raised an exception. Traceback:
[36mray::ImplicitFunc.train()[39m (pid=127000, ip=192.168.249.74, repr=train_tune)
  File "/home/xwm/anaconda3/envs/SV/lib/python3.6/site-packages/ray/tune/function_runner.py", line 262, in run
    self._entrypoint()
  File "/home/xwm/anaconda3/envs/SV/lib/python3.6/site-packages/ray/tune/function_runner.py", line 331, in entrypoint
    self._status_reporter.get_checkpoint())
  File "/home/xwm/anaconda3/envs/SV/lib/python3.6/site-packages/ray/tune/function_runner.py", line 600, in _trainable_func
    output = fn()
  File "/home/xwm/anaconda3/envs/SV/lib/python3.6/site-packages/ray/tune/utils/trainable.py", line 371, in inner
    trainable(config, **fn_kwargs)
  File "train.py", line 572, in train_tune
    on="validation_end"),
  File "/home/xwm/anaconda3/envs/SV/lib/python3.6/site-packages/pytorch_lightning/trainer/trainer.py", line 741, in fit
    self._fit_impl, model, train_dataloaders, val_dataloaders, datamodule, ckpt_path
  File "/home/xwm/anaconda3/envs/SV/lib/python3.6/site-packages/pytorch_lightning/trainer/trainer.py", line 685, in _call_and_handle_interrupt
    return trainer_fn(*args, **kwargs)
  File "/home/xwm/anaconda3/envs/SV/lib/python3.6/site-packages/pytorch_lightning/trainer/trainer.py", line 777, in _fit_impl
    self._run(model, ckpt_path=ckpt_path)
  File "/home/xwm/anaconda3/envs/SV/lib/python3.6/site-packages/pytorch_lightning/trainer/trainer.py", line 1145, in _run
    self.accelerator.setup(self)
  File "/home/xwm/anaconda3/envs/SV/lib/python3.6/site-packages/pytorch_lightning/accelerators/gpu.py", line 46, in setup
    return super().setup(trainer)
  File "/home/xwm/anaconda3/envs/SV/lib/python3.6/site-packages/pytorch_lightning/accelerators/accelerator.py", line 91, in setup
    self.setup_training_type_plugin()
  File "/home/xwm/anaconda3/envs/SV/lib/python3.6/site-packages/pytorch_lightning/accelerators/accelerator.py", line 363, in setup_training_type_plugin
    self.training_type_plugin.setup()
  File "/home/xwm/anaconda3/envs/SV/lib/python3.6/site-packages/pytorch_lightning/plugins/training_type/single_device.py", line 71, in setup
    self.model_to_device()
  File "/home/xwm/anaconda3/envs/SV/lib/python3.6/site-packages/pytorch_lightning/plugins/training_type/single_device.py", line 68, in model_to_device
    self._model.to(self.root_device)
  File "/home/xwm/anaconda3/envs/SV/lib/python3.6/site-packages/pytorch_lightning/core/mixins/device_dtype_mixin.py", line 111, in to
    return super().to(*args, **kwargs)
  File "/home/xwm/anaconda3/envs/SV/lib/python3.6/site-packages/torch/nn/modules/module.py", line 899, in to
    return self._apply(convert)
  File "/home/xwm/anaconda3/envs/SV/lib/python3.6/site-packages/torch/nn/modules/module.py", line 570, in _apply
    module._apply(fn)
  File "/home/xwm/anaconda3/envs/SV/lib/python3.6/site-packages/torch/nn/modules/module.py", line 570, in _apply
    module._apply(fn)
  File "/home/xwm/anaconda3/envs/SV/lib/python3.6/site-packages/torch/nn/modules/module.py", line 570, in _apply
    module._apply(fn)
  [Previous line repeated 1 more time]
  File "/home/xwm/anaconda3/envs/SV/lib/python3.6/site-packages/torch/nn/modules/module.py", line 593, in _apply
    param_applied = fn(param)
  File "/home/xwm/anaconda3/envs/SV/lib/python3.6/site-packages/torch/nn/modules/module.py", line 897, in convert
    return t.to(device, dtype if t.is_floating_point() or t.is_complex() else None, non_blocking)
RuntimeError: CUDA error: out of memory
CUDA kernel errors might be asynchronously reported at some other API call,so the stacktrace below might be incorrect.
For debugging consider passing CUDA_LAUNCH_BLOCKING=1.

Failure # 25 (occurred at 2022-06-15_23-04-18)
Traceback (most recent call last):
  File "/home/xwm/anaconda3/envs/SV/lib/python3.6/site-packages/ray/tune/trial_runner.py", line 886, in _process_trial
    results = self.trial_executor.fetch_result(trial)
  File "/home/xwm/anaconda3/envs/SV/lib/python3.6/site-packages/ray/tune/ray_trial_executor.py", line 675, in fetch_result
    result = ray.get(trial_future[0], timeout=DEFAULT_GET_TIMEOUT)
  File "/home/xwm/anaconda3/envs/SV/lib/python3.6/site-packages/ray/_private/client_mode_hook.py", line 105, in wrapper
    return func(*args, **kwargs)
  File "/home/xwm/anaconda3/envs/SV/lib/python3.6/site-packages/ray/worker.py", line 1763, in get
    raise value.as_instanceof_cause()
ray.exceptions.RayTaskError(TuneError): [36mray::ImplicitFunc.train()[39m (pid=131890, ip=192.168.249.74, repr=train_tune)
  File "/home/xwm/anaconda3/envs/SV/lib/python3.6/site-packages/ray/tune/trainable.py", line 319, in train
    result = self.step()
  File "/home/xwm/anaconda3/envs/SV/lib/python3.6/site-packages/ray/tune/function_runner.py", line 381, in step
    self._report_thread_runner_error(block=True)
  File "/home/xwm/anaconda3/envs/SV/lib/python3.6/site-packages/ray/tune/function_runner.py", line 532, in _report_thread_runner_error
    ("Trial raised an exception. Traceback:\n{}".format(err_tb_str)
ray.tune.error.TuneError: Trial raised an exception. Traceback:
[36mray::ImplicitFunc.train()[39m (pid=131890, ip=192.168.249.74, repr=train_tune)
  File "/home/xwm/anaconda3/envs/SV/lib/python3.6/site-packages/ray/tune/function_runner.py", line 262, in run
    self._entrypoint()
  File "/home/xwm/anaconda3/envs/SV/lib/python3.6/site-packages/ray/tune/function_runner.py", line 331, in entrypoint
    self._status_reporter.get_checkpoint())
  File "/home/xwm/anaconda3/envs/SV/lib/python3.6/site-packages/ray/tune/function_runner.py", line 600, in _trainable_func
    output = fn()
  File "/home/xwm/anaconda3/envs/SV/lib/python3.6/site-packages/ray/tune/utils/trainable.py", line 371, in inner
    trainable(config, **fn_kwargs)
  File "train.py", line 572, in train_tune
    on="validation_end"),
  File "/home/xwm/anaconda3/envs/SV/lib/python3.6/site-packages/pytorch_lightning/trainer/trainer.py", line 741, in fit
    self._fit_impl, model, train_dataloaders, val_dataloaders, datamodule, ckpt_path
  File "/home/xwm/anaconda3/envs/SV/lib/python3.6/site-packages/pytorch_lightning/trainer/trainer.py", line 685, in _call_and_handle_interrupt
    return trainer_fn(*args, **kwargs)
  File "/home/xwm/anaconda3/envs/SV/lib/python3.6/site-packages/pytorch_lightning/trainer/trainer.py", line 777, in _fit_impl
    self._run(model, ckpt_path=ckpt_path)
  File "/home/xwm/anaconda3/envs/SV/lib/python3.6/site-packages/pytorch_lightning/trainer/trainer.py", line 1145, in _run
    self.accelerator.setup(self)
  File "/home/xwm/anaconda3/envs/SV/lib/python3.6/site-packages/pytorch_lightning/accelerators/gpu.py", line 46, in setup
    return super().setup(trainer)
  File "/home/xwm/anaconda3/envs/SV/lib/python3.6/site-packages/pytorch_lightning/accelerators/accelerator.py", line 91, in setup
    self.setup_training_type_plugin()
  File "/home/xwm/anaconda3/envs/SV/lib/python3.6/site-packages/pytorch_lightning/accelerators/accelerator.py", line 363, in setup_training_type_plugin
    self.training_type_plugin.setup()
  File "/home/xwm/anaconda3/envs/SV/lib/python3.6/site-packages/pytorch_lightning/plugins/training_type/single_device.py", line 71, in setup
    self.model_to_device()
  File "/home/xwm/anaconda3/envs/SV/lib/python3.6/site-packages/pytorch_lightning/plugins/training_type/single_device.py", line 68, in model_to_device
    self._model.to(self.root_device)
  File "/home/xwm/anaconda3/envs/SV/lib/python3.6/site-packages/pytorch_lightning/core/mixins/device_dtype_mixin.py", line 111, in to
    return super().to(*args, **kwargs)
  File "/home/xwm/anaconda3/envs/SV/lib/python3.6/site-packages/torch/nn/modules/module.py", line 899, in to
    return self._apply(convert)
  File "/home/xwm/anaconda3/envs/SV/lib/python3.6/site-packages/torch/nn/modules/module.py", line 570, in _apply
    module._apply(fn)
  File "/home/xwm/anaconda3/envs/SV/lib/python3.6/site-packages/torch/nn/modules/module.py", line 570, in _apply
    module._apply(fn)
  File "/home/xwm/anaconda3/envs/SV/lib/python3.6/site-packages/torch/nn/modules/module.py", line 570, in _apply
    module._apply(fn)
  [Previous line repeated 1 more time]
  File "/home/xwm/anaconda3/envs/SV/lib/python3.6/site-packages/torch/nn/modules/module.py", line 593, in _apply
    param_applied = fn(param)
  File "/home/xwm/anaconda3/envs/SV/lib/python3.6/site-packages/torch/nn/modules/module.py", line 897, in convert
    return t.to(device, dtype if t.is_floating_point() or t.is_complex() else None, non_blocking)
RuntimeError: CUDA error: out of memory
CUDA kernel errors might be asynchronously reported at some other API call,so the stacktrace below might be incorrect.
For debugging consider passing CUDA_LAUNCH_BLOCKING=1.

Failure # 26 (occurred at 2022-06-15_23-05-31)
Traceback (most recent call last):
  File "/home/xwm/anaconda3/envs/SV/lib/python3.6/site-packages/ray/tune/trial_runner.py", line 886, in _process_trial
    results = self.trial_executor.fetch_result(trial)
  File "/home/xwm/anaconda3/envs/SV/lib/python3.6/site-packages/ray/tune/ray_trial_executor.py", line 675, in fetch_result
    result = ray.get(trial_future[0], timeout=DEFAULT_GET_TIMEOUT)
  File "/home/xwm/anaconda3/envs/SV/lib/python3.6/site-packages/ray/_private/client_mode_hook.py", line 105, in wrapper
    return func(*args, **kwargs)
  File "/home/xwm/anaconda3/envs/SV/lib/python3.6/site-packages/ray/worker.py", line 1763, in get
    raise value.as_instanceof_cause()
ray.exceptions.RayTaskError(TuneError): [36mray::ImplicitFunc.train()[39m (pid=136390, ip=192.168.249.74, repr=train_tune)
  File "/home/xwm/anaconda3/envs/SV/lib/python3.6/site-packages/ray/tune/trainable.py", line 319, in train
    result = self.step()
  File "/home/xwm/anaconda3/envs/SV/lib/python3.6/site-packages/ray/tune/function_runner.py", line 381, in step
    self._report_thread_runner_error(block=True)
  File "/home/xwm/anaconda3/envs/SV/lib/python3.6/site-packages/ray/tune/function_runner.py", line 532, in _report_thread_runner_error
    ("Trial raised an exception. Traceback:\n{}".format(err_tb_str)
ray.tune.error.TuneError: Trial raised an exception. Traceback:
[36mray::ImplicitFunc.train()[39m (pid=136390, ip=192.168.249.74, repr=train_tune)
  File "/home/xwm/anaconda3/envs/SV/lib/python3.6/site-packages/ray/tune/function_runner.py", line 262, in run
    self._entrypoint()
  File "/home/xwm/anaconda3/envs/SV/lib/python3.6/site-packages/ray/tune/function_runner.py", line 331, in entrypoint
    self._status_reporter.get_checkpoint())
  File "/home/xwm/anaconda3/envs/SV/lib/python3.6/site-packages/ray/tune/function_runner.py", line 600, in _trainable_func
    output = fn()
  File "/home/xwm/anaconda3/envs/SV/lib/python3.6/site-packages/ray/tune/utils/trainable.py", line 371, in inner
    trainable(config, **fn_kwargs)
  File "train.py", line 572, in train_tune
    on="validation_end"),
  File "/home/xwm/anaconda3/envs/SV/lib/python3.6/site-packages/pytorch_lightning/trainer/trainer.py", line 741, in fit
    self._fit_impl, model, train_dataloaders, val_dataloaders, datamodule, ckpt_path
  File "/home/xwm/anaconda3/envs/SV/lib/python3.6/site-packages/pytorch_lightning/trainer/trainer.py", line 685, in _call_and_handle_interrupt
    return trainer_fn(*args, **kwargs)
  File "/home/xwm/anaconda3/envs/SV/lib/python3.6/site-packages/pytorch_lightning/trainer/trainer.py", line 777, in _fit_impl
    self._run(model, ckpt_path=ckpt_path)
  File "/home/xwm/anaconda3/envs/SV/lib/python3.6/site-packages/pytorch_lightning/trainer/trainer.py", line 1145, in _run
    self.accelerator.setup(self)
  File "/home/xwm/anaconda3/envs/SV/lib/python3.6/site-packages/pytorch_lightning/accelerators/gpu.py", line 46, in setup
    return super().setup(trainer)
  File "/home/xwm/anaconda3/envs/SV/lib/python3.6/site-packages/pytorch_lightning/accelerators/accelerator.py", line 91, in setup
    self.setup_training_type_plugin()
  File "/home/xwm/anaconda3/envs/SV/lib/python3.6/site-packages/pytorch_lightning/accelerators/accelerator.py", line 363, in setup_training_type_plugin
    self.training_type_plugin.setup()
  File "/home/xwm/anaconda3/envs/SV/lib/python3.6/site-packages/pytorch_lightning/plugins/training_type/single_device.py", line 71, in setup
    self.model_to_device()
  File "/home/xwm/anaconda3/envs/SV/lib/python3.6/site-packages/pytorch_lightning/plugins/training_type/single_device.py", line 68, in model_to_device
    self._model.to(self.root_device)
  File "/home/xwm/anaconda3/envs/SV/lib/python3.6/site-packages/pytorch_lightning/core/mixins/device_dtype_mixin.py", line 111, in to
    return super().to(*args, **kwargs)
  File "/home/xwm/anaconda3/envs/SV/lib/python3.6/site-packages/torch/nn/modules/module.py", line 899, in to
    return self._apply(convert)
  File "/home/xwm/anaconda3/envs/SV/lib/python3.6/site-packages/torch/nn/modules/module.py", line 570, in _apply
    module._apply(fn)
  File "/home/xwm/anaconda3/envs/SV/lib/python3.6/site-packages/torch/nn/modules/module.py", line 570, in _apply
    module._apply(fn)
  File "/home/xwm/anaconda3/envs/SV/lib/python3.6/site-packages/torch/nn/modules/module.py", line 570, in _apply
    module._apply(fn)
  [Previous line repeated 1 more time]
  File "/home/xwm/anaconda3/envs/SV/lib/python3.6/site-packages/torch/nn/modules/module.py", line 593, in _apply
    param_applied = fn(param)
  File "/home/xwm/anaconda3/envs/SV/lib/python3.6/site-packages/torch/nn/modules/module.py", line 897, in convert
    return t.to(device, dtype if t.is_floating_point() or t.is_complex() else None, non_blocking)
RuntimeError: CUDA error: out of memory
CUDA kernel errors might be asynchronously reported at some other API call,so the stacktrace below might be incorrect.
For debugging consider passing CUDA_LAUNCH_BLOCKING=1.

Failure # 27 (occurred at 2022-06-15_23-06-53)
Traceback (most recent call last):
  File "/home/xwm/anaconda3/envs/SV/lib/python3.6/site-packages/ray/tune/trial_runner.py", line 886, in _process_trial
    results = self.trial_executor.fetch_result(trial)
  File "/home/xwm/anaconda3/envs/SV/lib/python3.6/site-packages/ray/tune/ray_trial_executor.py", line 675, in fetch_result
    result = ray.get(trial_future[0], timeout=DEFAULT_GET_TIMEOUT)
  File "/home/xwm/anaconda3/envs/SV/lib/python3.6/site-packages/ray/_private/client_mode_hook.py", line 105, in wrapper
    return func(*args, **kwargs)
  File "/home/xwm/anaconda3/envs/SV/lib/python3.6/site-packages/ray/worker.py", line 1763, in get
    raise value.as_instanceof_cause()
ray.exceptions.RayTaskError(TuneError): [36mray::ImplicitFunc.train()[39m (pid=141253, ip=192.168.249.74, repr=train_tune)
  File "/home/xwm/anaconda3/envs/SV/lib/python3.6/site-packages/ray/tune/trainable.py", line 319, in train
    result = self.step()
  File "/home/xwm/anaconda3/envs/SV/lib/python3.6/site-packages/ray/tune/function_runner.py", line 381, in step
    self._report_thread_runner_error(block=True)
  File "/home/xwm/anaconda3/envs/SV/lib/python3.6/site-packages/ray/tune/function_runner.py", line 532, in _report_thread_runner_error
    ("Trial raised an exception. Traceback:\n{}".format(err_tb_str)
ray.tune.error.TuneError: Trial raised an exception. Traceback:
[36mray::ImplicitFunc.train()[39m (pid=141253, ip=192.168.249.74, repr=train_tune)
  File "/home/xwm/anaconda3/envs/SV/lib/python3.6/site-packages/ray/tune/function_runner.py", line 262, in run
    self._entrypoint()
  File "/home/xwm/anaconda3/envs/SV/lib/python3.6/site-packages/ray/tune/function_runner.py", line 331, in entrypoint
    self._status_reporter.get_checkpoint())
  File "/home/xwm/anaconda3/envs/SV/lib/python3.6/site-packages/ray/tune/function_runner.py", line 600, in _trainable_func
    output = fn()
  File "/home/xwm/anaconda3/envs/SV/lib/python3.6/site-packages/ray/tune/utils/trainable.py", line 371, in inner
    trainable(config, **fn_kwargs)
  File "train.py", line 572, in train_tune
    on="validation_end"),
  File "/home/xwm/anaconda3/envs/SV/lib/python3.6/site-packages/pytorch_lightning/trainer/trainer.py", line 741, in fit
    self._fit_impl, model, train_dataloaders, val_dataloaders, datamodule, ckpt_path
  File "/home/xwm/anaconda3/envs/SV/lib/python3.6/site-packages/pytorch_lightning/trainer/trainer.py", line 685, in _call_and_handle_interrupt
    return trainer_fn(*args, **kwargs)
  File "/home/xwm/anaconda3/envs/SV/lib/python3.6/site-packages/pytorch_lightning/trainer/trainer.py", line 777, in _fit_impl
    self._run(model, ckpt_path=ckpt_path)
  File "/home/xwm/anaconda3/envs/SV/lib/python3.6/site-packages/pytorch_lightning/trainer/trainer.py", line 1145, in _run
    self.accelerator.setup(self)
  File "/home/xwm/anaconda3/envs/SV/lib/python3.6/site-packages/pytorch_lightning/accelerators/gpu.py", line 46, in setup
    return super().setup(trainer)
  File "/home/xwm/anaconda3/envs/SV/lib/python3.6/site-packages/pytorch_lightning/accelerators/accelerator.py", line 91, in setup
    self.setup_training_type_plugin()
  File "/home/xwm/anaconda3/envs/SV/lib/python3.6/site-packages/pytorch_lightning/accelerators/accelerator.py", line 363, in setup_training_type_plugin
    self.training_type_plugin.setup()
  File "/home/xwm/anaconda3/envs/SV/lib/python3.6/site-packages/pytorch_lightning/plugins/training_type/single_device.py", line 71, in setup
    self.model_to_device()
  File "/home/xwm/anaconda3/envs/SV/lib/python3.6/site-packages/pytorch_lightning/plugins/training_type/single_device.py", line 68, in model_to_device
    self._model.to(self.root_device)
  File "/home/xwm/anaconda3/envs/SV/lib/python3.6/site-packages/pytorch_lightning/core/mixins/device_dtype_mixin.py", line 111, in to
    return super().to(*args, **kwargs)
  File "/home/xwm/anaconda3/envs/SV/lib/python3.6/site-packages/torch/nn/modules/module.py", line 899, in to
    return self._apply(convert)
  File "/home/xwm/anaconda3/envs/SV/lib/python3.6/site-packages/torch/nn/modules/module.py", line 570, in _apply
    module._apply(fn)
  File "/home/xwm/anaconda3/envs/SV/lib/python3.6/site-packages/torch/nn/modules/module.py", line 570, in _apply
    module._apply(fn)
  File "/home/xwm/anaconda3/envs/SV/lib/python3.6/site-packages/torch/nn/modules/module.py", line 570, in _apply
    module._apply(fn)
  [Previous line repeated 1 more time]
  File "/home/xwm/anaconda3/envs/SV/lib/python3.6/site-packages/torch/nn/modules/module.py", line 593, in _apply
    param_applied = fn(param)
  File "/home/xwm/anaconda3/envs/SV/lib/python3.6/site-packages/torch/nn/modules/module.py", line 897, in convert
    return t.to(device, dtype if t.is_floating_point() or t.is_complex() else None, non_blocking)
RuntimeError: CUDA error: out of memory
CUDA kernel errors might be asynchronously reported at some other API call,so the stacktrace below might be incorrect.
For debugging consider passing CUDA_LAUNCH_BLOCKING=1.

Failure # 28 (occurred at 2022-06-15_23-08-06)
Traceback (most recent call last):
  File "/home/xwm/anaconda3/envs/SV/lib/python3.6/site-packages/ray/tune/trial_runner.py", line 886, in _process_trial
    results = self.trial_executor.fetch_result(trial)
  File "/home/xwm/anaconda3/envs/SV/lib/python3.6/site-packages/ray/tune/ray_trial_executor.py", line 675, in fetch_result
    result = ray.get(trial_future[0], timeout=DEFAULT_GET_TIMEOUT)
  File "/home/xwm/anaconda3/envs/SV/lib/python3.6/site-packages/ray/_private/client_mode_hook.py", line 105, in wrapper
    return func(*args, **kwargs)
  File "/home/xwm/anaconda3/envs/SV/lib/python3.6/site-packages/ray/worker.py", line 1763, in get
    raise value.as_instanceof_cause()
ray.exceptions.RayTaskError(TuneError): [36mray::ImplicitFunc.train()[39m (pid=145857, ip=192.168.249.74, repr=train_tune)
  File "/home/xwm/anaconda3/envs/SV/lib/python3.6/site-packages/ray/tune/trainable.py", line 319, in train
    result = self.step()
  File "/home/xwm/anaconda3/envs/SV/lib/python3.6/site-packages/ray/tune/function_runner.py", line 381, in step
    self._report_thread_runner_error(block=True)
  File "/home/xwm/anaconda3/envs/SV/lib/python3.6/site-packages/ray/tune/function_runner.py", line 532, in _report_thread_runner_error
    ("Trial raised an exception. Traceback:\n{}".format(err_tb_str)
ray.tune.error.TuneError: Trial raised an exception. Traceback:
[36mray::ImplicitFunc.train()[39m (pid=145857, ip=192.168.249.74, repr=train_tune)
  File "/home/xwm/anaconda3/envs/SV/lib/python3.6/site-packages/ray/tune/function_runner.py", line 262, in run
    self._entrypoint()
  File "/home/xwm/anaconda3/envs/SV/lib/python3.6/site-packages/ray/tune/function_runner.py", line 331, in entrypoint
    self._status_reporter.get_checkpoint())
  File "/home/xwm/anaconda3/envs/SV/lib/python3.6/site-packages/ray/tune/function_runner.py", line 600, in _trainable_func
    output = fn()
  File "/home/xwm/anaconda3/envs/SV/lib/python3.6/site-packages/ray/tune/utils/trainable.py", line 371, in inner
    trainable(config, **fn_kwargs)
  File "train.py", line 572, in train_tune
    on="validation_end"),
  File "/home/xwm/anaconda3/envs/SV/lib/python3.6/site-packages/pytorch_lightning/trainer/trainer.py", line 741, in fit
    self._fit_impl, model, train_dataloaders, val_dataloaders, datamodule, ckpt_path
  File "/home/xwm/anaconda3/envs/SV/lib/python3.6/site-packages/pytorch_lightning/trainer/trainer.py", line 685, in _call_and_handle_interrupt
    return trainer_fn(*args, **kwargs)
  File "/home/xwm/anaconda3/envs/SV/lib/python3.6/site-packages/pytorch_lightning/trainer/trainer.py", line 777, in _fit_impl
    self._run(model, ckpt_path=ckpt_path)
  File "/home/xwm/anaconda3/envs/SV/lib/python3.6/site-packages/pytorch_lightning/trainer/trainer.py", line 1145, in _run
    self.accelerator.setup(self)
  File "/home/xwm/anaconda3/envs/SV/lib/python3.6/site-packages/pytorch_lightning/accelerators/gpu.py", line 46, in setup
    return super().setup(trainer)
  File "/home/xwm/anaconda3/envs/SV/lib/python3.6/site-packages/pytorch_lightning/accelerators/accelerator.py", line 91, in setup
    self.setup_training_type_plugin()
  File "/home/xwm/anaconda3/envs/SV/lib/python3.6/site-packages/pytorch_lightning/accelerators/accelerator.py", line 363, in setup_training_type_plugin
    self.training_type_plugin.setup()
  File "/home/xwm/anaconda3/envs/SV/lib/python3.6/site-packages/pytorch_lightning/plugins/training_type/single_device.py", line 71, in setup
    self.model_to_device()
  File "/home/xwm/anaconda3/envs/SV/lib/python3.6/site-packages/pytorch_lightning/plugins/training_type/single_device.py", line 68, in model_to_device
    self._model.to(self.root_device)
  File "/home/xwm/anaconda3/envs/SV/lib/python3.6/site-packages/pytorch_lightning/core/mixins/device_dtype_mixin.py", line 111, in to
    return super().to(*args, **kwargs)
  File "/home/xwm/anaconda3/envs/SV/lib/python3.6/site-packages/torch/nn/modules/module.py", line 899, in to
    return self._apply(convert)
  File "/home/xwm/anaconda3/envs/SV/lib/python3.6/site-packages/torch/nn/modules/module.py", line 570, in _apply
    module._apply(fn)
  File "/home/xwm/anaconda3/envs/SV/lib/python3.6/site-packages/torch/nn/modules/module.py", line 570, in _apply
    module._apply(fn)
  File "/home/xwm/anaconda3/envs/SV/lib/python3.6/site-packages/torch/nn/modules/module.py", line 570, in _apply
    module._apply(fn)
  [Previous line repeated 1 more time]
  File "/home/xwm/anaconda3/envs/SV/lib/python3.6/site-packages/torch/nn/modules/module.py", line 593, in _apply
    param_applied = fn(param)
  File "/home/xwm/anaconda3/envs/SV/lib/python3.6/site-packages/torch/nn/modules/module.py", line 897, in convert
    return t.to(device, dtype if t.is_floating_point() or t.is_complex() else None, non_blocking)
RuntimeError: CUDA error: out of memory
CUDA kernel errors might be asynchronously reported at some other API call,so the stacktrace below might be incorrect.
For debugging consider passing CUDA_LAUNCH_BLOCKING=1.

Failure # 29 (occurred at 2022-06-15_23-09-38)
Traceback (most recent call last):
  File "/home/xwm/anaconda3/envs/SV/lib/python3.6/site-packages/ray/tune/trial_runner.py", line 886, in _process_trial
    results = self.trial_executor.fetch_result(trial)
  File "/home/xwm/anaconda3/envs/SV/lib/python3.6/site-packages/ray/tune/ray_trial_executor.py", line 675, in fetch_result
    result = ray.get(trial_future[0], timeout=DEFAULT_GET_TIMEOUT)
  File "/home/xwm/anaconda3/envs/SV/lib/python3.6/site-packages/ray/_private/client_mode_hook.py", line 105, in wrapper
    return func(*args, **kwargs)
  File "/home/xwm/anaconda3/envs/SV/lib/python3.6/site-packages/ray/worker.py", line 1763, in get
    raise value.as_instanceof_cause()
ray.exceptions.RayTaskError(TuneError): [36mray::ImplicitFunc.train()[39m (pid=148475, ip=192.168.249.74, repr=train_tune)
  File "/home/xwm/anaconda3/envs/SV/lib/python3.6/site-packages/ray/tune/trainable.py", line 319, in train
    result = self.step()
  File "/home/xwm/anaconda3/envs/SV/lib/python3.6/site-packages/ray/tune/function_runner.py", line 381, in step
    self._report_thread_runner_error(block=True)
  File "/home/xwm/anaconda3/envs/SV/lib/python3.6/site-packages/ray/tune/function_runner.py", line 532, in _report_thread_runner_error
    ("Trial raised an exception. Traceback:\n{}".format(err_tb_str)
ray.tune.error.TuneError: Trial raised an exception. Traceback:
[36mray::ImplicitFunc.train()[39m (pid=148475, ip=192.168.249.74, repr=train_tune)
  File "/home/xwm/anaconda3/envs/SV/lib/python3.6/site-packages/ray/tune/function_runner.py", line 262, in run
    self._entrypoint()
  File "/home/xwm/anaconda3/envs/SV/lib/python3.6/site-packages/ray/tune/function_runner.py", line 331, in entrypoint
    self._status_reporter.get_checkpoint())
  File "/home/xwm/anaconda3/envs/SV/lib/python3.6/site-packages/ray/tune/function_runner.py", line 600, in _trainable_func
    output = fn()
  File "/home/xwm/anaconda3/envs/SV/lib/python3.6/site-packages/ray/tune/utils/trainable.py", line 371, in inner
    trainable(config, **fn_kwargs)
  File "train.py", line 572, in train_tune
    on="validation_end"),
  File "/home/xwm/anaconda3/envs/SV/lib/python3.6/site-packages/pytorch_lightning/trainer/trainer.py", line 741, in fit
    self._fit_impl, model, train_dataloaders, val_dataloaders, datamodule, ckpt_path
  File "/home/xwm/anaconda3/envs/SV/lib/python3.6/site-packages/pytorch_lightning/trainer/trainer.py", line 685, in _call_and_handle_interrupt
    return trainer_fn(*args, **kwargs)
  File "/home/xwm/anaconda3/envs/SV/lib/python3.6/site-packages/pytorch_lightning/trainer/trainer.py", line 777, in _fit_impl
    self._run(model, ckpt_path=ckpt_path)
  File "/home/xwm/anaconda3/envs/SV/lib/python3.6/site-packages/pytorch_lightning/trainer/trainer.py", line 1145, in _run
    self.accelerator.setup(self)
  File "/home/xwm/anaconda3/envs/SV/lib/python3.6/site-packages/pytorch_lightning/accelerators/gpu.py", line 46, in setup
    return super().setup(trainer)
  File "/home/xwm/anaconda3/envs/SV/lib/python3.6/site-packages/pytorch_lightning/accelerators/accelerator.py", line 91, in setup
    self.setup_training_type_plugin()
  File "/home/xwm/anaconda3/envs/SV/lib/python3.6/site-packages/pytorch_lightning/accelerators/accelerator.py", line 363, in setup_training_type_plugin
    self.training_type_plugin.setup()
  File "/home/xwm/anaconda3/envs/SV/lib/python3.6/site-packages/pytorch_lightning/plugins/training_type/single_device.py", line 71, in setup
    self.model_to_device()
  File "/home/xwm/anaconda3/envs/SV/lib/python3.6/site-packages/pytorch_lightning/plugins/training_type/single_device.py", line 68, in model_to_device
    self._model.to(self.root_device)
  File "/home/xwm/anaconda3/envs/SV/lib/python3.6/site-packages/pytorch_lightning/core/mixins/device_dtype_mixin.py", line 111, in to
    return super().to(*args, **kwargs)
  File "/home/xwm/anaconda3/envs/SV/lib/python3.6/site-packages/torch/nn/modules/module.py", line 899, in to
    return self._apply(convert)
  File "/home/xwm/anaconda3/envs/SV/lib/python3.6/site-packages/torch/nn/modules/module.py", line 570, in _apply
    module._apply(fn)
  File "/home/xwm/anaconda3/envs/SV/lib/python3.6/site-packages/torch/nn/modules/module.py", line 570, in _apply
    module._apply(fn)
  File "/home/xwm/anaconda3/envs/SV/lib/python3.6/site-packages/torch/nn/modules/module.py", line 570, in _apply
    module._apply(fn)
  [Previous line repeated 1 more time]
  File "/home/xwm/anaconda3/envs/SV/lib/python3.6/site-packages/torch/nn/modules/module.py", line 593, in _apply
    param_applied = fn(param)
  File "/home/xwm/anaconda3/envs/SV/lib/python3.6/site-packages/torch/nn/modules/module.py", line 897, in convert
    return t.to(device, dtype if t.is_floating_point() or t.is_complex() else None, non_blocking)
RuntimeError: CUDA error: out of memory
CUDA kernel errors might be asynchronously reported at some other API call,so the stacktrace below might be incorrect.
For debugging consider passing CUDA_LAUNCH_BLOCKING=1.

Failure # 30 (occurred at 2022-06-15_23-10-47)
Traceback (most recent call last):
  File "/home/xwm/anaconda3/envs/SV/lib/python3.6/site-packages/ray/tune/trial_runner.py", line 886, in _process_trial
    results = self.trial_executor.fetch_result(trial)
  File "/home/xwm/anaconda3/envs/SV/lib/python3.6/site-packages/ray/tune/ray_trial_executor.py", line 675, in fetch_result
    result = ray.get(trial_future[0], timeout=DEFAULT_GET_TIMEOUT)
  File "/home/xwm/anaconda3/envs/SV/lib/python3.6/site-packages/ray/_private/client_mode_hook.py", line 105, in wrapper
    return func(*args, **kwargs)
  File "/home/xwm/anaconda3/envs/SV/lib/python3.6/site-packages/ray/worker.py", line 1763, in get
    raise value.as_instanceof_cause()
ray.exceptions.RayTaskError(TuneError): [36mray::ImplicitFunc.train()[39m (pid=156397, ip=192.168.249.74, repr=train_tune)
  File "/home/xwm/anaconda3/envs/SV/lib/python3.6/site-packages/ray/tune/trainable.py", line 319, in train
    result = self.step()
  File "/home/xwm/anaconda3/envs/SV/lib/python3.6/site-packages/ray/tune/function_runner.py", line 381, in step
    self._report_thread_runner_error(block=True)
  File "/home/xwm/anaconda3/envs/SV/lib/python3.6/site-packages/ray/tune/function_runner.py", line 532, in _report_thread_runner_error
    ("Trial raised an exception. Traceback:\n{}".format(err_tb_str)
ray.tune.error.TuneError: Trial raised an exception. Traceback:
[36mray::ImplicitFunc.train()[39m (pid=156397, ip=192.168.249.74, repr=train_tune)
  File "/home/xwm/anaconda3/envs/SV/lib/python3.6/site-packages/ray/tune/function_runner.py", line 262, in run
    self._entrypoint()
  File "/home/xwm/anaconda3/envs/SV/lib/python3.6/site-packages/ray/tune/function_runner.py", line 331, in entrypoint
    self._status_reporter.get_checkpoint())
  File "/home/xwm/anaconda3/envs/SV/lib/python3.6/site-packages/ray/tune/function_runner.py", line 600, in _trainable_func
    output = fn()
  File "/home/xwm/anaconda3/envs/SV/lib/python3.6/site-packages/ray/tune/utils/trainable.py", line 371, in inner
    trainable(config, **fn_kwargs)
  File "train.py", line 572, in train_tune
    on="validation_end"),
  File "/home/xwm/anaconda3/envs/SV/lib/python3.6/site-packages/pytorch_lightning/trainer/trainer.py", line 741, in fit
    self._fit_impl, model, train_dataloaders, val_dataloaders, datamodule, ckpt_path
  File "/home/xwm/anaconda3/envs/SV/lib/python3.6/site-packages/pytorch_lightning/trainer/trainer.py", line 685, in _call_and_handle_interrupt
    return trainer_fn(*args, **kwargs)
  File "/home/xwm/anaconda3/envs/SV/lib/python3.6/site-packages/pytorch_lightning/trainer/trainer.py", line 777, in _fit_impl
    self._run(model, ckpt_path=ckpt_path)
  File "/home/xwm/anaconda3/envs/SV/lib/python3.6/site-packages/pytorch_lightning/trainer/trainer.py", line 1145, in _run
    self.accelerator.setup(self)
  File "/home/xwm/anaconda3/envs/SV/lib/python3.6/site-packages/pytorch_lightning/accelerators/gpu.py", line 46, in setup
    return super().setup(trainer)
  File "/home/xwm/anaconda3/envs/SV/lib/python3.6/site-packages/pytorch_lightning/accelerators/accelerator.py", line 91, in setup
    self.setup_training_type_plugin()
  File "/home/xwm/anaconda3/envs/SV/lib/python3.6/site-packages/pytorch_lightning/accelerators/accelerator.py", line 363, in setup_training_type_plugin
    self.training_type_plugin.setup()
  File "/home/xwm/anaconda3/envs/SV/lib/python3.6/site-packages/pytorch_lightning/plugins/training_type/single_device.py", line 71, in setup
    self.model_to_device()
  File "/home/xwm/anaconda3/envs/SV/lib/python3.6/site-packages/pytorch_lightning/plugins/training_type/single_device.py", line 68, in model_to_device
    self._model.to(self.root_device)
  File "/home/xwm/anaconda3/envs/SV/lib/python3.6/site-packages/pytorch_lightning/core/mixins/device_dtype_mixin.py", line 111, in to
    return super().to(*args, **kwargs)
  File "/home/xwm/anaconda3/envs/SV/lib/python3.6/site-packages/torch/nn/modules/module.py", line 899, in to
    return self._apply(convert)
  File "/home/xwm/anaconda3/envs/SV/lib/python3.6/site-packages/torch/nn/modules/module.py", line 570, in _apply
    module._apply(fn)
  File "/home/xwm/anaconda3/envs/SV/lib/python3.6/site-packages/torch/nn/modules/module.py", line 570, in _apply
    module._apply(fn)
  File "/home/xwm/anaconda3/envs/SV/lib/python3.6/site-packages/torch/nn/modules/module.py", line 570, in _apply
    module._apply(fn)
  [Previous line repeated 1 more time]
  File "/home/xwm/anaconda3/envs/SV/lib/python3.6/site-packages/torch/nn/modules/module.py", line 593, in _apply
    param_applied = fn(param)
  File "/home/xwm/anaconda3/envs/SV/lib/python3.6/site-packages/torch/nn/modules/module.py", line 897, in convert
    return t.to(device, dtype if t.is_floating_point() or t.is_complex() else None, non_blocking)
RuntimeError: CUDA error: out of memory
CUDA kernel errors might be asynchronously reported at some other API call,so the stacktrace below might be incorrect.
For debugging consider passing CUDA_LAUNCH_BLOCKING=1.

Failure # 31 (occurred at 2022-06-15_23-11-56)
Traceback (most recent call last):
  File "/home/xwm/anaconda3/envs/SV/lib/python3.6/site-packages/ray/tune/trial_runner.py", line 886, in _process_trial
    results = self.trial_executor.fetch_result(trial)
  File "/home/xwm/anaconda3/envs/SV/lib/python3.6/site-packages/ray/tune/ray_trial_executor.py", line 675, in fetch_result
    result = ray.get(trial_future[0], timeout=DEFAULT_GET_TIMEOUT)
  File "/home/xwm/anaconda3/envs/SV/lib/python3.6/site-packages/ray/_private/client_mode_hook.py", line 105, in wrapper
    return func(*args, **kwargs)
  File "/home/xwm/anaconda3/envs/SV/lib/python3.6/site-packages/ray/worker.py", line 1763, in get
    raise value.as_instanceof_cause()
ray.exceptions.RayTaskError(TuneError): [36mray::ImplicitFunc.train()[39m (pid=161151, ip=192.168.249.74, repr=train_tune)
  File "/home/xwm/anaconda3/envs/SV/lib/python3.6/site-packages/ray/tune/trainable.py", line 319, in train
    result = self.step()
  File "/home/xwm/anaconda3/envs/SV/lib/python3.6/site-packages/ray/tune/function_runner.py", line 381, in step
    self._report_thread_runner_error(block=True)
  File "/home/xwm/anaconda3/envs/SV/lib/python3.6/site-packages/ray/tune/function_runner.py", line 532, in _report_thread_runner_error
    ("Trial raised an exception. Traceback:\n{}".format(err_tb_str)
ray.tune.error.TuneError: Trial raised an exception. Traceback:
[36mray::ImplicitFunc.train()[39m (pid=161151, ip=192.168.249.74, repr=train_tune)
  File "/home/xwm/anaconda3/envs/SV/lib/python3.6/site-packages/ray/tune/function_runner.py", line 262, in run
    self._entrypoint()
  File "/home/xwm/anaconda3/envs/SV/lib/python3.6/site-packages/ray/tune/function_runner.py", line 331, in entrypoint
    self._status_reporter.get_checkpoint())
  File "/home/xwm/anaconda3/envs/SV/lib/python3.6/site-packages/ray/tune/function_runner.py", line 600, in _trainable_func
    output = fn()
  File "/home/xwm/anaconda3/envs/SV/lib/python3.6/site-packages/ray/tune/utils/trainable.py", line 371, in inner
    trainable(config, **fn_kwargs)
  File "train.py", line 572, in train_tune
    on="validation_end"),
  File "/home/xwm/anaconda3/envs/SV/lib/python3.6/site-packages/pytorch_lightning/trainer/trainer.py", line 741, in fit
    self._fit_impl, model, train_dataloaders, val_dataloaders, datamodule, ckpt_path
  File "/home/xwm/anaconda3/envs/SV/lib/python3.6/site-packages/pytorch_lightning/trainer/trainer.py", line 685, in _call_and_handle_interrupt
    return trainer_fn(*args, **kwargs)
  File "/home/xwm/anaconda3/envs/SV/lib/python3.6/site-packages/pytorch_lightning/trainer/trainer.py", line 777, in _fit_impl
    self._run(model, ckpt_path=ckpt_path)
  File "/home/xwm/anaconda3/envs/SV/lib/python3.6/site-packages/pytorch_lightning/trainer/trainer.py", line 1145, in _run
    self.accelerator.setup(self)
  File "/home/xwm/anaconda3/envs/SV/lib/python3.6/site-packages/pytorch_lightning/accelerators/gpu.py", line 46, in setup
    return super().setup(trainer)
  File "/home/xwm/anaconda3/envs/SV/lib/python3.6/site-packages/pytorch_lightning/accelerators/accelerator.py", line 91, in setup
    self.setup_training_type_plugin()
  File "/home/xwm/anaconda3/envs/SV/lib/python3.6/site-packages/pytorch_lightning/accelerators/accelerator.py", line 363, in setup_training_type_plugin
    self.training_type_plugin.setup()
  File "/home/xwm/anaconda3/envs/SV/lib/python3.6/site-packages/pytorch_lightning/plugins/training_type/single_device.py", line 71, in setup
    self.model_to_device()
  File "/home/xwm/anaconda3/envs/SV/lib/python3.6/site-packages/pytorch_lightning/plugins/training_type/single_device.py", line 68, in model_to_device
    self._model.to(self.root_device)
  File "/home/xwm/anaconda3/envs/SV/lib/python3.6/site-packages/pytorch_lightning/core/mixins/device_dtype_mixin.py", line 111, in to
    return super().to(*args, **kwargs)
  File "/home/xwm/anaconda3/envs/SV/lib/python3.6/site-packages/torch/nn/modules/module.py", line 899, in to
    return self._apply(convert)
  File "/home/xwm/anaconda3/envs/SV/lib/python3.6/site-packages/torch/nn/modules/module.py", line 570, in _apply
    module._apply(fn)
  File "/home/xwm/anaconda3/envs/SV/lib/python3.6/site-packages/torch/nn/modules/module.py", line 570, in _apply
    module._apply(fn)
  File "/home/xwm/anaconda3/envs/SV/lib/python3.6/site-packages/torch/nn/modules/module.py", line 570, in _apply
    module._apply(fn)
  [Previous line repeated 1 more time]
  File "/home/xwm/anaconda3/envs/SV/lib/python3.6/site-packages/torch/nn/modules/module.py", line 593, in _apply
    param_applied = fn(param)
  File "/home/xwm/anaconda3/envs/SV/lib/python3.6/site-packages/torch/nn/modules/module.py", line 897, in convert
    return t.to(device, dtype if t.is_floating_point() or t.is_complex() else None, non_blocking)
RuntimeError: CUDA error: out of memory
CUDA kernel errors might be asynchronously reported at some other API call,so the stacktrace below might be incorrect.
For debugging consider passing CUDA_LAUNCH_BLOCKING=1.

Failure # 32 (occurred at 2022-06-15_23-13-15)
Traceback (most recent call last):
  File "/home/xwm/anaconda3/envs/SV/lib/python3.6/site-packages/ray/tune/trial_runner.py", line 886, in _process_trial
    results = self.trial_executor.fetch_result(trial)
  File "/home/xwm/anaconda3/envs/SV/lib/python3.6/site-packages/ray/tune/ray_trial_executor.py", line 675, in fetch_result
    result = ray.get(trial_future[0], timeout=DEFAULT_GET_TIMEOUT)
  File "/home/xwm/anaconda3/envs/SV/lib/python3.6/site-packages/ray/_private/client_mode_hook.py", line 105, in wrapper
    return func(*args, **kwargs)
  File "/home/xwm/anaconda3/envs/SV/lib/python3.6/site-packages/ray/worker.py", line 1763, in get
    raise value.as_instanceof_cause()
ray.exceptions.RayTaskError(TuneError): [36mray::ImplicitFunc.train()[39m (pid=163448, ip=192.168.249.74, repr=train_tune)
  File "/home/xwm/anaconda3/envs/SV/lib/python3.6/site-packages/ray/tune/trainable.py", line 319, in train
    result = self.step()
  File "/home/xwm/anaconda3/envs/SV/lib/python3.6/site-packages/ray/tune/function_runner.py", line 381, in step
    self._report_thread_runner_error(block=True)
  File "/home/xwm/anaconda3/envs/SV/lib/python3.6/site-packages/ray/tune/function_runner.py", line 532, in _report_thread_runner_error
    ("Trial raised an exception. Traceback:\n{}".format(err_tb_str)
ray.tune.error.TuneError: Trial raised an exception. Traceback:
[36mray::ImplicitFunc.train()[39m (pid=163448, ip=192.168.249.74, repr=train_tune)
  File "/home/xwm/anaconda3/envs/SV/lib/python3.6/site-packages/ray/tune/function_runner.py", line 262, in run
    self._entrypoint()
  File "/home/xwm/anaconda3/envs/SV/lib/python3.6/site-packages/ray/tune/function_runner.py", line 331, in entrypoint
    self._status_reporter.get_checkpoint())
  File "/home/xwm/anaconda3/envs/SV/lib/python3.6/site-packages/ray/tune/function_runner.py", line 600, in _trainable_func
    output = fn()
  File "/home/xwm/anaconda3/envs/SV/lib/python3.6/site-packages/ray/tune/utils/trainable.py", line 371, in inner
    trainable(config, **fn_kwargs)
  File "train.py", line 572, in train_tune
    on="validation_end"),
  File "/home/xwm/anaconda3/envs/SV/lib/python3.6/site-packages/pytorch_lightning/trainer/trainer.py", line 741, in fit
    self._fit_impl, model, train_dataloaders, val_dataloaders, datamodule, ckpt_path
  File "/home/xwm/anaconda3/envs/SV/lib/python3.6/site-packages/pytorch_lightning/trainer/trainer.py", line 685, in _call_and_handle_interrupt
    return trainer_fn(*args, **kwargs)
  File "/home/xwm/anaconda3/envs/SV/lib/python3.6/site-packages/pytorch_lightning/trainer/trainer.py", line 777, in _fit_impl
    self._run(model, ckpt_path=ckpt_path)
  File "/home/xwm/anaconda3/envs/SV/lib/python3.6/site-packages/pytorch_lightning/trainer/trainer.py", line 1145, in _run
    self.accelerator.setup(self)
  File "/home/xwm/anaconda3/envs/SV/lib/python3.6/site-packages/pytorch_lightning/accelerators/gpu.py", line 46, in setup
    return super().setup(trainer)
  File "/home/xwm/anaconda3/envs/SV/lib/python3.6/site-packages/pytorch_lightning/accelerators/accelerator.py", line 91, in setup
    self.setup_training_type_plugin()
  File "/home/xwm/anaconda3/envs/SV/lib/python3.6/site-packages/pytorch_lightning/accelerators/accelerator.py", line 363, in setup_training_type_plugin
    self.training_type_plugin.setup()
  File "/home/xwm/anaconda3/envs/SV/lib/python3.6/site-packages/pytorch_lightning/plugins/training_type/single_device.py", line 71, in setup
    self.model_to_device()
  File "/home/xwm/anaconda3/envs/SV/lib/python3.6/site-packages/pytorch_lightning/plugins/training_type/single_device.py", line 68, in model_to_device
    self._model.to(self.root_device)
  File "/home/xwm/anaconda3/envs/SV/lib/python3.6/site-packages/pytorch_lightning/core/mixins/device_dtype_mixin.py", line 111, in to
    return super().to(*args, **kwargs)
  File "/home/xwm/anaconda3/envs/SV/lib/python3.6/site-packages/torch/nn/modules/module.py", line 899, in to
    return self._apply(convert)
  File "/home/xwm/anaconda3/envs/SV/lib/python3.6/site-packages/torch/nn/modules/module.py", line 570, in _apply
    module._apply(fn)
  File "/home/xwm/anaconda3/envs/SV/lib/python3.6/site-packages/torch/nn/modules/module.py", line 570, in _apply
    module._apply(fn)
  File "/home/xwm/anaconda3/envs/SV/lib/python3.6/site-packages/torch/nn/modules/module.py", line 570, in _apply
    module._apply(fn)
  [Previous line repeated 1 more time]
  File "/home/xwm/anaconda3/envs/SV/lib/python3.6/site-packages/torch/nn/modules/module.py", line 593, in _apply
    param_applied = fn(param)
  File "/home/xwm/anaconda3/envs/SV/lib/python3.6/site-packages/torch/nn/modules/module.py", line 897, in convert
    return t.to(device, dtype if t.is_floating_point() or t.is_complex() else None, non_blocking)
RuntimeError: CUDA error: out of memory
CUDA kernel errors might be asynchronously reported at some other API call,so the stacktrace below might be incorrect.
For debugging consider passing CUDA_LAUNCH_BLOCKING=1.

Failure # 33 (occurred at 2022-06-15_23-14-26)
Traceback (most recent call last):
  File "/home/xwm/anaconda3/envs/SV/lib/python3.6/site-packages/ray/tune/trial_runner.py", line 886, in _process_trial
    results = self.trial_executor.fetch_result(trial)
  File "/home/xwm/anaconda3/envs/SV/lib/python3.6/site-packages/ray/tune/ray_trial_executor.py", line 675, in fetch_result
    result = ray.get(trial_future[0], timeout=DEFAULT_GET_TIMEOUT)
  File "/home/xwm/anaconda3/envs/SV/lib/python3.6/site-packages/ray/_private/client_mode_hook.py", line 105, in wrapper
    return func(*args, **kwargs)
  File "/home/xwm/anaconda3/envs/SV/lib/python3.6/site-packages/ray/worker.py", line 1763, in get
    raise value.as_instanceof_cause()
ray.exceptions.RayTaskError(TuneError): [36mray::ImplicitFunc.train()[39m (pid=171091, ip=192.168.249.74, repr=train_tune)
  File "/home/xwm/anaconda3/envs/SV/lib/python3.6/site-packages/ray/tune/trainable.py", line 319, in train
    result = self.step()
  File "/home/xwm/anaconda3/envs/SV/lib/python3.6/site-packages/ray/tune/function_runner.py", line 381, in step
    self._report_thread_runner_error(block=True)
  File "/home/xwm/anaconda3/envs/SV/lib/python3.6/site-packages/ray/tune/function_runner.py", line 532, in _report_thread_runner_error
    ("Trial raised an exception. Traceback:\n{}".format(err_tb_str)
ray.tune.error.TuneError: Trial raised an exception. Traceback:
[36mray::ImplicitFunc.train()[39m (pid=171091, ip=192.168.249.74, repr=train_tune)
  File "/home/xwm/anaconda3/envs/SV/lib/python3.6/site-packages/ray/tune/function_runner.py", line 262, in run
    self._entrypoint()
  File "/home/xwm/anaconda3/envs/SV/lib/python3.6/site-packages/ray/tune/function_runner.py", line 331, in entrypoint
    self._status_reporter.get_checkpoint())
  File "/home/xwm/anaconda3/envs/SV/lib/python3.6/site-packages/ray/tune/function_runner.py", line 600, in _trainable_func
    output = fn()
  File "/home/xwm/anaconda3/envs/SV/lib/python3.6/site-packages/ray/tune/utils/trainable.py", line 371, in inner
    trainable(config, **fn_kwargs)
  File "train.py", line 572, in train_tune
    on="validation_end"),
  File "/home/xwm/anaconda3/envs/SV/lib/python3.6/site-packages/pytorch_lightning/trainer/trainer.py", line 741, in fit
    self._fit_impl, model, train_dataloaders, val_dataloaders, datamodule, ckpt_path
  File "/home/xwm/anaconda3/envs/SV/lib/python3.6/site-packages/pytorch_lightning/trainer/trainer.py", line 685, in _call_and_handle_interrupt
    return trainer_fn(*args, **kwargs)
  File "/home/xwm/anaconda3/envs/SV/lib/python3.6/site-packages/pytorch_lightning/trainer/trainer.py", line 777, in _fit_impl
    self._run(model, ckpt_path=ckpt_path)
  File "/home/xwm/anaconda3/envs/SV/lib/python3.6/site-packages/pytorch_lightning/trainer/trainer.py", line 1145, in _run
    self.accelerator.setup(self)
  File "/home/xwm/anaconda3/envs/SV/lib/python3.6/site-packages/pytorch_lightning/accelerators/gpu.py", line 46, in setup
    return super().setup(trainer)
  File "/home/xwm/anaconda3/envs/SV/lib/python3.6/site-packages/pytorch_lightning/accelerators/accelerator.py", line 91, in setup
    self.setup_training_type_plugin()
  File "/home/xwm/anaconda3/envs/SV/lib/python3.6/site-packages/pytorch_lightning/accelerators/accelerator.py", line 363, in setup_training_type_plugin
    self.training_type_plugin.setup()
  File "/home/xwm/anaconda3/envs/SV/lib/python3.6/site-packages/pytorch_lightning/plugins/training_type/single_device.py", line 71, in setup
    self.model_to_device()
  File "/home/xwm/anaconda3/envs/SV/lib/python3.6/site-packages/pytorch_lightning/plugins/training_type/single_device.py", line 68, in model_to_device
    self._model.to(self.root_device)
  File "/home/xwm/anaconda3/envs/SV/lib/python3.6/site-packages/pytorch_lightning/core/mixins/device_dtype_mixin.py", line 111, in to
    return super().to(*args, **kwargs)
  File "/home/xwm/anaconda3/envs/SV/lib/python3.6/site-packages/torch/nn/modules/module.py", line 899, in to
    return self._apply(convert)
  File "/home/xwm/anaconda3/envs/SV/lib/python3.6/site-packages/torch/nn/modules/module.py", line 570, in _apply
    module._apply(fn)
  File "/home/xwm/anaconda3/envs/SV/lib/python3.6/site-packages/torch/nn/modules/module.py", line 570, in _apply
    module._apply(fn)
  File "/home/xwm/anaconda3/envs/SV/lib/python3.6/site-packages/torch/nn/modules/module.py", line 570, in _apply
    module._apply(fn)
  [Previous line repeated 1 more time]
  File "/home/xwm/anaconda3/envs/SV/lib/python3.6/site-packages/torch/nn/modules/module.py", line 593, in _apply
    param_applied = fn(param)
  File "/home/xwm/anaconda3/envs/SV/lib/python3.6/site-packages/torch/nn/modules/module.py", line 897, in convert
    return t.to(device, dtype if t.is_floating_point() or t.is_complex() else None, non_blocking)
RuntimeError: CUDA error: out of memory
CUDA kernel errors might be asynchronously reported at some other API call,so the stacktrace below might be incorrect.
For debugging consider passing CUDA_LAUNCH_BLOCKING=1.

Failure # 34 (occurred at 2022-06-15_23-15-30)
Traceback (most recent call last):
  File "/home/xwm/anaconda3/envs/SV/lib/python3.6/site-packages/ray/tune/trial_runner.py", line 886, in _process_trial
    results = self.trial_executor.fetch_result(trial)
  File "/home/xwm/anaconda3/envs/SV/lib/python3.6/site-packages/ray/tune/ray_trial_executor.py", line 675, in fetch_result
    result = ray.get(trial_future[0], timeout=DEFAULT_GET_TIMEOUT)
  File "/home/xwm/anaconda3/envs/SV/lib/python3.6/site-packages/ray/_private/client_mode_hook.py", line 105, in wrapper
    return func(*args, **kwargs)
  File "/home/xwm/anaconda3/envs/SV/lib/python3.6/site-packages/ray/worker.py", line 1763, in get
    raise value.as_instanceof_cause()
ray.exceptions.RayTaskError(TuneError): [36mray::ImplicitFunc.train()[39m (pid=175409, ip=192.168.249.74, repr=train_tune)
  File "/home/xwm/anaconda3/envs/SV/lib/python3.6/site-packages/ray/tune/trainable.py", line 319, in train
    result = self.step()
  File "/home/xwm/anaconda3/envs/SV/lib/python3.6/site-packages/ray/tune/function_runner.py", line 381, in step
    self._report_thread_runner_error(block=True)
  File "/home/xwm/anaconda3/envs/SV/lib/python3.6/site-packages/ray/tune/function_runner.py", line 532, in _report_thread_runner_error
    ("Trial raised an exception. Traceback:\n{}".format(err_tb_str)
ray.tune.error.TuneError: Trial raised an exception. Traceback:
[36mray::ImplicitFunc.train()[39m (pid=175409, ip=192.168.249.74, repr=train_tune)
  File "/home/xwm/anaconda3/envs/SV/lib/python3.6/site-packages/ray/tune/function_runner.py", line 262, in run
    self._entrypoint()
  File "/home/xwm/anaconda3/envs/SV/lib/python3.6/site-packages/ray/tune/function_runner.py", line 331, in entrypoint
    self._status_reporter.get_checkpoint())
  File "/home/xwm/anaconda3/envs/SV/lib/python3.6/site-packages/ray/tune/function_runner.py", line 600, in _trainable_func
    output = fn()
  File "/home/xwm/anaconda3/envs/SV/lib/python3.6/site-packages/ray/tune/utils/trainable.py", line 371, in inner
    trainable(config, **fn_kwargs)
  File "train.py", line 572, in train_tune
    on="validation_end"),
  File "/home/xwm/anaconda3/envs/SV/lib/python3.6/site-packages/pytorch_lightning/trainer/trainer.py", line 741, in fit
    self._fit_impl, model, train_dataloaders, val_dataloaders, datamodule, ckpt_path
  File "/home/xwm/anaconda3/envs/SV/lib/python3.6/site-packages/pytorch_lightning/trainer/trainer.py", line 685, in _call_and_handle_interrupt
    return trainer_fn(*args, **kwargs)
  File "/home/xwm/anaconda3/envs/SV/lib/python3.6/site-packages/pytorch_lightning/trainer/trainer.py", line 777, in _fit_impl
    self._run(model, ckpt_path=ckpt_path)
  File "/home/xwm/anaconda3/envs/SV/lib/python3.6/site-packages/pytorch_lightning/trainer/trainer.py", line 1145, in _run
    self.accelerator.setup(self)
  File "/home/xwm/anaconda3/envs/SV/lib/python3.6/site-packages/pytorch_lightning/accelerators/gpu.py", line 46, in setup
    return super().setup(trainer)
  File "/home/xwm/anaconda3/envs/SV/lib/python3.6/site-packages/pytorch_lightning/accelerators/accelerator.py", line 91, in setup
    self.setup_training_type_plugin()
  File "/home/xwm/anaconda3/envs/SV/lib/python3.6/site-packages/pytorch_lightning/accelerators/accelerator.py", line 363, in setup_training_type_plugin
    self.training_type_plugin.setup()
  File "/home/xwm/anaconda3/envs/SV/lib/python3.6/site-packages/pytorch_lightning/plugins/training_type/single_device.py", line 71, in setup
    self.model_to_device()
  File "/home/xwm/anaconda3/envs/SV/lib/python3.6/site-packages/pytorch_lightning/plugins/training_type/single_device.py", line 68, in model_to_device
    self._model.to(self.root_device)
  File "/home/xwm/anaconda3/envs/SV/lib/python3.6/site-packages/pytorch_lightning/core/mixins/device_dtype_mixin.py", line 111, in to
    return super().to(*args, **kwargs)
  File "/home/xwm/anaconda3/envs/SV/lib/python3.6/site-packages/torch/nn/modules/module.py", line 899, in to
    return self._apply(convert)
  File "/home/xwm/anaconda3/envs/SV/lib/python3.6/site-packages/torch/nn/modules/module.py", line 570, in _apply
    module._apply(fn)
  File "/home/xwm/anaconda3/envs/SV/lib/python3.6/site-packages/torch/nn/modules/module.py", line 570, in _apply
    module._apply(fn)
  File "/home/xwm/anaconda3/envs/SV/lib/python3.6/site-packages/torch/nn/modules/module.py", line 570, in _apply
    module._apply(fn)
  [Previous line repeated 1 more time]
  File "/home/xwm/anaconda3/envs/SV/lib/python3.6/site-packages/torch/nn/modules/module.py", line 593, in _apply
    param_applied = fn(param)
  File "/home/xwm/anaconda3/envs/SV/lib/python3.6/site-packages/torch/nn/modules/module.py", line 897, in convert
    return t.to(device, dtype if t.is_floating_point() or t.is_complex() else None, non_blocking)
RuntimeError: CUDA error: out of memory
CUDA kernel errors might be asynchronously reported at some other API call,so the stacktrace below might be incorrect.
For debugging consider passing CUDA_LAUNCH_BLOCKING=1.

Failure # 35 (occurred at 2022-06-16_20-35-52)
Traceback (most recent call last):
  File "/home/xwm/anaconda3/envs/SV/lib/python3.6/site-packages/ray/tune/trial_runner.py", line 886, in _process_trial
    results = self.trial_executor.fetch_result(trial)
  File "/home/xwm/anaconda3/envs/SV/lib/python3.6/site-packages/ray/tune/ray_trial_executor.py", line 675, in fetch_result
    result = ray.get(trial_future[0], timeout=DEFAULT_GET_TIMEOUT)
  File "/home/xwm/anaconda3/envs/SV/lib/python3.6/site-packages/ray/_private/client_mode_hook.py", line 105, in wrapper
    return func(*args, **kwargs)
  File "/home/xwm/anaconda3/envs/SV/lib/python3.6/site-packages/ray/worker.py", line 1765, in get
    raise value
ray.exceptions.RayActorError: The actor died unexpectedly before finishing this task.
	class_name: ImplicitFunc
	actor_id: cda438e6191b1053c12ffd9101000000
	pid: 177647
	namespace: a69f6d54-1e32-4ff9-be0c-65874c84c5fe
	ip: 192.168.249.74
The actor is dead because its worker process has died. Worker exit type: SYSTEM_ERROR_EXIT

