Failure # 1 (occurred at 2022-06-16_22-56-59)
Traceback (most recent call last):
  File "/home/xwm/anaconda3/envs/SV/lib/python3.6/site-packages/ray/tune/trial_runner.py", line 886, in _process_trial
    results = self.trial_executor.fetch_result(trial)
  File "/home/xwm/anaconda3/envs/SV/lib/python3.6/site-packages/ray/tune/ray_trial_executor.py", line 675, in fetch_result
    result = ray.get(trial_future[0], timeout=DEFAULT_GET_TIMEOUT)
  File "/home/xwm/anaconda3/envs/SV/lib/python3.6/site-packages/ray/_private/client_mode_hook.py", line 105, in wrapper
    return func(*args, **kwargs)
  File "/home/xwm/anaconda3/envs/SV/lib/python3.6/site-packages/ray/worker.py", line 1763, in get
    raise value.as_instanceof_cause()
ray.exceptions.RayTaskError(TuneError): [36mray::ImplicitFunc.train()[39m (pid=142217, ip=192.168.249.74, repr=train_tune)
  File "/home/xwm/anaconda3/envs/SV/lib/python3.6/site-packages/ray/tune/trainable.py", line 319, in train
    result = self.step()
  File "/home/xwm/anaconda3/envs/SV/lib/python3.6/site-packages/ray/tune/function_runner.py", line 381, in step
    self._report_thread_runner_error(block=True)
  File "/home/xwm/anaconda3/envs/SV/lib/python3.6/site-packages/ray/tune/function_runner.py", line 532, in _report_thread_runner_error
    ("Trial raised an exception. Traceback:\n{}".format(err_tb_str)
ray.tune.error.TuneError: Trial raised an exception. Traceback:
[36mray::ImplicitFunc.train()[39m (pid=142217, ip=192.168.249.74, repr=train_tune)
  File "/home/xwm/anaconda3/envs/SV/lib/python3.6/site-packages/ray/tune/function_runner.py", line 262, in run
    self._entrypoint()
  File "/home/xwm/anaconda3/envs/SV/lib/python3.6/site-packages/ray/tune/function_runner.py", line 331, in entrypoint
    self._status_reporter.get_checkpoint())
  File "/home/xwm/anaconda3/envs/SV/lib/python3.6/site-packages/ray/tune/function_runner.py", line 600, in _trainable_func
    output = fn()
  File "/home/xwm/anaconda3/envs/SV/lib/python3.6/site-packages/ray/tune/utils/trainable.py", line 371, in inner
    trainable(config, **fn_kwargs)
  File "train.py", line 572, in train_tune
    trainer.fit(model)
  File "/home/xwm/anaconda3/envs/SV/lib/python3.6/site-packages/pytorch_lightning/trainer/trainer.py", line 741, in fit
    self._fit_impl, model, train_dataloaders, val_dataloaders, datamodule, ckpt_path
  File "/home/xwm/anaconda3/envs/SV/lib/python3.6/site-packages/pytorch_lightning/trainer/trainer.py", line 685, in _call_and_handle_interrupt
    return trainer_fn(*args, **kwargs)
  File "/home/xwm/anaconda3/envs/SV/lib/python3.6/site-packages/pytorch_lightning/trainer/trainer.py", line 777, in _fit_impl
    self._run(model, ckpt_path=ckpt_path)
  File "/home/xwm/anaconda3/envs/SV/lib/python3.6/site-packages/pytorch_lightning/trainer/trainer.py", line 1199, in _run
    self._dispatch()
  File "/home/xwm/anaconda3/envs/SV/lib/python3.6/site-packages/pytorch_lightning/trainer/trainer.py", line 1279, in _dispatch
    self.training_type_plugin.start_training(self)
  File "/home/xwm/anaconda3/envs/SV/lib/python3.6/site-packages/pytorch_lightning/plugins/training_type/training_type_plugin.py", line 202, in start_training
    self._results = trainer.run_stage()
  File "/home/xwm/anaconda3/envs/SV/lib/python3.6/site-packages/pytorch_lightning/trainer/trainer.py", line 1289, in run_stage
    return self._run_train()
  File "/home/xwm/anaconda3/envs/SV/lib/python3.6/site-packages/pytorch_lightning/trainer/trainer.py", line 1311, in _run_train
    self._run_sanity_check(self.lightning_module)
  File "/home/xwm/anaconda3/envs/SV/lib/python3.6/site-packages/pytorch_lightning/trainer/trainer.py", line 1375, in _run_sanity_check
    self._evaluation_loop.run()
  File "/home/xwm/anaconda3/envs/SV/lib/python3.6/site-packages/pytorch_lightning/loops/base.py", line 151, in run
    output = self.on_run_end()
  File "/home/xwm/anaconda3/envs/SV/lib/python3.6/site-packages/pytorch_lightning/loops/dataloader/evaluation_loop.py", line 131, in on_run_end
    self._evaluation_epoch_end(outputs)
  File "/home/xwm/anaconda3/envs/SV/lib/python3.6/site-packages/pytorch_lightning/loops/dataloader/evaluation_loop.py", line 236, in _evaluation_epoch_end
    model.validation_epoch_end(outputs)
  File "/home/xwm/DeepSVFilter/code/net.py", line 486, in validation_epoch_end
    metric = classification_report(y, y_pred, output_dict = True)
NameError: name 'y_pred' is not defined

